Workbook
Name A: #REF!
Name A: #REF!
Name A: #REF!
Name A: #REF!
Name A: #REF!
Name AAAA: #REF!
Name AAAA: #REF!
Name AAAA: #REF!
Name AAAA: #REF!
Name AAAA: #REF!
Name AG: #REF!
Name AG: #REF!
Name AG: #REF!
Name AG: #REF!
Name AG: #REF!
Name b: #REF!
Name b: #REF!
Name b: #REF!
Name b: #REF!
Name b: #REF!
Name BANTU: #REF!
Name BANTU: #REF!
Name BANTU: #REF!
Name BANTU: #REF!
Name BANTU: #REF!
Name barat: #REF!
Name barat: #REF!
Name barat: #REF!
Name barat: #REF!
Name barat: #REF!
Name d: #REF!
Name d: #REF!
Name d: #REF!
Name d: #REF!
Name d: #REF!
Name DAN: #REF!
Name DAN: #REF!
Name DAN: #REF!
Name DAN: #REF!
Name DAN: #REF!
Name DS: #REF!
Name DS: #REF!
Name DS: #REF!
Name DS: #REF!
Name DS: #REF!
Name e: #REF!
Name e: #REF!
Name e: #REF!
Name e: #REF!
Name e: #REF!
Name GHNJFG: #REF!
Name GHNJFG: #REF!
Name GHNJFG: #REF!
Name GHNJFG: #REF!
Name GHNJFG: #REF!
Name lubis: #REF!
Name lubis: #REF!
Name lubis: #REF!
Name lubis: #REF!
Name lubis: #REF!

Sheet MASA KERJA AB
A1: MASA KERJA KARYAWAN
A2: AIR RUAK ESTATE B2 AIR BANGEK
A4: Tanggal | E4: 45808
A6: PERAWATAN
A7: No | B7: Nama | C7: Tgl Lahir | D7: Umur | E7: Tgl Masuk | F7: Masa Kerja | G7: Bulan Kerja | H7: Tahun Kerja | I7: Rp.Masa Kerja | J7: Status | K7: Rp.Tunjangan Beras | L7: FEB'25 | M7: MAR'24
A8: 1 | B8: KARYADI | C8: 28404 | D8: =DATEDIF(C8,$E$4,"Y")&" Tahun, "&DATEDIF(C8,$E$4,"YM")&" Bulan, "&DATEDIF(C8,$E$4,"MD")&" hari" -> 47 Tahun, 7 Bulan, 25 hari | E8: 01-03-2008 | F8: =DATEDIF(E8,$E$4,"Y")&" Tahun, "&DATEDIF(E8,$E$4,"YM")&" Bulan, "&DATEDIF(E8,$E$4,"MD")&" hari" -> 17 Tahun, 4 Bulan, 28 hari | G8: 3 | H8: 17 | I8: 50500 | J8: K/1 | K8: 4650 | L8: 47000 | M8: 50500 | N8: =L8-M8 -> -3500
A9: 2 | B9: SARINA | C9: 29628 | D9: =DATEDIF(C9,$E$4,"Y")&" Tahun, "&DATEDIF(C9,$E$4,"YM")&" Bulan, "&DATEDIF(C9,$E$4,"MD")&" hari" -> 44 Tahun, 3 Bulan, 20 hari | E9: 01-07-2008 | F9: =DATEDIF(E9,$E$4,"Y")&" Tahun, "&DATEDIF(E9,$E$4,"YM")&" Bulan, "&DATEDIF(E9,$E$4,"MD")&" hari" -> 17 Tahun, 4 Bulan, 24 hari | G9: 7 | H9: 16 | I9: 47000 | J9: TK/0 | K9: 2250 | L9: 47000 | N9: =L9-M9 -> 47000
A10: 3 | B10: SUPRIYANI | C10: 32199 | D10: =DATEDIF(C10,$E$4,"Y")&" Tahun, "&DATEDIF(C10,$E$4,"YM")&" Bulan, "&DATEDIF(C10,$E$4,"MD")&" hari" -> 37 Tahun, 3 Bulan, 5 hari | E10: 02-05-2015 | F10: =DATEDIF(E10,$E$4,"Y")&" Tahun, "&DATEDIF(E10,$E$4,"YM")&" Bulan, "&DATEDIF(E10,$E$4,"MD")&" hari" -> 10 Tahun, 3 Bulan, 26 hari | G10: 5 | H10: 10 | I10: 27000 | J10: TK/0 | K10: 2250 | L10: 24000 | N10: =L10-M10 -> 24000
A11: 4 | B11: HELMIYADI | C11: 34692 | D11: =DATEDIF(C11,$E$4,"Y")&" Tahun, "&DATEDIF(C11,$E$4,"YM")&" Bulan, "&DATEDIF(C11,$E$4,"MD")&" hari" -> 30 Tahun, 5 Bulan, 7 hari | E11: 41625 | F11: =DATEDIF(E11,$E$4,"Y")&" Tahun, "&DATEDIF(E11,$E$4,"YM")&" Bulan, "&DATEDIF(E11,$E$4,"MD")&" hari" -> 11 Tahun, 5 Bulan, 14 hari | G11: 12 | H11: 10 | I11: 27000 | J11: K/1 | K11: 4650 | L11: 30000 | N11: =L11-M11 -> 30000
A12: 5 | B12: RHIZA KURNIA | C12: 32206 | D12: =DATEDIF(C12,$E$4,"Y")&" Tahun, "&DATEDIF(C12,$E$4,"YM")&" Bulan, "&DATEDIF(C12,$E$4,"MD")&" hari" -> 37 Tahun, 2 Bulan, 27 hari | E12: 03/11/2009 | F12: =DATEDIF(E12,$E$4,"Y")&" Tahun, "&DATEDIF(E12,$E$4,"YM")&" Bulan, "&DATEDIF(E12,$E$4,"MD")&" hari" -> 16 Tahun, 2 Bulan, 20 hari | G12: 11 | H12: 15 | I12: 43500 | J12: TK/0 | K12: 2250 | L12: 43500 | N12: =L12-M12 -> 43500
A13: 6 | B13: HENDRI | C13: 36272 | D13: =DATEDIF(C13,$E$4,"Y")&" Tahun, "&DATEDIF(C13,$E$4,"YM")&" Bulan, "&DATEDIF(C13,$E$4,"MD")&" hari" -> 26 Tahun, 1 Bulan, 9 hari | E13: 11-07-2017 | F13: =DATEDIF(E13,$E$4,"Y")&" Tahun, "&DATEDIF(E13,$E$4,"YM")&" Bulan, "&DATEDIF(E13,$E$4,"MD")&" hari" -> 7 Tahun, 6 Bulan, 24 hari | G13: 7 | H13: 7 | I13: 18000 | J13: K/1 | K13: 4650 | L13: 18000 | N13: =L13-M13 -> 18000
A14: 7 | B14: SOLIKAN | C14: 27613 | D14: =DATEDIF(C14,$E$4,"Y")&" Tahun, "&DATEDIF(C14,$E$4,"YM")&" Bulan, "&DATEDIF(C14,$E$4,"MD")&" hari" -> 49 Tahun, 9 Bulan, 24 hari | E14: 01-03-2013 | F14: =DATEDIF(E14,$E$4,"Y")&" Tahun, "&DATEDIF(E14,$E$4,"YM")&" Bulan, "&DATEDIF(E14,$E$4,"MD")&" hari" -> 12 Tahun, 4 Bulan, 28 hari | G14: 3 | H14: 12 | I14: 33000 | J14: TK/2 | K14: 4200 | L14: 30000 | M14: 33000 | N14: =L14-M14 -> -3000
A15: 8 | B15: ERLANDI EDI SUYANTO | C15: 26788 | D15: =DATEDIF(C15,$E$4,"Y")&" Tahun, "&DATEDIF(C15,$E$4,"YM")&" Bulan, "&DATEDIF(C15,$E$4,"MD")&" hari" -> 52 Tahun, 0 Bulan, 27 hari | E15: 01-03-2015 | F15: =DATEDIF(E15,$E$4,"Y")&" Tahun, "&DATEDIF(E15,$E$4,"YM")&" Bulan, "&DATEDIF(E15,$E$4,"MD")&" hari" -> 10 Tahun, 4 Bulan, 28 hari | G15: 3 | H15: 10 | I15: 27000 | J15: K/1 | K15: 4650 | L15: 24000 | M15: 27000 | N15: =L15-M15 -> -3000
A16: 9 | B16: HENNI FRIANTI | C16: 34738 | D16: =DATEDIF(C16,$E$4,"Y")&" Tahun, "&DATEDIF(C16,$E$4,"YM")&" Bulan, "&DATEDIF(C16,$E$4,"MD")&" hari" -> 30 Tahun, 3 Bulan, 23 hari | E16: 01-04-2013 | F16: =DATEDIF(E16,$E$4,"Y")&" Tahun, "&DATEDIF(E16,$E$4,"YM")&" Bulan, "&DATEDIF(E16,$E$4,"MD")&" hari" -> 12 Tahun, 4 Bulan, 27 hari | G16: 4 | H16: 12 | I16: 33000 | J16: TK/0 | K16: 2250 | L16: 30000 | N16: =L16-M16 -> 30000
A17: 10 | B17: NELLY MARLINA | C17: 29553 | D17: =DATEDIF(C17,$E$4,"Y")&" Tahun, "&DATEDIF(C17,$E$4,"YM")&" Bulan, "&DATEDIF(C17,$E$4,"MD")&" hari" -> 44 Tahun, 6 Bulan, 3 hari | E17: 04-08-2008 | F17: =DATEDIF(E17,$E$4,"Y")&" Tahun, "&DATEDIF(E17,$E$4,"YM")&" Bulan, "&DATEDIF(E17,$E$4,"MD")&" hari" -> 17 Tahun, 1 Bulan, 23 hari | G17: 8 | H17: 16 | I17: 43500 | J17: TK/0 | K17: 2250 | L17: 43500 | N17: =L17-M17 -> 43500
A18: 11 | B18: IISNAWATI | C18: 30762 | D18: =DATEDIF(C18,$E$4,"Y")&" Tahun, "&DATEDIF(C18,$E$4,"YM")&" Bulan, "&DATEDIF(C18,$E$4,"MD")&" hari" -> 41 Tahun, 2 Bulan, 10 hari | E18: 08-12-2014 | F18: =DATEDIF(E18,$E$4,"Y")&" Tahun, "&DATEDIF(E18,$E$4,"YM")&" Bulan, "&DATEDIF(E18,$E$4,"MD")&" hari" -> 10 Tahun, 9 Bulan, 19 hari | G18: 12 | H18: 10 | I18: 24000 | J18: TK/0 | K18: 2250 | L18: 24000 | N18: =L18-M18 -> 24000
A19: 12 | B19: DEWI KOMALASARI | C19: 29050 | D19: =DATEDIF(C19,$E$4,"Y")&" Tahun, "&DATEDIF(C19,$E$4,"YM")&" Bulan, "&DATEDIF(C19,$E$4,"MD")&" hari" -> 45 Tahun, 10 Bulan, 17 hari | E19: 01-08-2008 | F19: =DATEDIF(E19,$E$4,"Y")&" Tahun, "&DATEDIF(E19,$E$4,"YM")&" Bulan, "&DATEDIF(E19,$E$4,"MD")&" hari" -> 17 Tahun, 4 Bulan, 23 hari | G19: 8 | H19: 16 | I19: 47000 | J19: TK/0 | K19: 2250 | L19: 47000 | N19: =L19-M19 -> 47000
A20: 13 | B20: KUSMIATI | C20: 30894 | D20: =DATEDIF(C20,$E$4,"Y")&" Tahun, "&DATEDIF(C20,$E$4,"YM")&" Bulan, "&DATEDIF(C20,$E$4,"MD")&" hari" -> 40 Tahun, 10 Bulan, 0 hari | E20: 01-04-2008 | F20: =DATEDIF(E20,$E$4,"Y")&" Tahun, "&DATEDIF(E20,$E$4,"YM")&" Bulan, "&DATEDIF(E20,$E$4,"MD")&" hari" -> 17 Tahun, 4 Bulan, 27 hari | G20: 4 | H20: 17 | I20: 50500 | J20: TK/0 | K20: 2250 | L20: 47000 | N20: =L20-M20 -> 47000
A21: 14 | B21: SANUSI (ROYANI) | C21: 28538 | D21: =DATEDIF(C21,$E$4,"Y")&" Tahun, "&DATEDIF(C21,$E$4,"YM")&" Bulan, "&DATEDIF(C21,$E$4,"MD")&" hari" -> 47 Tahun, 3 Bulan, 14 hari | E21: 01-04-2008 | F21: =DATEDIF(E21,$E$4,"Y")&" Tahun, "&DATEDIF(E21,$E$4,"YM")&" Bulan, "&DATEDIF(E21,$E$4,"MD")&" hari" -> 17 Tahun, 4 Bulan, 27 hari | G21: 4 | H21: 17 | I21: 50500 | J21: K/2 | K21: 5550 | L21: 47000 | N21: =L21-M21 -> 47000
A22: 15 | B22: YUSNI | C22: 25815 | D22: =DATEDIF(C22,$E$4,"Y")&" Tahun, "&DATEDIF(C22,$E$4,"YM")&" Bulan, "&DATEDIF(C22,$E$4,"MD")&" hari" -> 54 Tahun, 8 Bulan, 27 hari | E22: 01-09-2008 | F22: =DATEDIF(E22,$E$4,"Y")&" Tahun, "&DATEDIF(E22,$E$4,"YM")&" Bulan, "&DATEDIF(E22,$E$4,"MD")&" hari" -> 17 Tahun, 4 Bulan, 22 hari | G22: 9 | H22: 16 | I22: 47000 | J22: TK/0 | K22: 2250 | L22: 47000 | N22: =L22-M22 -> 47000
A23: 16 | B23: RODIATI | C23: 27242 | D23: =DATEDIF(C23,$E$4,"Y")&" Tahun, "&DATEDIF(C23,$E$4,"YM")&" Bulan, "&DATEDIF(C23,$E$4,"MD")&" hari" -> 50 Tahun, 9 Bulan, 30 hari | E23: 01-04-2008 | F23: =DATEDIF(E23,$E$4,"Y")&" Tahun, "&DATEDIF(E23,$E$4,"YM")&" Bulan, "&DATEDIF(E23,$E$4,"MD")&" hari" -> 17 Tahun, 4 Bulan, 27 hari | G23: 4 | H23: 17 | I23: 50500 | J23: TK/0 | K23: 2250 | L23: 47000 | N23: =L23-M23 -> 47000
A24: 17 | B24: ERNAWATI | C24: 31594 | D24: =DATEDIF(C24,$E$4,"Y")&" Tahun, "&DATEDIF(C24,$E$4,"YM")&" Bulan, "&DATEDIF(C24,$E$4,"MD")&" hari" -> 38 Tahun, 10 Bulan, 30 hari | E24: 01-03-2015 | F24: =DATEDIF(E24,$E$4,"Y")&" Tahun, "&DATEDIF(E24,$E$4,"YM")&" Bulan, "&DATEDIF(E24,$E$4,"MD")&" hari" -> 10 Tahun, 4 Bulan, 28 hari | G24: 3 | H24: 10 | I24: 27000 | J24: TK/0 | K24: 2250 | L24: 24000 | M24: 27000 | N24: =L24-M24 -> -3000
A25: 18 | B25: ANDRISTO BUDIMAN | C25: 32231 | D25: =DATEDIF(C25,$E$4,"Y")&" Tahun, "&DATEDIF(C25,$E$4,"YM")&" Bulan, "&DATEDIF(C25,$E$4,"MD")&" hari" -> 37 Tahun, 2 Bulan, 2 hari | E25: 01-01-2009 | F25: =DATEDIF(E25,$E$4,"Y")&" Tahun, "&DATEDIF(E25,$E$4,"YM")&" Bulan, "&DATEDIF(E25,$E$4,"MD")&" hari" -> 16 Tahun, 4 Bulan, 30 hari | G25: 1 | H25: 16 | I25: 43500 | J25: K/2 | K25: 5550 | L25: 43500 | N25: =L25-M25 -> 43500
A26: 19 | B26: SUNITA | C26: 28710 | D26: =DATEDIF(C26,$E$4,"Y")&" Tahun, "&DATEDIF(C26,$E$4,"YM")&" Bulan, "&DATEDIF(C26,$E$4,"MD")&" hari" -> 46 Tahun, 9 Bulan, 23 hari | E26: 39630 | F26: =DATEDIF(E26,$E$4,"Y")&" Tahun, "&DATEDIF(E26,$E$4,"YM")&" Bulan, "&DATEDIF(E26,$E$4,"MD")&" hari" -> 16 Tahun, 10 Bulan, 30 hari | G26: 11 | H26: 16 | I26: 47000 | J26: TK/0 | K26: 2250 | L26: 47000 | N26: =L26-M26 -> 47000
A27: 20 | B27: MAMAN | C27: 32288 | D27: =DATEDIF(C27,$E$4,"Y")&" Tahun, "&DATEDIF(C27,$E$4,"YM")&" Bulan, "&DATEDIF(C27,$E$4,"MD")&" hari" -> 37 Tahun, 0 Bulan, 6 hari | E27: 01-07-2008 | F27: =DATEDIF(E27,$E$4,"Y")&" Tahun, "&DATEDIF(E27,$E$4,"YM")&" Bulan, "&DATEDIF(E27,$E$4,"MD")&" hari" -> 17 Tahun, 4 Bulan, 24 hari | G27: 7 | H27: 16 | I27: 47000 | J27: K/2 | K27: 5550 | L27: 47000 | N27: =L27-M27 -> 47000
A28: 21 | B28: BADIK BAGUS PRIBADI | C28: 28335 | D28: =DATEDIF(C28,$E$4,"Y")&" Tahun, "&DATEDIF(C28,$E$4,"YM")&" Bulan, "&DATEDIF(C28,$E$4,"MD")&" hari" -> 47 Tahun, 10 Bulan, 2 hari | E28: 39749 | F28: =DATEDIF(E28,$E$4,"Y")&" Tahun, "&DATEDIF(E28,$E$4,"YM")&" Bulan, "&DATEDIF(E28,$E$4,"MD")&" hari" -> 16 Tahun, 7 Bulan, 3 hari | G28: 10 | H28: 16 | I28: 43500 | J28: K/2 | K28: 5550 | L28: 43500 | N28: =L28-M28 -> 43500
A29: 22 | B29: AGUSTINI | C29: 26528 | D29: =DATEDIF(C29,$E$4,"Y")&" Tahun, "&DATEDIF(C29,$E$4,"YM")&" Bulan, "&DATEDIF(C29,$E$4,"MD")&" hari" -> 52 Tahun, 9 Bulan, 14 hari | E29: 02-10-2009 | F29: =DATEDIF(E29,$E$4,"Y")&" Tahun, "&DATEDIF(E29,$E$4,"YM")&" Bulan, "&DATEDIF(E29,$E$4,"MD")&" hari" -> 16 Tahun, 3 Bulan, 21 hari | G29: 10 | H29: 15 | I29: 43500 | J29: TK/0 | K29: 2250 | L29: 40000 | N29: =L29-M29 -> 40000
A30: 23 | B30: DEVI NATALIA | C30: 31506 | D30: =DATEDIF(C30,$E$4,"Y")&" Tahun, "&DATEDIF(C30,$E$4,"YM")&" Bulan, "&DATEDIF(C30,$E$4,"MD")&" hari" -> 39 Tahun, 1 Bulan, 27 hari | E30: 04-08-2008 | F30: =DATEDIF(E30,$E$4,"Y")&" Tahun, "&DATEDIF(E30,$E$4,"YM")&" Bulan, "&DATEDIF(E30,$E$4,"MD")&" hari" -> 17 Tahun, 1 Bulan, 23 hari | G30: 8 | H30: 16 | I30: 47000 | J30: TK/0 | K30: 2250 | L30: 47000 | N30: =L30-M30 -> 47000
A31: 24 | B31: HERLINDA | C31: 27211 | D31: =DATEDIF(C31,$E$4,"Y")&" Tahun, "&DATEDIF(C31,$E$4,"YM")&" Bulan, "&DATEDIF(C31,$E$4,"MD")&" hari" -> 50 Tahun, 10 Bulan, 30 hari | E31: 39734 | F31: =DATEDIF(E31,$E$4,"Y")&" Tahun, "&DATEDIF(E31,$E$4,"YM")&" Bulan, "&DATEDIF(E31,$E$4,"MD")&" hari" -> 16 Tahun, 7 Bulan, 18 hari | G31: 10 | H31: 16 | I31: 43500 | J31: TK/0 | K31: 2250 | L31: 43500 | N31: =L31-M31 -> 43500
A32: 25 | B32: ASERI | C32: 29984 | D32: =DATEDIF(C32,$E$4,"Y")&" Tahun, "&DATEDIF(C32,$E$4,"YM")&" Bulan, "&DATEDIF(C32,$E$4,"MD")&" hari" -> 43 Tahun, 3 Bulan, 29 hari | E32: 01-11-2008 | F32: =DATEDIF(E32,$E$4,"Y")&" Tahun, "&DATEDIF(E32,$E$4,"YM")&" Bulan, "&DATEDIF(E32,$E$4,"MD")&" hari" -> 17 Tahun, 4 Bulan, 20 hari | G32: 11 | H32: 16 | I32: 43500 | J32: K/1 | K32: 4650 | L32: 43500 | N32: =L32-M32 -> 43500
A33: 26 | B33: ADI SUSANTO | C33: 28745 | D33: =DATEDIF(C33,$E$4,"Y")&" Tahun, "&DATEDIF(C33,$E$4,"YM")&" Bulan, "&DATEDIF(C33,$E$4,"MD")&" hari" -> 46 Tahun, 8 Bulan, 19 hari | E33: 42702 | F33: =DATEDIF(E33,$E$4,"Y")&" Tahun, "&DATEDIF(E33,$E$4,"YM")&" Bulan, "&DATEDIF(E33,$E$4,"MD")&" hari" -> 8 Tahun, 6 Bulan, 3 hari | G33: 11 | H33: 8 | I33: 18000 | J33: K/1 | K33: 4650 | L33: 18000 | N33: =L33-M33 -> 18000
A34: 27 | B34: ANSITA | C34: 27219 | D34: =DATEDIF(C34,$E$4,"Y")&" Tahun, "&DATEDIF(C34,$E$4,"YM")&" Bulan, "&DATEDIF(C34,$E$4,"MD")&" hari" -> 50 Tahun, 10 Bulan, 22 hari | E34: 01-08-2008 | F34: =DATEDIF(E34,$E$4,"Y")&" Tahun, "&DATEDIF(E34,$E$4,"YM")&" Bulan, "&DATEDIF(E34,$E$4,"MD")&" hari" -> 17 Tahun, 4 Bulan, 23 hari | G34: 8 | H34: 16 | I34: 47000 | J34: TK/0 | K34: 2250 | L34: 47000 | N34: =L34-M34 -> 47000
A35: 28 | B35: ASNAWATI | C35: 29762 | D35: =DATEDIF(C35,$E$4,"Y")&" Tahun, "&DATEDIF(C35,$E$4,"YM")&" Bulan, "&DATEDIF(C35,$E$4,"MD")&" hari" -> 43 Tahun, 11 Bulan, 6 hari | E35: 01-11-2009 | F35: =DATEDIF(E35,$E$4,"Y")&" Tahun, "&DATEDIF(E35,$E$4,"YM")&" Bulan, "&DATEDIF(E35,$E$4,"MD")&" hari" -> 16 Tahun, 4 Bulan, 20 hari | G35: 11 | H35: 15 | I35: 40000 | J35: TK/0 | K35: 2250 | L35: 40000 | N35: =L35-M35 -> 40000
A36: 29 | B36: HATINA | C36: 30104 | D36: =DATEDIF(C36,$E$4,"Y")&" Tahun, "&DATEDIF(C36,$E$4,"YM")&" Bulan, "&DATEDIF(C36,$E$4,"MD")&" hari" -> 42 Tahun, 11 Bulan, 29 hari | E36: 42095 | F36: =DATEDIF(E36,$E$4,"Y")&" Tahun, "&DATEDIF(E36,$E$4,"YM")&" Bulan, "&DATEDIF(E36,$E$4,"MD")&" hari" -> 10 Tahun, 1 Bulan, 30 hari | G36: 4 | H36: 9 | I36: 24000 | J36: TK/0 | K36: 2250 | L36: 24000 | N36: =L36-M36 -> 24000
A37: 30 | B37: JUANDI | C37: 11/11/1994 | D37: =DATEDIF(C37,$E$4,"Y")&" Tahun, "&DATEDIF(C37,$E$4,"YM")&" Bulan, "&DATEDIF(C37,$E$4,"MD")&" hari" -> 30 Tahun, 6 Bulan, 20 hari | E37: 01-04-2013 | F37: =DATEDIF(E37,$E$4,"Y")&" Tahun, "&DATEDIF(E37,$E$4,"YM")&" Bulan, "&DATEDIF(E37,$E$4,"MD")&" hari" -> 12 Tahun, 4 Bulan, 27 hari | G37: 4 | H37: 12 | I37: 33000 | J37: K/1 | K37: 4650 | L37: 24000 | N37: =L37-M37 -> 24000
A38: 31 | B38: ALI SADIKIN | C38: 06/05/1969 | D38: =DATEDIF(C38,$E$4,"Y")&" Tahun, "&DATEDIF(C38,$E$4,"YM")&" Bulan, "&DATEDIF(C38,$E$4,"MD")&" hari" -> 55 Tahun, 11 Bulan, 26 hari | E38: 44216 | F38: =DATEDIF(E38,$E$4,"Y")&" Tahun, "&DATEDIF(E38,$E$4,"YM")&" Bulan, "&DATEDIF(E38,$E$4,"MD")&" hari" -> 4 Tahun, 4 Bulan, 11 hari | G38: 1 | H38: 3 | I38: 7500 | J38: K/0 | K38: 3700 | L38: 7500 | N38: =L38-M38 -> 7500
A39: 32 | B39: HERIYANTO | C39: 30662 | D39: =DATEDIF(C39,$E$4,"Y")&" Tahun, "&DATEDIF(C39,$E$4,"YM")&" Bulan, "&DATEDIF(C39,$E$4,"MD")&" hari" -> 41 Tahun, 5 Bulan, 19 hari | E39: 01-06-2015 | F39: =DATEDIF(E39,$E$4,"Y")&" Tahun, "&DATEDIF(E39,$E$4,"YM")&" Bulan, "&DATEDIF(E39,$E$4,"MD")&" hari" -> 10 Tahun, 4 Bulan, 25 hari | G39: 6 | H39: 9 | I39: 24000 | J39: K/2 | K39: 5550 | L39: 24000 | N39: =L39-M39 -> 24000
A40: 33 | B40: SAHRUL | C40: 28729 | D40: =DATEDIF(C40,$E$4,"Y")&" Tahun, "&DATEDIF(C40,$E$4,"YM")&" Bulan, "&DATEDIF(C40,$E$4,"MD")&" hari" -> 46 Tahun, 9 Bulan, 4 hari | E40: 01-04-2013 | F40: =DATEDIF(E40,$E$4,"Y")&" Tahun, "&DATEDIF(E40,$E$4,"YM")&" Bulan, "&DATEDIF(E40,$E$4,"MD")&" hari" -> 12 Tahun, 4 Bulan, 27 hari | G40: 4 | H40: 12 | I40: 33000 | J40: TK/1 | K40: 3250 | L40: 30000 | N40: =L40-M40 -> 30000
A41: TRANSPORT | N41: =L41-M41 -> 0
A42: No | B42: Nama | C42: Tgl Lahir | D42: Umur | E42: Tgl Masuk | F42: Masa Kerja | H42: Tahun Kerja | I42: Rp.Masa Kerja | J42: Status | K42: Rp.Tunjangan Beras | N42: =L42-M42 -> 0
...

Sheet PENGAJUAN PRUNING MEI 2025
A1: PT. REBINMAS JAYA
A2: ARE B2
A3: PENGAJUAN PENGERJAAN PRUNING
A4: BULAN : MEI 2025
A5: ARE. B2 ( AIK BANGEK)
A6: No. | B6: Nama Karyawan | C6: Block | O6: TOTAL POKOK ( A ) | P6: TOTAL ( Rp )
C7: P0807 ( J15-J16 ) | G7: P9801 ( J17-J18 ) | K7: P0808 ( J19-J20 )
C8: ANCAK | D8: POKOK | E8: Rp/ Pokok | F8: JUMLAH | G8: ANCAK | H8: POKOK | I8: Rp/ Pokok | J8: JUMLAH | K8: ANCAK | L8: POKOK | M8: Rp/ Pokok | N8: JUMLAH
A9: 1 | B9: JUMIN | C9: 29/30 | D9: 511 | E9: 500 | F9: =D9*E9 -> 255500 | G9: 29 | H9: 201 | I9: 650 | J9: =H9*I9 -> 130650 | K9: 29/30/11 | L9: 394 | M9: 500 | N9: =L9*M9 -> 197000 | O9: =D9+H9+L9 -> 1106 | P9: =F9+J9+N9 -> 583150
A10: 2 | B10: HENDRI SUSILO | C10: 2/1 | D10: 312 | E10: 500 | F10: =D10*E10 -> 156000 | G10: 2 | H10: 176 | I10: 650 | J10: =H10*I10 -> 114400 | K10: 2 | L10: 301 | M10: 500 | N10: =L10*M10 -> 150500 | O10: =D10+H10+L10 -> 789 | P10: =F10+J10+N10 -> 420900
A11: 3 | B11: HERMANSAH | C11: 13/1 | D11: 451 | E11: 500 | F11: =D11*E11 -> 225500 | G11: 13 | H11: 169 | I11: 650 | J11: =H11*I11 -> 109850 | K11: 13 | L11: 274 | M11: 500 | N11: =L11*M11 -> 137000 | O11: =D11+H11+L11 -> 894 | P11: =F11+J11+N11 -> 472350
A12: 4 | B12: JUMADIL AWAL | C12: 18/25 | D12: 334 | E12: 500 | F12: =D12*E12 -> 167000 | G12: 18 | H12: 197 | I12: 650 | J12: =H12*I12 -> 128050 | K12: 18 | L12: 201 | M12: 500 | N12: =L12*M12 -> 100500 | O12: =D12+H12+L12 -> 732 | P12: =F12+J12+N12 -> 395550
A13: 5 | B13: NASRUDIN (SAHNUN) | C13: 17 | D13: 219 | E13: 500 | F13: =D13*E13 -> 109500 | G13: 17 | H13: 189 | I13: 650 | J13: =H13*I13 -> 122850 | K13: 17 | L13: 244 | M13: 500 | N13: =L13*M13 -> 122000 | O13: =D13+H13+L13 -> 652 | P13: =F13+J13+N13 -> 354350
A14: 6 | B14: NASRUDIN (INAK DENI) | C14: 27 | D14: 296 | E14: 500 | F14: =D14*E14 -> 148000 | G14: 27 | H14: 220 | I14: 650 | J14: =H14*I14 -> 143000 | K14: 27 | L14: 161 | M14: 500 | N14: =L14*M14 -> 80500 | O14: =D14+H14+L14 -> 677 | P14: =F14+J14+N14 -> 371500
A15: 7 | B15: SUDIRMAN | C15: 15 | D15: 214 | E15: 500 | F15: =D15*E15 -> 107000 | G15: 15/25/30 | H15: 400 | I15: 650 | J15: =H15*I15 -> 260000 | K15: 15 | L15: 251 | M15: 500 | N15: =L15*M15 -> 125500 | O15: =D15+H15+L15 -> 865 | P15: =F15+J15+N15 -> 492500
A16: 8 | B16: JAYA KUSUMA | C16: 12/11 | D16: 366 | E16: 500 | F16: =D16*E16 -> 183000 | G16: 12/5 | H16: 330 | I16: 650 | J16: =H16*I16 -> 214500 | K16: 12/9/11 | L16: 689 | M16: 500 | N16: =L16*M16 -> 344500 | O16: =D16+H16+L16 -> 1385 | P16: =F16+J16+N16 -> 742000
A17: 9 | B17: LALU HERI ISKANDAR | C17: 28 | D17: 311 | E17: 500 | F17: =D17*E17 -> 155500 | G17: 28 | H17: 190 | I17: 650 | J17: =H17*I17 -> 123500 | K17: 28 | L17: 156 | M17: 500 | N17: =L17*M17 -> 78000 | O17: =D17+H17+L17 -> 657 | P17: =F17+J17+N17 -> 357000
A18: 10 | B18: ZAINAL | C18: 23 | D18: 271 | E18: 500 | F18: =D18*E18 -> 135500 | G18: 23/25 | H18: 429 | I18: 650 | J18: =H18*I18 -> 278850 | K18: 23 | L18: 221 | M18: 500 | N18: =L18*M18 -> 110500 | O18: =D18+H18+L18 -> 921 | P18: =F18+J18+N18 -> 524850
A19: 11 | B19: MUHAMMAD TAHIR | C19: 14 | D19: 210 | E19: 500 | F19: =D19*E19 -> 105000 | G19: 14/1 | H19: 235 | I19: 650 | J19: =H19*I19 -> 152750 | K19: 14 | L19: 284 | M19: 500 | N19: =L19*M19 -> 142000 | O19: =D19+H19+L19 -> 729 | P19: =F19+J19+N19 -> 399750
A20: 12 | B20: TATO | C20: 26 | D20: 298 | E20: 500 | F20: =D20*E20 -> 149000 | G20: 26/11 | H20: 312 | I20: 650 | J20: =H20*I20 -> 202800 | K20: 26/25/25 | L20: 600 | M20: 500 | N20: =L20*M20 -> 300000 | O20: =D20+H20+L20 -> 1210 | P20: =F20+J20+N20 -> 651800
A21: 13 | B21: AGUS SURYADI | C21: 21 | D21: 254 | E21: 500 | F21: =D21*E21 -> 127000 | G21: 21 | H21: 290 | I21: 650 | J21: =H21*I21 -> 188500 | K21: 21 | L21: 202 | M21: 500 | N21: =L21*M21 -> 101000 | O21: =D21+H21+L21 -> 746 | P21: =F21+J21+N21 -> 416500
A22: 14 | B22: ALMAN | C22: 6/5/9 | D22: 777 | E22: 500 | F22: =D22*E22 -> 388500 | G22: 6/1 | H22: 261 | I22: 650 | J22: =H22*I22 -> 169650 | K22: 6/1 | L22: 434 | M22: 500 | N22: =L22*M22 -> 217000 | O22: =D22+H22+L22 -> 1472 | P22: =F22+J22+N22 -> 775150
A23: 15 | B23: HERI SUTANTO | C23: 10/11 | D23: 323 | E23: 500 | F23: =D23*E23 -> 161500 | G23: 10/9/11 | H23: 371 | I23: 650 | J23: =H23*I23 -> 241150 | K23: 10/1 | L23: 411 | M23: 500 | N23: =L23*M23 -> 205500 | O23: =D23+H23+L23 -> 1105 | P23: =F23+J23+N23 -> 608150
A24: 17 | B24: AWALUDIN | C24: 19/25 | D24: 377 | E24: 500 | F24: =D24*E24 -> 188500 | G24: 19 | H24: 198 | I24: 650 | J24: =H24*I24 -> 128700 | K24: 19 | L24: 194 | M24: 500 | N24: =L24*M24 -> 97000 | O24: =D24+H24+L24 -> 769 | P24: =F24+J24+N24 -> 414200
A25: 18 | B25: AHYAR RASIDI | C25: 20 | D25: 202 | E25: 500 | F25: =D25*E25 -> 101000 | G25: 20 | H25: 187 | I25: 650 | J25: =H25*I25 -> 121550 | K25: 20 | L25: 186 | M25: 500 | N25: =L25*M25 -> 93000 | O25: =D25+H25+L25 -> 575 | P25: =F25+J25+N25 -> 315550
A26: 19 | B26: PAUZIWADI | C26: 16 | D26: 202 | E26: 500 | F26: =D26*E26 -> 101000 | G26: 16 | H26: 171 | I26: 650 | J26: =H26*I26 -> 111150 | K26: 16 | L26: 211 | M26: 500 | N26: =L26*M26 -> 105500 | O26: =D26+H26+L26 -> 584 | P26: =F26+J26+N26 -> 317650
A27: 20 | B27: AGUS SATRIAWAN | C27: 3 | D27: 232 | E27: 500 | F27: =D27*E27 -> 116000 | G27: 3 | H27: 181 | I27: 650 | J27: =H27*I27 -> 117650 | K27: 3 | L27: 293 | M27: 500 | N27: =L27*M27 -> 146500 | O27: =D27+H27+L27 -> 706 | P27: =F27+J27+N27 -> 380150
A28: 21 | B28: ZAINUL | C28: 4 | D28: 249 | E28: 500 | F28: =D28*E28 -> 124500 | G28: 4 | H28: 170 | I28: 650 | J28: =H28*I28 -> 110500 | K28: 4 | L28: 298 | M28: 500 | N28: =L28*M28 -> 149000 | O28: =D28+H28+L28 -> 717 | P28: =F28+J28+N28 -> 384000
A29: 22 | B29: M. EZAN FAHRI | C29: 22 | D29: 241 | E29: 500 | F29: =D29*E29 -> 120500 | G29: 22 | H29: 292 | I29: 650 | J29: =H29*I29 -> 189800 | K29: 22 | L29: 201 | M29: 500 | N29: =L29*M29 -> 100500 | O29: =D29+H29+L29 -> 734 | P29: =F29+J29+N29 -> 410800
A30: 23 | B30: TAHARUDIN | C30: 24 | D30: 270 | E30: 500 | F30: =D30*E30 -> 135000 | G30: 24 | H30: 286 | I30: 650 | J30: =H30*I30 -> 185900 | K30: 24 | L30: 219 | M30: 500 | N30: =L30*M30 -> 109500 | O30: =D30+H30+L30 -> 775 | P30: =F30+J30+N30 -> 430400
A31: 24 | B31: ANDREAN AGUSTIN HADI | C31: 8 | D31: 260 | E31: 500 | F31: =D31*E31 -> 130000 | G31: 8 | H31: 160 | I31: 650 | J31: =H31*I31 -> 104000 | K31: 8 | L31: 294 | M31: 500 | N31: =L31*M31 -> 147000 | O31: =D31+H31+L31 -> 714 | P31: =F31+J31+N31 -> 381000
A32: 25 | B32: HAMDI | C32: 7 | D32: 260 | E32: 500 | F32: =D32*E32 -> 130000 | G32: 7 | H32: 161 | I32: 650 | J32: =H32*I32 -> 104650 | K32: 7 | L32: 296 | M32: 500 | N32: =L32*M32 -> 148000 | O32: =D32+H32+L32 -> 717 | P32: =F32+J32+N32 -> 382650
A33: 28 | F33: =D33*E33 -> 0 | J33: =H33*I33 -> 0 | N33: =L33*M33 -> 0 | O33: =D33+H33+J33+N33 -> 0 | P33: =O33*$P$5 -> 0
A34: 29 | F34: =D34*E34 -> 0 | J34: =H34*I34 -> 0 | N34: =L34*M34 -> 0 | O34: =D34+H34+J34+N34 -> 0 | P34: =O34*$P$5 -> 0
A35: 30 | F35: =D35*E35 -> 0 | J35: =H35*I35 -> 0 | N35: =L35*M35 -> 0 | O35: =D35+H35+J35+N35 -> 0 | P35: =O35*$P$5 -> 0
A36: Total | D36: =SUM(D9:D35) -> 7440 | F36: =SUM(F9:F35) -> 3720000 | H36: =SUM(H9:H35) -> 5776 | J36: =SUM(J9:J35) -> 3754400 | L36: =SUM(L9:L35) -> 7015 | N36: =SUM(N9:N35) -> 3507500 | O36: =SUM(O9:O35) -> 20231 | P36: =SUM(P9:P35) -> 10981900
D37: 8452 | H37: 6775 | L37: 5549 | O37: =D36+H36+L36 -> 20231
D38: =D36-D37 -> -1012 | H38: =H36-H37 -> -999 | L38: =L36-L37 -> 1466 | O38: =O36-O37 -> 0
A39: SUMMARY BLOCK
A40: ARE B2 ( AIK BANGEK)
...

Sheet INSETIF MEI'25
A1: PT. REBINMAS JAYA
A2: AIR RUAK ESTATE B2
A3: DAFTAR PREMI INSENTIVE PANEN ARE B2 (AIR BANGEK)
A5: NO. | B5: NAMA PEMANEN | C5: ARE B2 (AIR BANGEK) | H5: BANTU ARE B1 TIMUR | K5: TOTAL TON | L5: INSENTIVE PREMI | M5: KETERANGAN | N5: RANK | O5: JANJANG
C6: PANEN | H6: PANEN | Q6: RUMUS
C7: JJG | D7: KONTANAN | E7: TOTAL JJG | F7: BJR | G7: TON | H7: JJG | I7: BJR | J7: TON
A8: 1 | B8: ='MONITORING '!B7 -> JUMIN | C8: =O8-H8 -> 2252 | E8: =C8+D8 -> 2252 | F8: 15.1 | G8: =E8*F8/1000 -> 34.0052 | J8: =H8*I8/1000 -> 0 | K8: =G8+J8 -> 34.0052 | L8: =VLOOKUP(K8,$R$8:$S$13,2) -> 300000 | N8: =RANK(O8,$O$8:$O$36,0) -> 5 | O8: ='MONITORING '!AI11 -> 2252 | R8: 0
A9: 2 | B9: ='MONITORING '!B20 -> HENDRI SUSILO | C9: =O9-H9 -> 1866 | E9: =C9+D9 -> 1866 | F9: 15.1 | G9: =E9*F9/1000 -> 28.1766 | J9: =H9*I9/1000 -> 0 | K9: =G9+J9 -> 28.1766 | L9: =VLOOKUP(K9,$R$8:$S$13,2) -> 150000 | N9: =RANK(O9,$O$8:$O$36,0) -> 10 | O9: ='MONITORING '!AI24 -> 1866 | Q9: 25,00-30,00 | R9: 25 | S9: 150000
A10: 3 | B10: ='MONITORING '!B33 -> HERMANSAH | C10: =O10-H10 -> 2234 | E10: =C10+D10 -> 2234 | F10: 15.1 | G10: =E10*F10/1000 -> 33.7334 | J10: =H10*I10/1000 -> 0 | K10: =G10+J10 -> 33.7334 | L10: =VLOOKUP(K10,$R$8:$S$13,2) -> 300000 | N10: =RANK(O10,$O$8:$O$36,0) -> 6 | O10: ='MONITORING '!AI37 -> 2234 | Q10: 30,01-45,00 | R10: 30.01 | S10: 300000
A11: 4 | B11: ='MONITORING '!B46 -> JUMADIL AWAL | C11: =O11-H11 -> 1699 | E11: =C11+D11 -> 1699 | F11: 15.1 | G11: =E11*F11/1000 -> 25.6549 | J11: =H11*I11/1000 -> 0 | K11: =G11+J11 -> 25.6549 | L11: =VLOOKUP(K11,$R$8:$S$13,2) -> 150000 | M11: ADA SP | N11: =RANK(O11,$O$8:$O$36,0) -> 15 | O11: ='MONITORING '!AI50 -> 1699 | Q11: 45,01-55,00 | R11: 45.01 | S11: 750000
A12: 5 | B12: ='MONITORING '!B59 -> NASRUDIN (SAHNUN) | C12: =O12-H12 -> 1669 | E12: =C12+D12 -> 1669 | F12: 15.1 | G12: =E12*F12/1000 -> 25.2019 | J12: =H12*I12/1000 -> 0 | K12: =G12+J12 -> 25.2019 | L12: =VLOOKUP(K12,$R$8:$S$13,2) -> 150000 | M12: ADA SP | N12: =RANK(O12,$O$8:$O$36,0) -> 17 | O12: ='MONITORING '!AI63 -> 1669 | Q12: 55,01-65,00 | R12: 55.01 | S12: 950000
A13: 6 | B13: ='MONITORING '!B72 -> NASRUDIN (INAK DENI) | C13: =O13-H13 -> 2191 | E13: =C13+D13 -> 2191 | F13: 15.1 | G13: =E13*F13/1000 -> 33.0841 | J13: =H13*I13/1000 -> 0 | K13: =G13+J13 -> 33.0841 | L13: =VLOOKUP(K13,$R$8:$S$13,2) -> 300000 | M13: ADA SP | N13: =RANK(O13,$O$8:$O$36,0) -> 7 | O13: ='MONITORING '!AI76 -> 2191 | Q13: 65,01-75 TON | R13: 65.01 | S13: 1150000
A14: 7 | B14: ='MONITORING '!B85 -> SUDIRMAN | C14: =O14-H14 -> 2308 | E14: =C14+D14 -> 2308 | F14: 15.1 | G14: =E14*F14/1000 -> 34.8508 | J14: =H14*I14/1000 -> 0 | K14: =G14+J14 -> 34.8508 | L14: =VLOOKUP(K14,$R$8:$S$13,2) -> 300000 | N14: =RANK(O14,$O$8:$O$36,0) -> 3 | O14: ='MONITORING '!AI89 -> 2308
A15: 8 | B15: ='MONITORING '!B98 -> JAYA KUSUMA | C15: =O15-H15 -> 2683 | E15: =C15+D15 -> 2683 | F15: 15.1 | G15: =E15*F15/1000 -> 40.5133 | J15: =H15*I15/1000 -> 0 | K15: =G15+J15 -> 40.5133 | L15: =VLOOKUP(K15,$R$8:$S$13,2) -> 300000 | N15: =RANK(O15,$O$8:$O$36,0) -> 1 | O15: ='MONITORING '!AI102 -> 2683
A16: 9 | B16: ='MONITORING '!B111 -> LALU HERI ISKANDAR | C16: =O16-H16 -> 1748 | E16: =C16+D16 -> 1748 | F16: 15.1 | G16: =E16*F16/1000 -> 26.3948 | J16: =H16*I16/1000 -> 0 | K16: =G16+J16 -> 26.3948 | L16: =VLOOKUP(K16,$R$8:$S$13,2) -> 150000 | N16: =RANK(O16,$O$8:$O$36,0) -> 14 | O16: ='MONITORING '!AI115 -> 1748
A17: 10 | B17: ='MONITORING '!B124 -> ZAINAL | C17: =O17-H17 -> 1884 | E17: =C17+D17 -> 1884 | F17: 15.1 | G17: =E17*F17/1000 -> 28.4484 | J17: =H17*I17/1000 -> 0 | K17: =G17+J17 -> 28.4484 | L17: =VLOOKUP(K17,$R$8:$S$13,2) -> 150000 | M17: ADA SP | N17: =RANK(O17,$O$8:$O$36,0) -> 9 | O17: ='MONITORING '!AI128 -> 1884
A18: 11 | B18: ='MONITORING '!B137 -> MUHAMMAD TAHIR | C18: =O18-H18 -> 1775 | E18: =C18+D18 -> 1775 | F18: 15.1 | G18: =E18*F18/1000 -> 26.8025 | J18: =H18*I18/1000 -> 0 | K18: =G18+J18 -> 26.8025 | L18: =VLOOKUP(K18,$R$8:$S$13,2) -> 150000 | N18: =RANK(O18,$O$8:$O$36,0) -> 12 | O18: ='MONITORING '!AI141 -> 1775
A19: 12 | B19: ='MONITORING '!B150 -> TATO | C19: =O19-H19 -> 2628 | E19: =C19+D19 -> 2628 | F19: 15.1 | G19: =E19*F19/1000 -> 39.6828 | J19: =H19*I19/1000 -> 0 | K19: =G19+J19 -> 39.6828 | L19: =VLOOKUP(K19,$R$8:$S$13,2) -> 300000 | M19: ADA SP | N19: =RANK(O19,$O$8:$O$36,0) -> 2 | O19: ='MONITORING '!AI154 -> 2628
A20: 13 | B20: ='MONITORING '!B163 -> AGUS SURYADI | C20: =O20-H20 -> 1680 | E20: =C20+D20 -> 1680 | F20: 15.1 | G20: =E20*F20/1000 -> 25.368 | J20: =H20*I20/1000 -> 0 | K20: =G20+J20 -> 25.368 | L20: =VLOOKUP(K20,$R$8:$S$13,2) -> 150000 | N20: =RANK(O20,$O$8:$O$36,0) -> 16 | O20: ='MONITORING '!AI167 -> 1680
A21: 14 | B21: ='MONITORING '!B176 -> ALMAN | C21: =O21-H21 -> 2293 | E21: =C21+D21 -> 2293 | F21: 15.1 | G21: =E21*F21/1000 -> 34.6243 | J21: =H21*I21/1000 -> 0 | K21: =G21+J21 -> 34.6243 | L21: =VLOOKUP(K21,$R$8:$S$13,2) -> 300000 | N21: =RANK(O21,$O$8:$O$36,0) -> 4 | O21: ='MONITORING '!AI180 -> 2293
A22: 15 | B22: ='MONITORING '!B189 -> HERI SUTANTO | C22: =O22-H22 -> 1820 | E22: =C22+D22 -> 1820 | F22: 15.1 | G22: =E22*F22/1000 -> 27.482 | J22: =H22*I22/1000 -> 0 | K22: =G22+J22 -> 27.482 | L22: =VLOOKUP(K22,$R$8:$S$13,2) -> 150000 | N22: =RANK(O22,$O$8:$O$36,0) -> 11 | O22: ='MONITORING '!AI193 -> 1820
A23: 16 | B23: ='MONITORING '!B202 -> SUPRIYONO | C23: =O23-H23 -> 1456 | E23: =C23+D23 -> 1456 | F23: 15.1 | G23: =E23*F23/1000 -> 21.9856 | J23: =H23*I23/1000 -> 0 | K23: =G23+J23 -> 21.9856 | L23: =VLOOKUP(K23,$R$8:$S$13,2) -> 0 | N23: =RANK(O23,$O$8:$O$36,0) -> 24 | O23: ='MONITORING '!AI206 -> 1456
A24: 17 | B24: ='MONITORING '!B215 -> AWALUDIN ( INUN ) | C24: =O24-H24 -> 1552 | E24: =C24+D24 -> 1552 | F24: 15.1 | G24: =E24*F24/1000 -> 23.4352 | J24: =H24*I24/1000 -> 0 | K24: =G24+J24 -> 23.4352 | L24: =VLOOKUP(K24,$R$8:$S$13,2) -> 0 | N24: =RANK(O24,$O$8:$O$36,0) -> 21 | O24: ='MONITORING '!AI219 -> 1552
A25: 18 | B25: ='MONITORING '!B228 -> AHYAR RASIDI | C25: =O25-H25 -> 1910 | E25: =C25+D25 -> 1910 | F25: 15.1 | G25: =E25*F25/1000 -> 28.841 | J25: =H25*I25/1000 -> 0 | K25: =G25+J25 -> 28.841 | L25: =VLOOKUP(K25,$R$8:$S$13,2) -> 150000 | M25: ADA SP | N25: =RANK(O25,$O$8:$O$36,0) -> 8 | O25: ='MONITORING '!AI232 -> 1910
A26: 19 | B26: ='MONITORING '!B241 -> PAUZIWADI | C26: =O26-H26 -> 1770 | E26: =C26+D26 -> 1770 | F26: 15.1 | G26: =E26*F26/1000 -> 26.727 | J26: =H26*I26/1000 -> 0 | K26: =G26+J26 -> 26.727 | L26: =VLOOKUP(K26,$R$8:$S$13,2) -> 150000 | M26: ADA SP | N26: =RANK(O26,$O$8:$O$36,0) -> 13 | O26: ='MONITORING '!AI245 -> 1770
A27: 20 | B27: ='MONITORING '!B254 -> AGUS SATRIAWAN | C27: =O27-H27 -> 1567 | E27: =C27+D27 -> 1567 | F27: 15.1 | G27: =E27*F27/1000 -> 23.6617 | J27: =H27*I27/1000 -> 0 | K27: =G27+J27 -> 23.6617 | L27: =VLOOKUP(K27,$R$8:$S$13,2) -> 0 | N27: =RANK(O27,$O$8:$O$36,0) -> 19 | O27: ='MONITORING '!AI258 -> 1567
A28: 21 | B28: ='MONITORING '!B267 -> ZAINUL | C28: =O28-H28 -> 1499 | E28: =C28+D28 -> 1499 | F28: 15.1 | G28: =E28*F28/1000 -> 22.6349 | J28: =H28*I28/1000 -> 0 | K28: =G28+J28 -> 22.6349 | L28: =VLOOKUP(K28,$R$8:$S$13,2) -> 0 | N28: =RANK(O28,$O$8:$O$36,0) -> 22 | O28: ='MONITORING '!AI271 -> 1499
A29: 22 | B29: ='MONITORING '!B280 -> M. EZAN FARIZI | C29: =O29-H29 -> 1489 | E29: =C29+D29 -> 1489 | F29: 15.1 | G29: =E29*F29/1000 -> 22.4839 | J29: =H29*I29/1000 -> 0 | K29: =G29+J29 -> 22.4839 | L29: =VLOOKUP(K29,$R$8:$S$13,2) -> 0 | N29: =RANK(O29,$O$8:$O$36,0) -> 23 | O29: ='MONITORING '!AI284 -> 1489
A30: 23 | B30: ='MONITORING '!B293 -> TAHARUDIN | C30: =O30-H30 -> 1632 | E30: =C30+D30 -> 1632 | F30: 15.1 | G30: =E30*F30/1000 -> 24.6432 | J30: =H30*I30/1000 -> 0 | K30: =G30+J30 -> 24.6432 | L30: =VLOOKUP(K30,$R$8:$S$13,2) -> 0 | N30: =RANK(O30,$O$8:$O$36,0) -> 18 | O30: ='MONITORING '!AI297 -> 1632
A31: 24 | B31: ='MONITORING '!B306 -> ANDREAN AUSTIN HADI | C31: =O31-H31 -> 1444 | E31: =C31+D31 -> 1444 | F31: 15.1 | G31: =E31*F31/1000 -> 21.8044 | J31: =H31*I31/1000 -> 0 | K31: =G31+J31 -> 21.8044 | L31: =VLOOKUP(K31,$R$8:$S$13,2) -> 0 | N31: =RANK(O31,$O$8:$O$36,0) -> 25 | O31: ='MONITORING '!AI310 -> 1444
A32: 25 | B32: ='MONITORING '!B319 -> HAMDI | C32: =O32-H32 -> 1564 | E32: =C32+D32 -> 1564 | F32: 15.1 | G32: =E32*F32/1000 -> 23.6164 | J32: =H32*I32/1000 -> 0 | K32: =G32+J32 -> 23.6164 | L32: =VLOOKUP(K32,$R$8:$S$13,2) -> 0 | N32: =RANK(O32,$O$8:$O$36,0) -> 20 | O32: ='MONITORING '!AI323 -> 1564
A33: 26 | B33: ='MONITORING '!B332 -> SOPIAN HADI | C33: =O33-H33 -> 351 | E33: =C33+D33 -> 351 | F33: 15.1 | G33: =E33*F33/1000 -> 5.3001 | J33: =H33*I33/1000 -> 0 | K33: =G33+J33 -> 5.3001 | L33: =VLOOKUP(K33,$R$8:$S$13,2) -> 0 | N33: =RANK(O33,$O$8:$O$36,0) -> 28 | O33: ='MONITORING '!AI336 -> 351
A34: 27 | B34: ='MONITORING '!B345 -> MASRON | C34: =O34-H34 -> 455 | E34: =C34+D34 -> 455 | F34: 15.1 | G34: =E34*F34/1000 -> 6.8705 | J34: =H34*I34/1000 -> 0 | K34: =G34+J34 -> 6.8705 | L34: =VLOOKUP(K34,$R$8:$S$13,2) -> 0 | N34: =RANK(O34,$O$8:$O$36,0) -> 27 | O34: ='MONITORING '!AI349 -> 455
A35: 28 | B35: ='MONITORING '!B358 -> HERIYANTO | C35: =O35-H35 -> 904 | E35: =C35+D35 -> 904 | F35: 15.1 | G35: =E35*F35/1000 -> 13.6504 | J35: =H35*I35/1000 -> 0 | K35: =G35+J35 -> 13.6504 | L35: =VLOOKUP(K35,$R$8:$S$13,2) -> 0 | N35: =RANK(O35,$O$8:$O$36,0) -> 26 | O35: ='MONITORING '!AI362 -> 904
A36: 29 | B36: ='MONITORING '!B371 -> ADI SUSANTO | C36: =O36-H36 -> 31 | E36: =C36+D36 -> 31 | F36: 15.1 | G36: =E36*F36/1000+0.13 -> 0.5981 | J36: =H36*I36/1000 -> 0 | K36: =G36+J36 -> 0.5981 | L36: =VLOOKUP(K36,$R$8:$S$13,2) -> 0 | N36: =RANK(O36,$O$8:$O$36,0) -> 29 | O36: ='MONITORING '!AI375 -> 31
A37: 30 | B37: ='MONITORING '!B384 -> 0 | C37: =O37-H37 -> 0 | E37: =C37+D37 -> 0 | G37: =E37*F37/1000 -> 0 | J37: =H37*I37/1000 -> 0 | K37: =G37+J37 -> 0 | L37: =VLOOKUP(K37,$R$8:$S$13,2) -> 0 | N37: =RANK(O37,$O$8:$O$36,0) -> #N/A | O37: ='MONITORING '!AI388 -> 0
A38: 31 | B38: ='MONITORING '!B397 -> 0 | E38: =C38+D38 -> 0 | G38: =E38*F38/1000 -> 0 | J38: =H38*I38/1000 -> 0 | K38: =G38+J38 -> 0 | L38: =VLOOKUP(K38,$R$8:$S$13,2) -> 0 | N38: =RANK(O38,$O$8:$O$36,0) -> #N/A | O38: ='MONITORING '!AI401 -> 0
A39: 32 | B39: ='MONITORING '!B410 -> 0 | C39: =O39-H39 -> 0 | E39: =C39+D39 -> 0 | G39: =E39*F39/1000 -> 0 | J39: =H39*I39/1000 -> 0 | K39: =G39+J39 -> 0 | L39: =VLOOKUP(K39,$R$8:$S$13,2) -> 0 | N39: =RANK(O39,$O$8:$O$36,0) -> #N/A | O39: ='MONITORING '!AI414 -> 0
A40: 33 | B40: ='MONITORING '!B423 -> 0 | E40: =C40+D40 -> 0 | G40: =E40*F40/1000 -> 0 | J40: =H40*I40/1000 -> 0 | K40: =G40+J40 -> 0 | L40: =VLOOKUP(K40,$R$8:$S$13,2) -> 0 | N40: =RANK(O40,$O$8:$O$36,0) -> #N/A | O40: ='MONITORING '!AI427 -> 0
A41: 34 | B41: ='MONITORING '!B436 -> 0 | E41: =C41+D41 -> 0 | G41: =E41*F41/1000 -> 0 | J41: =H41*I41/1000 -> 0 | K41: =G41+J41 -> 0 | L41: =VLOOKUP(K41,$R$8:$S$13,2) -> 0 | N41: =RANK(O41,$O$8:$O$36,0) -> #N/A | O41: ='MONITORING '!AI440 -> 0 | AA41: =836.28-836.37 -> -0.09
...

Sheet MONITORING 
A1: PT. REBINMAS JAYA
A3: MONITORING HASIL PANEN
A4: BULAN : MEI 2025 | E4: 129220 | F4: 129220 | T4: 129220 | AH4: 121333.33
A5: NO. | B5: ITEM | C5: TGL MASUK KERJA | D5: T A N G G A L | AI5: TOTAL | AJ5: HARGA PREMI | AK5: TOTAL PREMI
D6: 1 | E6: 2 | F6: 3 | G6: 4 | H6: 5 | I6: 6 | J6: 7 | K6: 8 | L6: 9 | M6: 10 | N6: 11 | O6: 12 | P6: 13 | Q6: 14 | R6: 15 | S6: 16 | T6: 17 | U6: 18 | V6: 19 | W6: 20 | X6: 21 | Y6: 22 | Z6: 23 | AA6: 24 | AB6: 25 | AC6: 26 | AD6: 27 | AE6: 28 | AF6: 29 | AG6: 30 | AH6: 31 | AM6: POKOK
A7: 1 | B7: JUMIN | C7: 08-12-2014 | E7: 1 | F7: 1 | H7: 1 | I7: 1 | J7: 1 | K7: 1 | L7: 1 | M7: 1 | P7: 1 | Q7: 1 | R7: 1 | S7: 1 | T7: 1 | V7: 1 | W7: 1 | X7: 1 | Y7: 1 | Z7: 1 | AA7: 1 | AC7: 1 | AD7: 1 | AE7: 1 | AG7: 1 | AH7: 1 | AI7: =SUM(D7:AH7) -> 24
B8: BLOCK | E8: P9802 | F8: P9802 P9803 | H8: P0901 | J8: P0808 P9801 | K8: P0811 | L8: P9802 | M8: P9803 | P8: P0901 | Q8: P0902 | R8: P0806 | S8: P0807 | T8: P0808 | V8: P9802 | W8: P0901 P0902 P9803 | X8: P0806 P0902 | Y8: P0806 P0807 P9801 | Z8: P0808 P0811 | AA8: P9802 | AC8: P9802 P9803 | AD8: P0901 P0902 | AE8: P0806 P0902 | AG8: P0806 | AH8: P0808 P9801
B9: ANCAK | E9: 29/30/27/28 | F9: 30/29 | H9: 25/29/30 | J9: 29/30 | K9: 29 | L9: 29/30 | M9: 29/30 | P9: 29 | Q9: 29/30 | R9: 29 | S9: 29/30 | T9: 29 | V9: 29/30 | W9: 29 | X9: 29/30 | Y9: 29/30 | Z9: 29/30 | AA9: 30 | AC9: 29 | AD9: 29/30 | AE9: 29/30 | AG9: 29/30 | AH9: 29
B10: BASIC | E10: 90 | F10: 90 | H10: 103 | J10: 103 | K10: 103 | L10: 90 | M10: 90 | P10: 103 | Q10: 114 | R10: 114 | S10: 103 | T10: 103 | V10: 90 | W10: 103 | X10: 114 | Y10: 114 | Z10: 103 | AA10: 90 | AC10: 90 | AD10: 103 | AE10: 114 | AG10: 114 | AH10: 103 | AI10: =SUM(D10:AH10) -> 2344
B11: JANJANG | E11: 150 | F11: 75 | H11: 190 | J11: 58 | K11: 62 | L11: 37 | M11: 57 | P11: 74 | Q11: 101 | R11: 79 | S11: =212+13 -> 225 | T11: =74+2 -> 76 | V11: 166 | W11: 100 | X11: =102+3+5 -> 110 | Y11: =80+1+6 -> 87 | Z11: 56 | AA11: =39+6 -> 45 | AC11: =65+3 -> 68 | AD11: =68+2 -> 70 | AE11: 121 | AG11: =178+11 -> 189 | AH11: 56 | AI11: =SUM(D11:AH11) -> 2252 | AL11: 1648 | AM11: =AI11-AL11 -> 604
B12: PREMI (BASIS 90) | E12: =E11-E10 -> 60 | V12: =V11-V10 -> 76 | AI12: =SUM(D12:AH12) -> 136 | AJ12: 1409 | AK12: =AI12*AJ12 -> 191624
B13: PREMI (BASIS 103) | H13: =H11-H10 -> 87 | S13: =S11-S10 -> 122 | AI13: =SUM(D13:AH13) -> 209 | AJ13: 1322 | AK13: =AI13*AJ13 -> 276298
B14: PREMI (BASIS 114) | AE14: =AE11-AE10 -> 7 | AG14: =AG11-AG10 -> 75 | AI14: =SUM(D14:AH14) -> 82 | AJ14: 1233 | AK14: =AI14*AJ14 -> 101106
B15: PREMI (BASIS 154) | AI15: =SUM(D15:AH15) -> 0 | AJ15: 1043 | AK15: =AI15*AJ15 -> 0
B16: PREMI (BASIS ) | AI16: =SUM(D16:AH16) -> 0 | AK16: =AI16*AJ16 -> 0
B17: TOTAL PREMI | AI17: =SUM(D17:AH17) -> 0 | AK17: =SUM(AK12:AK16) -> 569028
B18: BRONDOL | E18: 15 | F18: 6 | H18: 27 | J18: 4 | K18: 5 | L18: 5 | M18: 9 | P18: 9 | Q18: 6 | R18: 6 | S18: 21 | T18: 11 | V18: 23 | W18: 10 | X18: 6 | Y18: 18 | Z18: 14 | AA18: 8 | AC18: 9 | AD18: 12 | AE18: 10 | AG18: 27 | AH18: 12 | AI18: =SUM(D18:AH18) -> 273 | AJ18: 1750 | AK18: =AI18*AJ18 -> 477750 | AL18: 233 | AM18: =AI18-AL18 -> 40
B19: KOREKSI | AI19: =SUM(D19:AH19) -> 0 | AK19: =AI19 -> 0
A20: 2 | B20: HENDRI SUSILO | C20: 23-09-2019 | E20: 1 | F20: 1 | H20: 1 | I20: 1 | J20: 1 | K20: 1 | L20: 1 | M20: 1 | P20: 1 | Q20: 1 | R20: 1 | S20: 1 | T20: 1 | V20: 1 | W20: 1 | X20: 1 | Y20: 1 | Z20: 1 | AA20: 1 | AC20: 1 | AD20: 1 | AE20: 1 | AG20: 1 | AH20: 1 | AI20: =SUM(D20:AH20) -> 24
B21: BLOCK | E21: P0811 | F21: P9803 | H21: P0901 P0902 | I21: P0807 | J21: P0808 P9801 | K21: P0811 | L21: P9802 | M21: P9803 | P21: P0901 P0902 | Q21: P0902 | R21: P0807 | S21: P0807 P0808 P9801 | T21: P0811 | V21: P9802 | W21: P0901 P9802 | X21: P0806 P0902 | Y21: P0806 P0807 P9801 | Z21: P0808 P0811 | AA21: P0811 P9802 | AC21: P9802 P9803 | AD21: P0901 P0902 | AE21: P0806 P0902 | AG21: P0806 P0807 P9801 | AH21: P0808 P0811
B22: ANCAK | E22: 1/2 | F22: 2 | H22: 1/2 | I22: 2/1 | J22: 2/1 | K22: 2 | L22: 1/2 | M22: 1/2 | P22: 2/13 | Q22: 1/2 | R22: 2/1 | S22: 2 | T22: 2 | V22: 2/1 | W22: 1/2 | X22: 1/2 | Y22: 1/2 | Z22: 1/2 | AA22: 1/2 | AC22: 2 | AD22: 2 | AE22: 1/2 | AG22: 2/1 | AH22: 2
B23: BASIC | E23: 103 | F23: 90 | H23: 103 | I23: 103 | J23: 103 | K23: 13 | L23: 90 | M23: 90 | P23: 103 | Q23: 114 | R23: 103 | S23: 103 | T23: 103 | V23: 90 | W23: 103 | X23: 114 | Y23: 114 | Z23: 103 | AA23: 103 | AC23: 90 | AD23: 103 | AE23: 114 | AG23: 114 | AH23: 103 | AI23: =SUM(D23:AH23) -> 2372
B24: JANJANG | E24: 150 | F24: 40 | H24: 83 | I24: 127 | J24: 127 | K24: 40 | L24: 33 | M24: 28 | P24: 53 | Q24: 162 | R24: 128 | S24: 55 | T24: 40 | V24: 130 | W24: 57 | X24: 60 | Y24: =99+2 -> 101 | Z24: 73 | AA24: 19 | AC24: 49 | AD24: =42+2 -> 44 | AE24: 105 | AG24: 109 | AH24: 53 | AI24: =SUM(D24:AH24) -> 1866 | AL24: 4439 | AM24: =AI24-AL24 -> -2573
B25: PREMI (BASIS 90) | V25: =V24-V23 -> 40 | AI25: =SUM(D25:AH25) -> 40 | AJ25: 1409 | AK25: =AI25*AJ25 -> 56360
B26: PREMI (BASIS 103) | E26: =E24-E23 -> 47 | I26: =I24-I23 -> 24 | J26: =J24-J23 -> 24 | R26: =R24-R23 -> 25 | AI26: =SUM(D26:AH26) -> 120 | AJ26: 1322 | AK26: =AI26*AJ26 -> 158640
B27: PREMI (BASIS 114) | Q27: =Q24-Q23 -> 48 | AI27: =SUM(D27:AH27) -> 48 | AJ27: 1233 | AK27: =AI27*AJ27 -> 59184
B28: PREMI (BASIS 154) | AI28: =SUM(D28:AH28) -> 0 | AJ28: 1043 | AK28: =AI28*AJ28 -> 0
B29: PREMI (BASIS ) | AI29: =SUM(D29:AH29) -> 0 | AK29: =AI29*AJ29 -> 0
B30: TOTAL PREMI | AI30: =SUM(D30:AH30) -> 0 | AK30: =SUM(AK25:AK29) -> 274184
B31: BRONDOL | E31: 9 | F31: 2 | H31: 4 | I31: 9 | J31: 4 | K31: 3 | L31: 4 | M31: 3 | P31: 4 | Q31: 7 | R31: 8 | S31: 3 | T31: 3 | V31: 9 | W31: 3 | X31: 2 | Y31: 4 | Z31: 4 | AA31: 1 | AC31: 3 | AD31: 3 | AE31: 5 | AG31: 6 | AH31: 3 | AI31: =SUM(D31:AH31) -> 106 | AJ31: 1750 | AK31: =AI31*AJ31 -> 185500 | AL31: 469 | AM31: =AI31-AL31 -> -363
B32: KOREKSI | AI32: =SUM(D32:AH32) -> 0 | AK32: =AI32 -> 0
A33: 3 | B33: HERMANSAH | C33: 17-09-2019 | E33: 1 | F33: 1 | H33: 1 | I33: 1 | J33: 1 | K33: 1 | L33: 1 | M33: 1 | P33: 1 | Q33: 1 | R33: 1 | S33: 1 | T33: 1 | V33: 1 | W33: 1 | X33: 1 | Y33: 1 | Z33: 1 | AA33: 1 | AC33: 1 | AD33: 1 | AE33: 1 | AG33: 1 | AH33: 1 | AI33: =SUM(D33:AH33) -> 24
B34: BLOCK | E34: P9802 | F34: P9802 | H34: P9802 | I34: P0902 | J34: P0808 | K34: P0811 | L34: P9802 | M34: P9803 | P34: P0901 P0902 | Q34: P0902 | R34: P0807 | S34: P9801 | T34: P0811 | V34: P9802 | W34: P0901 P0902 P9802 | X34: P0806 | Y34: P0806 P0807 P9801 | Z34: P0808 P0811 | AA34: P0811 P9802 | AC34: P9802 P9803 | AD34: P0901 P0902 | AE34: P0806 P0902 | AG34: P0807 P9801 | AH34: P0808
B35: ANCAK | E35: 13/14 | F35: 2/13/14 | H35: 13/14/1 | I35: 13/25 | J35: 13/14 | K35: 13/14 | L35: 13/14 | M35: 14/12/13 | P35: 13 | Q35: 13/15 | R35: 13 | S35: 13/1 | T35: 13 | V35: 13 | W35: 4/13 | X35: 5/13/1 | Y35: 15/1/3/14 | Z35: 13/9/14 | AA35: 9/13/14 | AC35: 13/14 | AD35: 13/9 | AE35: 9/13/14 | AG35: 1/13 | AH35: 13
B36: BASIC | E36: 90 | F36: 90 | H36: 90 | I36: 114 | J36: 103 | K36: 103 | L36: 90 | M36: 90 | P36: 103 | Q36: 114 | R36: 103 | S36: 90 | T36: 103 | V36: 90 | W36: 103 | X36: 114 | Y36: 114 | Z36: 114 | AA36: 103 | AC36: 90 | AD36: 103 | AE36: 114 | AG36: 103 | AH36: 103 | AI36: =SUM(D36:AH36) -> 2434
B37: JANJANG | E37: 223 | F37: 84 | H37: 150 | I37: 120 | J37: 123 | K37: 66 | L37: 62 | M37: 24 | P37: 63 | Q37: 156 | R37: 108 | S37: =113+2 -> 115 | T37: 78 | V37: 142 | W37: 78 | X37: =161+8 -> 169 | Y37: 73 | Z37: 44 | AA37: 32 | AC37: 71 | AD37: =53+1 -> 54 | AE37: =58+10 -> 68 | AG37: 83 | AH37: 48 | AI37: =SUM(D37:AH37) -> 2234 | AL37: =2967 -> 2967 | AM37: =AI37-AL37 -> -733
B38: PREMI (BASIS 90) | E38: =E37-E36 -> 133 | H38: =H37-H36 -> 60 | S38: =S37-S36 -> 25 | V38: =V37-V36 -> 52 | AI38: =SUM(D38:AH38) -> 270 | AJ38: 1409 | AK38: =AI38*AJ38 -> 380430
B39: PREMI (BASIS 103) | J39: =J37-J36 -> 20 | R39: =R37-R36 -> 5 | AI39: =SUM(D39:AH39) -> 25 | AJ39: 1322 | AK39: =AI39*AJ39 -> 33050
B40: PREMI (BASIS 114) | I40: =I37-I36 -> 6 | Q40: =Q37-Q36 -> 42 | X40: =X37-X36 -> 55 | AI40: =SUM(D40:AH40) -> 103 | AJ40: 1233 | AK40: =AI40*AJ40 -> 126999
B41: PREMI (BASIS 154) | AI41: =SUM(D41:AH41) -> 0 | AJ41: 1043 | AK41: =AI41*AJ41 -> 0
...

Sheet HK PANEN
A1: ABSENSI
A2: KARYAWAN PANEN BHT AIR BANGEK
A3: BULAN : MEI 2025
A4: NO | B4: KARYAWAN | C4: TANGGAL | AH4: TOTAL HK | AI4: JUMLAH CUTI/LIBUR | AP4: JUMLAH | AQ4: CTH | AR4: ALPA
C6: 1 | D6: 2 | E6: 3 | F6: 4 | G6: 5 | H6: 6 | I6: 7 | J6: 8 | K6: 9 | L6: 10 | M6: 11 | N6: 12 | O6: 13 | P6: 14 | Q6: 15 | R6: 16 | S6: 17 | T6: 18 | U6: 19 | V6: 20 | W6: 21 | X6: 22 | Y6: 23 | Z6: 24 | AA6: 25 | AB6: 26 | AC6: 27 | AD6: 28 | AE6: 29 | AF6: 30 | AG6: 31 | AI6: THN | AJ6: SKT | AK6: HAID | AL6: MG | AM6: NAS | AN6: H/M | AO6: IZIN
A7: 1 | B7: AFRIWANTONI | C7: NAS | D7: =COUNTIF(ABSEN!B:B,"AFRIWANTONI ( Yusna Yetti )") -> 1 | E7: =COUNTIF(ABSEN!C:C,"AFRIWANTONI ( Yusna Yetti )") -> 1 | F7: MG | G7: =COUNTIF(ABSEN!E:E,"AFRIWANTONI ( Yusna Yetti )") -> 1 | H7: =COUNTIF(ABSEN!F:F,"AFRIWANTONI ( Yusna Yetti )") -> 1 | I7: CT | J7: =COUNTIF(ABSEN!H:H,"AFRIWANTONI ( Yusna Yetti )") -> 1 | K7: CT | L7: =COUNTIF(ABSEN!J:J,"AFRIWANTONI ( Yusna Yetti )") -> 1 | M7: MG | N7: NAS | O7: S | P7: S | Q7: S | R7: S | S7: =COUNTIF(ABSEN!Q:Q,"AFRIWANTONI ( Yusna Yetti )") -> 1 | T7: MG | U7: =COUNTIF(ABSEN!S:S,"AFRIWANTONI ( Yusna Yetti )") -> 1 | V7: =COUNTIF(ABSEN!T:T,"AFRIWANTONI ( Yusna Yetti )") -> 1 | W7: =COUNTIF(ABSEN!U:U,"AFRIWANTONI ( Yusna Yetti )") -> 1 | X7: =COUNTIF(ABSEN!V:V,"AFRIWANTONI ( Yusna Yetti )") -> 1 | Y7: =COUNTIF(ABSEN!W:W,"AFRIWANTONI ( Yusna Yetti )") -> 1 | Z7: =COUNTIF(ABSEN!X:X,"AFRIWANTONI ( Yusna Yetti )") -> 1 | AA7: MG | AB7: CT | AC7: =COUNTIF(ABSEN!AA:AA,"AFRIWANTONI ( Yusna Yetti )") -> 1 | AD7: =COUNTIF(ABSEN!AB:AB,"AFRIWANTONI ( Yusna Yetti )") -> 1 | AE7: NAS | AF7: =COUNTIF(ABSEN!AD:AD,"AFRIWANTONI ( Yusna Yetti )") -> 1 | AG7: =COUNTIF(ABSEN!AE:AE,"AFRIWANTONI ( Yusna Yetti )") -> 1 | AH7: =SUM(C7:AG7) -> 17 | AI7: =COUNTIF(C7:AG7,"CT") -> 3 | AJ7: =COUNTIF(C7:AG7,"S") -> 4 | AK7: =COUNTIF(C7:AG7,"H1") -> 0 | AL7: =COUNTIF(C7:AG7,"MG") -> 4 | AM7: =COUNTIF(C7:AG7,"NAS") -> 3 | AN7: =COUNTIF(C7:AG7,"H2") -> 0 | AO7: =COUNTIF(C7:AG7,"P1") -> 0 | AP7: =+AH7+AI7+AJ7+AK7+AL7+AM7+AN7+AO7 -> 31 | AQ7: =COUNTIF(C7:AG7,"CTH") -> 0 | AR7: =COUNTIF(C7:AG7,"A") -> 0 | AT7: =AP7-AS7 -> 31
A8: 2 | B8: ROZI SUSANTO | C8: NAS | D8: =COUNTIF(ABSEN!B:B,"ROZI SUSANTO ( SARMINAH )") -> 1 | E8: =COUNTIF(ABSEN!C:C,"ROZI SUSANTO ( SARMINAH )") -> 1 | F8: MG | G8: =COUNTIF(ABSEN!E:E,"ROZI SUSANTO ( SARMINAH )") -> 1 | H8: =COUNTIF(ABSEN!F:F,"ROZI SUSANTO ( SARMINAH )") -> 1 | I8: =COUNTIF(ABSEN!G:G,"ROZI SUSANTO ( SARMINAH )") -> 1 | J8: =COUNTIF(ABSEN!H:H,"ROZI SUSANTO ( SARMINAH )") -> 1 | K8: =COUNTIF(ABSEN!I:I,"ROZI SUSANTO ( SARMINAH )") -> 1 | L8: =COUNTIF(ABSEN!J:J,"ROZI SUSANTO ( SARMINAH )") -> 1 | M8: MG | N8: NAS | O8: =COUNTIF(ABSEN!M:M,"ROZI SUSANTO ( SARMINAH )") -> 1 | P8: =COUNTIF(ABSEN!N:N,"ROZI SUSANTO ( SARMINAH )") -> 1 | Q8: CT | R8: =COUNTIF(ABSEN!P:P,"ROZI SUSANTO ( SARMINAH )") -> 1 | S8: =COUNTIF(ABSEN!Q:Q,"ROZI SUSANTO ( SARMINAH )") -> 1 | T8: MG | U8: =COUNTIF(ABSEN!S:S,"ROZI SUSANTO ( SARMINAH )") -> 1 | V8: =COUNTIF(ABSEN!T:T,"ROZI SUSANTO ( SARMINAH )") -> 1 | W8: =COUNTIF(ABSEN!U:U,"ROZI SUSANTO ( SARMINAH )") -> 1 | X8: =COUNTIF(ABSEN!V:V,"ROZI SUSANTO ( SARMINAH )") -> 1 | Y8: =COUNTIF(ABSEN!W:W,"ROZI SUSANTO ( SARMINAH )") -> 1 | Z8: =COUNTIF(ABSEN!X:X,"ROZI SUSANTO ( SARMINAH )") -> 1 | AA8: MG | AB8: =COUNTIF(ABSEN!Z:Z,"ROZI SUSANTO ( SARMINAH )") -> 1 | AC8: S | AD8: S | AE8: NAS | AF8: =COUNTIF(ABSEN!AD:AD,"ROZI SUSANTO ( SARMINAH )") -> 1 | AG8: =COUNTIF(ABSEN!AE:AE,"ROZI SUSANTO ( SARMINAH )") -> 1 | AH8: =SUM(C8:AG8) -> 21 | AI8: =COUNTIF(C8:AG8,"CT") -> 1 | AJ8: =COUNTIF(C8:AG8,"S") -> 2 | AK8: =COUNTIF(C8:AG8,"H1") -> 0 | AL8: =COUNTIF(C8:AG8,"MG") -> 4 | AM8: =COUNTIF(C8:AG8,"NAS") -> 3 | AN8: =COUNTIF(C8:AG8,"H2") -> 0 | AO8: =COUNTIF(C8:AG8,"P1") -> 0 | AP8: =+AH8+AI8+AJ8+AK8+AL8+AM8+AN8+AO8 -> 31 | AQ8: =COUNTIF(C8:AG8,"CTH") -> 0 | AR8: =COUNTIF(C8:AG8,"A") -> 0 | AT8: =AP8-AS8 -> 31
A9: 3 | B9: SAZELA | C9: NAS | D9: =COUNTIF(ABSEN!B:B,"SAZELA ( MASTINA )") -> 1 | E9: =COUNTIF(ABSEN!C:C,"SAZELA ( MASTINA )") -> 1 | F9: MG | G9: =COUNTIF(ABSEN!E:E,"SAZELA ( MASTINA )") -> 1 | H9: =COUNTIF(ABSEN!F:F,"SAZELA ( MASTINA )") -> 1 | I9: =COUNTIF(ABSEN!G:G,"SAZELA ( MASTINA )") -> 1 | J9: =COUNTIF(ABSEN!H:H,"SAZELA ( MASTINA )") -> 1 | K9: S | L9: S | M9: MG | N9: NAS | O9: =COUNTIF(ABSEN!M:M,"SAZELA ( MASTINA )") -> 1 | P9: =COUNTIF(ABSEN!N:N,"SAZELA ( MASTINA )") -> 1 | Q9: =COUNTIF(ABSEN!O:O,"SAZELA ( MASTINA )") -> 1 | R9: =COUNTIF(ABSEN!P:P,"SAZELA ( MASTINA )") -> 1 | S9: =COUNTIF(ABSEN!Q:Q,"SAZELA ( MASTINA )") -> 1 | T9: MG | U9: H1 | V9: H1 | W9: =COUNTIF(ABSEN!U:U,"SAZELA ( MASTINA )") -> 1 | X9: =COUNTIF(ABSEN!V:V,"SAZELA ( MASTINA )") -> 1 | Y9: =COUNTIF(ABSEN!W:W,"SAZELA ( MASTINA )") -> 1 | Z9: =COUNTIF(ABSEN!X:X,"SAZELA ( MASTINA )") -> 1 | AA9: MG | AB9: =COUNTIF(ABSEN!Z:Z,"SAZELA ( MASTINA )") -> 1 | AC9: =COUNTIF(ABSEN!AA:AA,"SAZELA ( MASTINA )") -> 1 | AD9: =COUNTIF(ABSEN!AB:AB,"SAZELA ( MASTINA )") -> 1 | AE9: NAS | AF9: 1 | AG9: =COUNTIF(ABSEN!AE:AE,"SAZELA ( MASTINA )") -> 1 | AH9: =SUM(C9:AG9) -> 20 | AI9: =COUNTIF(C9:AG9,"CT") -> 0 | AJ9: =COUNTIF(C9:AG9,"S") -> 2 | AK9: =COUNTIF(C9:AG9,"H1") -> 2 | AL9: =COUNTIF(C9:AG9,"MG") -> 4 | AM9: =COUNTIF(C9:AG9,"NAS") -> 3 | AN9: =COUNTIF(C9:AG9,"H2") -> 0 | AO9: =COUNTIF(C9:AG9,"P1") -> 0 | AP9: =+AH9+AI9+AJ9+AK9+AL9+AM9+AN9+AO9 -> 31 | AQ9: =COUNTIF(C9:AG9,"CTH") -> 0 | AR9: =COUNTIF(C9:AG9,"A") -> 0 | AS9: =COUNTIF(C9:AG9,"CTH") -> 0 | AT9: =AP9-AS9 -> 31
A10: 4 | B10: JUMIN | C10: NAS | D10: =COUNTIF(ABSEN!B:B,"JUMIN") -> 1 | E10: =COUNTIF(ABSEN!C:C,"JUMIN") -> 1 | F10: MG | G10: =COUNTIF(ABSEN!E:E,"JUMIN") -> 1 | H10: CT | I10: =COUNTIF(ABSEN!G:G,"JUMIN") -> 1 | J10: =COUNTIF(ABSEN!H:H,"JUMIN") -> 1 | K10: =COUNTIF(ABSEN!I:I,"JUMIN") -> 1 | L10: =COUNTIF(ABSEN!J:J,"JUMIN") -> 1 | M10: MG | N10: NAS | O10: =COUNTIF(ABSEN!M:M,"JUMIN") -> 1 | P10: =COUNTIF(ABSEN!N:N,"JUMIN") -> 1 | Q10: =COUNTIF(ABSEN!O:O,"JUMIN") -> 1 | R10: =COUNTIF(ABSEN!P:P,"JUMIN") -> 1 | S10: =COUNTIF(ABSEN!Q:Q,"JUMIN") -> 1 | T10: MG | U10: =COUNTIF(ABSEN!S:S,"JUMIN") -> 1 | V10: =COUNTIF(ABSEN!T:T,"JUMIN") -> 1 | W10: =COUNTIF(ABSEN!U:U,"JUMIN") -> 1 | X10: =COUNTIF(ABSEN!V:V,"JUMIN") -> 1 | Y10: =COUNTIF(ABSEN!W:W,"JUMIN") -> 1 | Z10: =COUNTIF(ABSEN!X:X,"JUMIN") -> 1 | AA10: MG | AB10: =COUNTIF(ABSEN!Z:Z,"JUMIN") -> 1 | AC10: =COUNTIF(ABSEN!AA:AA,"JUMIN") -> 1 | AD10: =COUNTIF(ABSEN!AB:AB,"JUMIN") -> 1 | AE10: NAS | AF10: =COUNTIF(ABSEN!AD:AD,"JUMIN") -> 1 | AG10: =COUNTIF(ABSEN!AE:AE,"JUMIN") -> 1 | AH10: =SUM(C10:AG10) -> 23 | AI10: =COUNTIF(C10:AG10,"CT") -> 1 | AJ10: =COUNTIF(C10:AG10,"S") -> 0 | AK10: =COUNTIF(C10:AG10,"H1") -> 0 | AL10: =COUNTIF(C10:AG10,"MG") -> 4 | AM10: =COUNTIF(C10:AG10,"NAS") -> 3 | AN10: =COUNTIF(C10:AG10,"H2") -> 0 | AO10: =COUNTIF(C10:AG10,"P1") -> 0 | AP10: =+AH10+AI10+AJ10+AK10+AL10+AM10+AN10+AO10 -> 31 | AQ10: =COUNTIF(C10:AG10,"CTH") -> 0 | AR10: =COUNTIF(C10:AG10,"A") -> 0 | AT10: =AP10-AS10 -> 31
A11: 5 | B11: HENDRI SUSILO | C11: NAS | D11: =COUNTIF(ABSEN!B:B,"HENDRI SUSILO ( PARTINI )") -> 1 | E11: =COUNTIF(ABSEN!C:C,"HENDRI SUSILO ( PARTINI )") -> 1 | F11: MG | G11: =COUNTIF(ABSEN!E:E,"HENDRI SUSILO ( PARTINI )") -> 1 | H11: =COUNTIF(ABSEN!F:F,"HENDRI SUSILO ( PARTINI )") -> 1 | I11: =COUNTIF(ABSEN!G:G,"HENDRI SUSILO ( PARTINI )") -> 1 | J11: =COUNTIF(ABSEN!H:H,"HENDRI SUSILO ( PARTINI )") -> 1 | K11: =COUNTIF(ABSEN!I:I,"HENDRI SUSILO ( PARTINI )") -> 1 | L11: =COUNTIF(ABSEN!J:J,"HENDRI SUSILO ( PARTINI )") -> 1 | M11: MG | N11: NAS | O11: =COUNTIF(ABSEN!M:M,"HENDRI SUSILO ( PARTINI )") -> 1 | P11: =COUNTIF(ABSEN!N:N,"HENDRI SUSILO ( PARTINI )") -> 1 | Q11: =COUNTIF(ABSEN!O:O,"HENDRI SUSILO ( PARTINI )") -> 1 | R11: =COUNTIF(ABSEN!P:P,"HENDRI SUSILO ( PARTINI )") -> 1 | S11: =COUNTIF(ABSEN!Q:Q,"HENDRI SUSILO ( PARTINI )") -> 1 | T11: MG | U11: =COUNTIF(ABSEN!S:S,"HENDRI SUSILO ( PARTINI )") -> 1 | V11: =COUNTIF(ABSEN!T:T,"HENDRI SUSILO ( PARTINI )") -> 1 | W11: =COUNTIF(ABSEN!U:U,"HENDRI SUSILO ( PARTINI )") -> 1 | X11: =COUNTIF(ABSEN!V:V,"HENDRI SUSILO ( PARTINI )") -> 1 | Y11: =COUNTIF(ABSEN!W:W,"HENDRI SUSILO ( PARTINI )") -> 1 | Z11: =COUNTIF(ABSEN!X:X,"HENDRI SUSILO ( PARTINI )") -> 1 | AA11: MG | AB11: =COUNTIF(ABSEN!Z:Z,"HENDRI SUSILO ( PARTINI )") -> 1 | AC11: =COUNTIF(ABSEN!AA:AA,"HENDRI SUSILO ( PARTINI )") -> 1 | AD11: =COUNTIF(ABSEN!AB:AB,"HENDRI SUSILO ( PARTINI )") -> 1 | AE11: NAS | AF11: =COUNTIF(ABSEN!AD:AD,"HENDRI SUSILO ( PARTINI )") -> 1 | AG11: =COUNTIF(ABSEN!AE:AE,"HENDRI SUSILO ( PARTINI )") -> 1 | AH11: =SUM(C11:AG11) -> 24 | AI11: =COUNTIF(C11:AG11,"CT") -> 0 | AJ11: =COUNTIF(C11:AG11,"S") -> 0 | AK11: =COUNTIF(C11:AG11,"H1") -> 0 | AL11: =COUNTIF(C11:AG11,"MG") -> 4 | AM11: =COUNTIF(C11:AG11,"NAS") -> 3 | AN11: =COUNTIF(C11:AG11,"H2") -> 0 | AO11: =COUNTIF(C11:AG11,"P1") -> 0 | AP11: =+AH11+AI11+AJ11+AK11+AL11+AM11+AN11+AO11 -> 31 | AQ11: =COUNTIF(C11:AG11,"CTH") -> 0 | AR11: =COUNTIF(C11:AG11,"A") -> 0 | AT11: =AP11-AS11 -> 31
A12: 6 | B12: HERMANSAH | C12: NAS | D12: =COUNTIF(ABSEN!B:B,"HERMANSYAH ( SINARAH )") -> 1 | E12: =COUNTIF(ABSEN!C:C,"HERMANSYAH ( SINARAH )") -> 1 | F12: MG | G12: =COUNTIF(ABSEN!E:E,"HERMANSYAH ( SINARAH )") -> 1 | H12: =COUNTIF(ABSEN!F:F,"HERMANSYAH ( SINARAH )") -> 1 | I12: =COUNTIF(ABSEN!G:G,"HERMANSYAH ( SINARAH )") -> 1 | J12: =COUNTIF(ABSEN!H:H,"HERMANSYAH ( SINARAH )") -> 1 | K12: =COUNTIF(ABSEN!I:I,"HERMANSYAH ( SINARAH )") -> 1 | L12: =COUNTIF(ABSEN!J:J,"HERMANSYAH ( SINARAH )") -> 1 | M12: MG | N12: NAS | O12: =COUNTIF(ABSEN!M:M,"HERMANSYAH ( SINARAH )") -> 1 | P12: =COUNTIF(ABSEN!N:N,"HERMANSYAH ( SINARAH )") -> 1 | Q12: =COUNTIF(ABSEN!O:O,"HERMANSYAH ( SINARAH )") -> 1 | R12: =COUNTIF(ABSEN!P:P,"HERMANSYAH ( SINARAH )") -> 1 | S12: =COUNTIF(ABSEN!Q:Q,"HERMANSYAH ( SINARAH )") -> 1 | T12: MG | U12: =COUNTIF(ABSEN!S:S,"HERMANSYAH ( SINARAH )") -> 1 | V12: =COUNTIF(ABSEN!T:T,"HERMANSYAH ( SINARAH )") -> 1 | W12: =COUNTIF(ABSEN!U:U,"HERMANSYAH ( SINARAH )") -> 1 | X12: =COUNTIF(ABSEN!V:V,"HERMANSYAH ( SINARAH )") -> 1 | Y12: =COUNTIF(ABSEN!W:W,"HERMANSYAH ( SINARAH )") -> 1 | Z12: =COUNTIF(ABSEN!X:X,"HERMANSYAH ( SINARAH )") -> 1 | AA12: MG | AB12: =COUNTIF(ABSEN!Z:Z,"HERMANSYAH ( SINARAH )") -> 1 | AC12: =COUNTIF(ABSEN!AA:AA,"HERMANSYAH ( SINARAH )") -> 1 | AD12: =COUNTIF(ABSEN!AB:AB,"HERMANSYAH ( SINARAH )") -> 1 | AE12: NAS | AF12: =COUNTIF(ABSEN!AD:AD,"HERMANSYAH ( SINARAH )") -> 1 | AG12: =COUNTIF(ABSEN!AE:AE,"HERMANSYAH ( SINARAH )") -> 1 | AH12: =SUM(C12:AG12) -> 24 | AI12: =COUNTIF(C12:AG12,"CT") -> 0 | AJ12: =COUNTIF(C12:AG12,"S") -> 0 | AK12: =COUNTIF(C12:AG12,"H1") -> 0 | AL12: =COUNTIF(C12:AG12,"MG") -> 4 | AM12: =COUNTIF(C12:AG12,"NAS") -> 3 | AN12: =COUNTIF(C12:AG12,"H2") -> 0 | AO12: =COUNTIF(C12:AG12,"P1") -> 0 | AP12: =+AH12+AI12+AJ12+AK12+AL12+AM12+AN12+AO12 -> 31 | AQ12: =COUNTIF(C12:AG12,"CTH") -> 0 | AR12: =COUNTIF(C12:AG12,"A") -> 0 | AT12: =AP12-AS12 -> 31
A13: 7 | B13: JUMADIL AWAL | C13: NAS | D13: =COUNTIF(ABSEN!B:B,"JUMADIL AWAL (Diasih)") -> 1 | E13: =COUNTIF(ABSEN!C:C,"JUMADIL AWAL (Diasih)") -> 1 | F13: MG | G13: =COUNTIF(ABSEN!E:E,"JUMADIL AWAL (Diasih)") -> 1 | H13: =COUNTIF(ABSEN!F:F,"JUMADIL AWAL (Diasih)") -> 1 | I13: =COUNTIF(ABSEN!G:G,"JUMADIL AWAL (Diasih)") -> 1 | J13: =COUNTIF(ABSEN!H:H,"JUMADIL AWAL (Diasih)") -> 1 | K13: =COUNTIF(ABSEN!I:I,"JUMADIL AWAL (Diasih)") -> 1 | L13: =COUNTIF(ABSEN!J:J,"JUMADIL AWAL (Diasih)") -> 1 | M13: MG | N13: NAS | O13: =COUNTIF(ABSEN!M:M,"JUMADIL AWAL (Diasih)") -> 1 | P13: =COUNTIF(ABSEN!N:N,"JUMADIL AWAL (Diasih)") -> 1 | Q13: =COUNTIF(ABSEN!O:O,"JUMADIL AWAL (Diasih)") -> 1 | R13: =COUNTIF(ABSEN!P:P,"JUMADIL AWAL (Diasih)") -> 1 | S13: =COUNTIF(ABSEN!Q:Q,"JUMADIL AWAL (Diasih)") -> 1 | T13: MG | U13: =COUNTIF(ABSEN!S:S,"JUMADIL AWAL (Diasih)") -> 1 | V13: =COUNTIF(ABSEN!T:T,"JUMADIL AWAL (Diasih)") -> 1 | W13: =COUNTIF(ABSEN!U:U,"JUMADIL AWAL (Diasih)") -> 1 | X13: =COUNTIF(ABSEN!V:V,"JUMADIL AWAL (Diasih)") -> 1 | Y13: =COUNTIF(ABSEN!W:W,"JUMADIL AWAL (Diasih)") -> 1 | Z13: =COUNTIF(ABSEN!X:X,"JUMADIL AWAL (Diasih)") -> 1 | AA13: MG | AB13: =COUNTIF(ABSEN!Z:Z,"JUMADIL AWAL (Diasih)") -> 1 | AC13: =COUNTIF(ABSEN!AA:AA,"JUMADIL AWAL (Diasih)") -> 1 | AD13: =COUNTIF(ABSEN!AB:AB,"JUMADIL AWAL (Diasih)") -> 1 | AE13: NAS | AF13: =COUNTIF(ABSEN!AD:AD,"JUMADIL AWAL (Diasih)") -> 1 | AG13: =COUNTIF(ABSEN!AE:AE,"JUMADIL AWAL (Diasih)") -> 1 | AH13: =SUM(C13:AG13) -> 24 | AI13: =COUNTIF(C13:AG13,"CT") -> 0 | AJ13: =COUNTIF(C13:AG13,"S") -> 0 | AK13: =COUNTIF(C13:AG13,"H1") -> 0 | AL13: =COUNTIF(C13:AG13,"MG") -> 4 | AM13: =COUNTIF(C13:AG13,"NAS") -> 3 | AN13: =COUNTIF(C13:AG13,"H2") -> 0 | AO13: =COUNTIF(C13:AG13,"P1") -> 0 | AP13: =+AH13+AI13+AJ13+AK13+AL13+AM13+AN13+AO13 -> 31 | AQ13: =COUNTIF(C13:AG13,"CTH") -> 0 | AR13: =COUNTIF(C13:AG13,"A") -> 0 | AT13: =AP13-AS13 -> 31
A14: 8 | B14: NASRUDIN (SAHNUN) | C14: NAS | D14: =COUNTIF(ABSEN!B:B,"NASRUDIN (Sahnun)") -> 1 | E14: =COUNTIF(ABSEN!C:C,"NASRUDIN (Sahnun)") -> 1 | F14: MG | G14: =COUNTIF(ABSEN!E:E,"NASRUDIN (Sahnun)") -> 1 | H14: =COUNTIF(ABSEN!F:F,"NASRUDIN (Sahnun)") -> 1 | I14: =COUNTIF(ABSEN!G:G,"NASRUDIN (Sahnun)") -> 1 | J14: =COUNTIF(ABSEN!H:H,"NASRUDIN (Sahnun)") -> 1 | K14: =COUNTIF(ABSEN!I:I,"NASRUDIN (Sahnun)") -> 1 | L14: =COUNTIF(ABSEN!J:J,"NASRUDIN (Sahnun)") -> 1 | M14: MG | N14: NAS | O14: =COUNTIF(ABSEN!M:M,"NASRUDIN (Sahnun)") -> 1 | P14: =COUNTIF(ABSEN!N:N,"NASRUDIN (Sahnun)") -> 1 | Q14: =COUNTIF(ABSEN!O:O,"NASRUDIN (Sahnun)") -> 1 | R14: =COUNTIF(ABSEN!P:P,"NASRUDIN (Sahnun)") -> 1 | S14: =COUNTIF(ABSEN!Q:Q,"NASRUDIN (Sahnun)") -> 1 | T14: MG | U14: =COUNTIF(ABSEN!S:S,"NASRUDIN (Sahnun)") -> 1 | V14: =COUNTIF(ABSEN!T:T,"NASRUDIN (Sahnun)") -> 1 | W14: =COUNTIF(ABSEN!U:U,"NASRUDIN (Sahnun)") -> 1 | X14: =COUNTIF(ABSEN!V:V,"NASRUDIN (Sahnun)") -> 1 | Y14: =COUNTIF(ABSEN!W:W,"NASRUDIN (Sahnun)") -> 1 | Z14: =COUNTIF(ABSEN!X:X,"NASRUDIN (Sahnun)") -> 1 | AA14: MG | AB14: =COUNTIF(ABSEN!Z:Z,"NASRUDIN (Sahnun)") -> 1 | AC14: =COUNTIF(ABSEN!AA:AA,"NASRUDIN (Sahnun)") -> 1 | AD14: =COUNTIF(ABSEN!AB:AB,"NASRUDIN (Sahnun)") -> 1 | AE14: NAS | AF14: =COUNTIF(ABSEN!AD:AD,"NASRUDIN (Sahnun)") -> 1 | AG14: =COUNTIF(ABSEN!AE:AE,"NASRUDIN (Sahnun)") -> 1 | AH14: =SUM(C14:AG14) -> 24 | AI14: =COUNTIF(C14:AG14,"CT") -> 0 | AJ14: =COUNTIF(C14:AG14,"S") -> 0 | AK14: =COUNTIF(C14:AG14,"H1") -> 0 | AL14: =COUNTIF(C14:AG14,"MG") -> 4 | AM14: =COUNTIF(C14:AG14,"NAS") -> 3 | AN14: =COUNTIF(C14:AG14,"H2") -> 0 | AO14: =COUNTIF(C14:AG14,"P1") -> 0 | AP14: =+AH14+AI14+AJ14+AK14+AL14+AM14+AN14+AO14 -> 31 | AQ14: =COUNTIF(C14:AG14,"CTH") -> 0 | AR14: =COUNTIF(C14:AG14,"A") -> 0 | AT14: =AP14-AS14 -> 31
A15: 9 | B15: NASRUDIN (INAK DENI) | C15: NAS | D15: =COUNTIF(ABSEN!B:B,"NASRUDIN (Inak Deni)") -> 1 | E15: =COUNTIF(ABSEN!C:C,"NASRUDIN (Inak Deni)") -> 1 | F15: MG | G15: =COUNTIF(ABSEN!E:E,"NASRUDIN (Inak Deni)") -> 1 | H15: =COUNTIF(ABSEN!F:F,"NASRUDIN (Inak Deni)") -> 1 | I15: =COUNTIF(ABSEN!G:G,"NASRUDIN (Inak Deni)") -> 1 | J15: =COUNTIF(ABSEN!H:H,"NASRUDIN (Inak Deni)") -> 1 | K15: =COUNTIF(ABSEN!I:I,"NASRUDIN (Inak Deni)") -> 1 | L15: =COUNTIF(ABSEN!J:J,"NASRUDIN (Inak Deni)") -> 1 | M15: MG | N15: NAS | O15: =COUNTIF(ABSEN!M:M,"NASRUDIN (Inak Deni)") -> 1 | P15: =COUNTIF(ABSEN!N:N,"NASRUDIN (Inak Deni)") -> 1 | Q15: =COUNTIF(ABSEN!O:O,"NASRUDIN (Inak Deni)") -> 1 | R15: =COUNTIF(ABSEN!P:P,"NASRUDIN (Inak Deni)") -> 1 | S15: =COUNTIF(ABSEN!Q:Q,"NASRUDIN (Inak Deni)") -> 1 | T15: MG | U15: =COUNTIF(ABSEN!S:S,"NASRUDIN (Inak Deni)") -> 1 | V15: =COUNTIF(ABSEN!T:T,"NASRUDIN (Inak Deni)") -> 1 | W15: =COUNTIF(ABSEN!U:U,"NASRUDIN (Inak Deni)") -> 1 | X15: =COUNTIF(ABSEN!V:V,"NASRUDIN (Inak Deni)") -> 1 | Y15: =COUNTIF(ABSEN!W:W,"NASRUDIN (Inak Deni)") -> 1 | Z15: =COUNTIF(ABSEN!X:X,"NASRUDIN (Inak Deni)") -> 1 | AA15: MG | AB15: =COUNTIF(ABSEN!Z:Z,"NASRUDIN (Inak Deni)") -> 1 | AC15: =COUNTIF(ABSEN!AA:AA,"NASRUDIN (Inak Deni)") -> 1 | AD15: =COUNTIF(ABSEN!AB:AB,"NASRUDIN (Inak Deni)") -> 1 | AE15: NAS | AF15: =COUNTIF(ABSEN!AD:AD,"NASRUDIN (Inak Deni)") -> 1 | AG15: =COUNTIF(ABSEN!AE:AE,"NASRUDIN (Inak Deni)") -> 1 | AH15: =SUM(C15:AG15) -> 24 | AI15: =COUNTIF(C15:AG15,"CT") -> 0 | AJ15: =COUNTIF(C15:AG15,"S") -> 0 | AK15: =COUNTIF(C15:AG15,"H1") -> 0 | AL15: =COUNTIF(C15:AG15,"MG") -> 4 | AM15: =COUNTIF(C15:AG15,"NAS") -> 3 | AN15: =COUNTIF(C15:AG15,"H2") -> 0 | AO15: =COUNTIF(C15:AG15,"P1") -> 0 | AP15: =+AH15+AI15+AJ15+AK15+AL15+AM15+AN15+AO15 -> 31 | AQ15: =COUNTIF(C15:AG15,"CTH") -> 0 | AR15: =COUNTIF(C15:AG15,"A") -> 0 | AT15: =AP15-AS15 -> 31
