Workbook

Sheet Sheet3
B3: WORKERS | O3: Upah & Astek | P3: Total &
A4: ESTATE/DIVISION | D4: 50000 | E4: 20000 | F4: 10000 | G4: 5000 | H4: 1000 | I4: 500 | J4: 100 | K4: 50 | L4: OTHERS | M4: TOTAL | P4: Rata-rata
A5: AR. MAINTENANCE
M6: =SUM(D6:L6) -> 0
A7: 1 | B7: 14 | C7: 280 | D7: 14650000 | E7: 100000 | F7: 40000 | G7: 15000 | H7: 42000 | L7: 9549 | M7: =SUM(D7:L7) -> 14856549 | O7: =5769904+225865 -> 5995769
A8: Sub Total | B8: =B6+B7 -> 14 | C8: =C6+C7 -> 280 | D8: =D6+D7 -> 14650000 | E8: =E6+E7 -> 100000 | F8: =F6+F7 -> 40000 | G8: =G6+G7 -> 15000 | H8: =H6+H7 -> 42000 | I8: =I6+I7 -> 0 | ... M8: =M6+M7 -> 14856549
A10: AR. HARVESTING 2
M11: =SUM(D11:L11) -> 0
A12: 1 | B12: 10 | C12: 215 | D12: 10800000 | E12: 160000 | F12: 30000 | G12: 30000 | H12: 20000 | L12: 5612 | M12: =SUM(D12:L12) -> 11045612
A13: Sub Total | B13: =B11+B12 -> 10 | C13: =C11+C12 -> 215 | D13: =D11+D12 -> 10800000 | E13: =E11+E12 -> 160000 | F13: =F11+F12 -> 30000 | G13: =G11+G12 -> 30000 | H13: =H11+H12 -> 20000 | I13: =I11+I12 -> 0 | ... M13: =M11+M12 -> 11045612
A18: Sub Total | B18: =B17 -> 0 | C18: =C17 -> 0 | D18: =D17 -> 0 | E18: =E17 -> 0 | F18: =F17 -> 0 | G18: =G17 -> 0 | H18: =H17 -> 0 | I18: =I17 -> 0 | ... M18: =M17 -> 0
A21: AR. TRANSPORT 1
A22: 1 | B22: 7 | C22: 143 | D22: 14250000 | E22: 20000 | F22: 30000 | G22: 20000 | H22: 17000 | L22: 4264 | M22: =SUM(D22:L22) -> 14341264 | O22: =5062955+180692 -> 5243647
A23: Sub Total | B23: =B22 -> 7 | C23: =C22 -> 143 | D23: =D22 -> 14250000 | E23: =E22 -> 20000 | F23: =F22 -> 30000 | G23: =G22 -> 20000 | H23: =H22 -> 17000 | I23: =I22 -> 0 | ... M23: =M22 -> 14341264
A28: Sub Total | B28: =B27 -> 0 | C28: =C27 -> 0 | D28: =D27 -> 0 | E28: =E27 -> 0 | F28: =F27 -> 0 | G28: =G27 -> 0 | H28: =H27 -> 0 | I28: =I27 -> 0 | ... M28: =M27 -> 0
A30: AR. LC PHT
A31: 1 | B31: 71 | C31: 1455 | D31: 75400000 | E31: 520000 | F31: 220000 | G31: 90000 | H31: 205000 | L31: 42723 | M31: =SUM(D31:L31) -> 76477723
A32: Sub Total | B32: =B31 -> 71 | C32: =C31 -> 1455 | D32: =D31 -> 75400000 | E32: =E31 -> 520000 | F32: =F31 -> 220000 | G32: =G31 -> 90000 | H32: =H31 -> 205000 | I32: =I31 -> 0 | ... M32: =M31 -> 76477723
A35: BIBITAN
A36: 1 | B36: 38 | C36: 755 | D36: 40100000 | E36: 260000 | F36: 210000 | G36: 65000 | H36: 93000 | L36: 27608 | M36: =SUM(D36:L36) -> 40755608
A37: Sub Total | B37: =B36 -> 38 | C37: =C36 -> 755 | D37: =D36 -> 40100000 | E37: =E36 -> 260000 | F37: =F36 -> 210000 | G37: =G36 -> 65000 | H37: =H36 -> 93000 | I37: =I36 -> 0 | ... M37: =M36 -> 40755608
P39: =SUM(O5:O39) -> 11239416
A40: TOTAL | B40: =B37+B32+B28+B23+B18+B13+B8 -> 140 | C40: =C37+C32+C28+C23+C18+C13+C8 -> 2848 | D40: =D37+D32+D28+D23+D18+D13+D8 -> 155200000 | E40: =E37+E32+E28+E23+E18+E13+E8 -> 1060000 | F40: =F37+F32+F28+F23+F18+F13+F8 -> 530000 | G40: =G37+G32+G28+G23+G18+G13+G8 -> 220000 | H40: =H37+H32+H28+H23+H18+H13+H8 -> 377000 | I40: =I37+I32+I28+I23+I18+I13+I8 -> 0 | ... M40: =M37+M32+M28+M23+M18+M13+M8 -> 157476756 | P40: =P39/C40 -> 3946.4242 | Q40: Upah rata-rata / HK | S40: =SUM(D40:L40) -> 157476756
B46: WORKERS
A47: ESTATE/DIVISION | D47: 50000 | E47: 20000 | F47: 10000 | G47: 5000 | H47: 1000 | I47: 500 | J47: 100 | K47: 50 | L47: OTHERS | M47: TOTAL
A48: AR. MAINTENANCE
M49: =SUM(D49:L49) -> 0
A50: 1
A51: Sub Total
A53: AR. HARVESTING 2
A55: 1
A56: Sub Total
A59: AR. Maintenance AB
A60: 1 | B60: 75 | C60: 1487 | D60: 76750000 | E60: 660000 | F60: 360000 | G60: 230000 | H60: 217000 | L60: 49609 | M60: =SUM(D60:L60) -> 78266609
A61: Sub Total | B61: =B60 -> 75 | C61: =C60 -> 1487 | D61: =D60 -> 76750000 | E61: =E60 -> 660000 | F61: =F60 -> 360000 | G61: =G60 -> 230000 | H61: =H60 -> 217000 | I61: =I60 -> 0 | ... M61: =M60 -> 78266609
A64: AR. TRANSPORT 1
A65: 1
A66: Sub Total | B66: =B65 -> 0 | C66: =C65 -> 0 | D66: =D65 -> 0 | E66: =E65 -> 0 | F66: =F65 -> 0 | G66: =G65 -> 0 | H66: =H65 -> 0 | I66: =I65 -> 0 | ... M66: =M65 -> 0
A69: AR. TRANSPORT A
A70: 1 | B70: 1 | C70: 23 | D70: 1750000 | L70: 571 | M70: =SUM(D70:L70) -> 1750571
...

Sheet SEPTEMBER DIBAYAR OKT 2025 
B3: PT. REBINMAS JAYA
B4: DENOMINATION FOR OKTOBER 2025
B6: ESTATE/DIVISION | C6: WORKERS | D6: HK | G6: JUMLAH | H6: BERAS | I6: JABATAN | J6: MASA KERJA | K6: TUNJ. LAIN | L6: JKK | M6: KOREKSI | N6: JKK | O6: BPJS | Q6: TOTAL PPH 21 | R6: TOTAL PPH | S6: POT | T6: TOTAL PREMI | U6: TOTAL LEMBUR | V6: TOTAL MANUAL | W6: Upah & Astek | X6: Total & | AA6: THUMB PRINT | AB6: SELISIH | AD6: PRUNNING | AF6: Koreksi | AG6: Insentif | AH6: Kontanan | AJ6: PREMI ( Rp ) | AL6: Ember | AN6: Pengembalian Tiket
D7: Ifest | E7: Cekroll | F7: Selisih | L7: JKM | N7: JKM | O7: Kes & Pen | Q7: (MASA OKTOBER 2025) | R7: EX-GRATIA | S7: SPSI | X7: Rata-rata | AJ7: TBS | AK7: BRDL
AA8: 878370277 | AB8: =V35-AA8 -> 0.0050001144
B9: PHASE IA MAINTENANCE KHT AIK HIJAU | C9: 22 | E9: 668 | Q9: 73888 | S9: 84000 | T9: 231010 | U9: 3193152.9 | V9: 89293007 | AL9: =AK9/1050 -> 0
B11: PHASE IA OPERATOR AIK HIJAU | C11: 8 | E11: 240 | Q11: 595803 | S11: 32000 | T11: 14437260 | U11: 8716747.8 | V11: 54307923 | AL11: =AK11/1050 -> 0
B13: PHASE IA HARVESTING AIK HIJAU | C13: 30 | E13: 920 | Q13: 347060 | S13: 64000 | T13: =3639444+64000+AM13 -> 33136125 | U13: 0 | V13: 1.6501079e+08 | AD13: 4903600 | AF13: 787069 | AG13: =7050000+2217478 -> 9267478 | AJ13: 14151681 | AK13: 15281000 | AL13: =AK13/1050 -> 14553.333 | AM13: =AJ13+AK13 -> 29432681
B15: PHASE IA HARVESTING AIK HIJAU masa percobaan | C15: 2 | E15: 62 | Q15: 28987 | S15: 0 | T15: =AM15 -> 2218345 | U15: 0 | V15: 10390586 | AJ15: 1103595 | AK15: 1114750 | AL15: =AK15/1050 -> 1061.6667 | AM15: =AJ15+AK15 -> 2218345
B17: PHASE IA HARVESTING KHT AIK BATU | C17: 33 | E17: 1007 | Q17: 121625 | S17: 120000 | T17: =AM17+2629000 -> 17797944 | U17: 918731.76 | V17: 1.6053064e+08 | AD17: 10563150 | AF17: 1095499 | AG17: 4977896 | AJ17: 6390944 | AK17: 8778000 | AL17: =AK17/1050 -> 8360 | AM17: =AJ17+AK17 -> 15168944
B19: PHASE IA MAINTENANCE KHT AIK BATU | C19: 24 | E19: 715 | Q19: 85836 | S19: 92000 | T19: 110000 | U19: 4190313.1 | V19: 96038461 | AL19: =AK19/1050 -> 0
B21: PHASE IA HARVESTING AIK BATU masa percobaan | AL21: =AK21/1050 -> 0
B23: PHASE IA OPERATOR AIK BATU | C23: 4 | E23: 124 | Q23: 154187 | S23: 16000 | T23: 5464385 | U23: 4190313.2 | V23: 26028565 | AL23: =AK23/1050 -> 0
B25: PHASE IA HARVESTING KHT AIK KUNDO | C25: 0 | AL25: =AK25/1050 -> 0
B27: PHASE IA MAINTENANCE KHT AIK KUNDO | C27: 66 | E27: 1967 | Q27: 13690 | S27: 260000 | T27: 0 | U27: 4033456.5 | V27: 2.572098e+08 | AL27: =AK27/1050 -> 0
B29: PHASE IA OPERATOR AIK KUNDO | C29: 2 | E29: 59 | Q29: 16020 | S29: 8000 | T29: 1289450 | U29: 2588134.6 | V29: 11735747 | AL29: =AK29/1050 -> 0
B31: PHASE IA HARVESTING AIK KUNDO masa percobaan | AL31: =AK31/1050 -> 0
B33: PHASE 1A MAINTENANCE AIR KUNDO masa percobaan | C33: 2 | E33: 62 | Q33: 0 | S33: 0 | T33: 0 | U33: 123244.5 | V33: 7824756.5
B35: TOTAL | C35: =SUM(C8:C34) -> 193 | D35: =SUM(D8:D34) -> 0 | E35: =SUM(E8:E34) -> 5824 | F35: =SUM(F8:F34) -> 0 | G35: =SUM(G8:G34) -> 0 | H35: =SUM(H8:H34) -> 0 | I35: =SUM(I8:I34) -> 0 | J35: =SUM(J8:J34) -> 0 | ... V35: =SUM(V8:V34) -> 8.7837028e+08 | X35: =#REF!/#REF! -> #REF! | Y35: Upah rata-rata/ hk | AA35: =AA8 -> 878370277 | AB35: =AB8 -> 0.0050001144 | AD35: =SUM(AD8:AD34) -> 15466750 | AF35: =SUM(AF9:AF34) -> 1882568 | AG35: =SUM(AG9:AG34) -> 14245374 | AH35: =SUM(AH9:AH34) -> 0 | AJ35: =SUM(AJ9:AJ34) -> 21646220 | AK35: =SUM(AK8:AK34) -> 25173750 | AL35: =SUM(AL8:AL34) -> 23975
B41: DIBUAT OLEH : | C41: DIPERIKSA OLEH : | L41: DISETUJUI OLEH :
B50: PT. REBINMAS JAYA
B51: =B4 -> DENOMINATION FOR OKTOBER 2025
B53: ESTATE/DIVISION | C53: WORKERS | D53: HK | G53: JUMLAH | H53: BERAS | I53: JABATAN | J53: MASA KERJA | K53: TUNJ. LAIN | L53: JKK | M53: KOREKSI | N53: JKK | O53: BPJS | Q53: TOTAL PPH 21 | R53: TOTAL PPH | S53: POT | T53: =T6 -> TOTAL PREMI | U53: =U6 -> TOTAL LEMBUR | V53: TOTAL MANUAL | W53: Upah & Astek | X53: Total & | AA53: THUMB PRINT | AB53: SELISIH | AD53: PRUNNING | AF53: Koreksi | AG53: Insentif | AH53: Kontanan | AJ53: PREMI | AN53: Pokok Prunning
D54: Ifest | E54: Cekroll | F54: Selisih | L54: JKM | N54: JKM | O54: Kes & Pen | Q54: =Q7 -> (MASA OKTOBER 2025) | R54: EX-GRATIA | S54: SPSI | X54: Rata-rata | AJ54: TBS | AK54: BRDL
AA55: 695391805 | AB55: =V90-AA90 -> 0.44148147
B56: PHASE IB OPERATOR GUNUNG RUM | C56: 6 | E56: 185 | Q56: 97618 | S56: 24000 | T56: 2020515 | U56: 5321921.8 | V56: 31980345 | AL56: =AK56/1050 -> 0
B58: PHASE IB HARVESTING KHT GUNUNG RUM | AL58: =AK58/1050 -> 0 | AN58: =AD58/550 -> 0
AN59: =AD59/550 -> 0
B60: PHASE IB MAINTENANCE KHT GUNUNG RUM | C60: 61 | E60: 1831 | Q60: 86107 | S60: 240000 | T60: 0 | U60: 3249173.2 | V60: 2.3875984e+08 | AL60: =AK60/1050 -> 0 | AN60: =AD60/550 -> 0
AN61: =AD61/550 -> 0
B62: PHASE IB MAINTENANCE GUNUNG RUM masa percobaan | AL62: =AK62/1050 -> 0 | AN62: =AD62/550 -> 0
AL63: =AK63/1050 -> 0
B64: PHASE IB HARVESTING KHT GUNUNG RUM | C64: 22 | E64: 654 | Q64: 28278 | S64: 88000 | T64: =2328889+AM64 -> 8987701 | U64: 0 | V64: 85913667 | AD64: 0 | AF64: 7496127.4 | AG64: 2328888.9 | AJ64: 1340562 | AK64: 5318250 | AL64: =AK64/1050 -> 5065 | AM64: =AJ64+AK64 -> 6658812
B66: PHASE IB HARVESTING GUNUNG RUM ( masa percobaan ) | AL66: =AK66/1050 -> 0
B68: PHASE IB MAINTENANCE KHT PADANG TEMBALUN | C68: 72 | E68: 2187 | Q68: 157349 | S68: 284000 | T68: 0 | U68: 5277105.4 | V68: 2.8630553e+08 | AL68: =AK68/1050 -> 0 | AM68: =AJ68+AK68 -> 0
B70: PHASE IB PLASMA PADANG TEMBALUN
B72: PHASE IB MAINTENANCE PADANG TEMBALUN masa percobaan | C72: 6 | E72: 182 | Q72: 0 | S72: 0 | T72: 0 | U72: 0 | V72: 22587656 | AL72: =AK72/1050 -> 0
B74: PHASE IB OPERATOR PADANG TEMBALUN | C74: 5 | E74: 155 | Q74: 181988 | S74: 20000 | T74: 2287431 | U74: 7237813.6 | V74: 29844767 | AL74: =AK74/1050 -> 0
AL76: =AK76/1050 -> 0
AL78: =AK78/1050 -> 0
...

Sheet Sheet8
A3: SUMMARY - WAGES MEI 2022
A6: ESTATE/DIVISION | B6: 26-30 April 2022 | C6: 01-31 Mei 2022 | D6: TOTAL
A8: PHASE IA | B8: 123600328 | C8: ='SEPTEMBER DIBAYAR OKT 2025 '!V522 -> 8.7837028e+08 | D8: =B8+C8 -> 1.0019706e+09
A10: PHASE IB | B10: 113089408 | C10: ='SEPTEMBER DIBAYAR OKT 2025 '!V524 -> 6.9539181e+08 | D10: =B10+C10 -> 8.0848121e+08
A12: PHASE IIA | B12: 1.2795668e+08 | C12: ='SEPTEMBER DIBAYAR OKT 2025 '!V526 -> 8.0436036e+08 | D12: =B12+C12 -> 9.3231704e+08
A14: PHASE IIB | B14: 85491957 | C14: ='SEPTEMBER DIBAYAR OKT 2025 '!V528 -> 5.945058e+08 | D14: =B14+C14 -> 6.7999776e+08
A16: DARUL MAKMUR | B16: 126346301 | C16: ='SEPTEMBER DIBAYAR OKT 2025 '!V530 -> 9.6692756e+08 | D16: =B16+C16 -> 1.0932739e+09
A18: WORKSHOP PGE | B18: 9966517 | C18: ='SEPTEMBER DIBAYAR OKT 2025 '!V532 -> 87891747 | D18: =B18+C18 -> 97858264
A20: INFRASTUKTUR | B20: 17796309 | C20: ='SEPTEMBER DIBAYAR OKT 2025 '!V534 -> 1.611283e+08 | D20: =B20+C20 -> 1.7892461e+08
A22: MILL PKS | C22: ='SEPTEMBER DIBAYAR OKT 2025 '!V538 -> 1234277949 | D22: =B22+C22 -> 1234277949
A24: MILL Bioplant | C24: ='SEPTEMBER DIBAYAR OKT 2025 '!V540 -> 0 | D24: =B24+C24 -> 0
A26: Sub Total | B26: 6.042475e+08 | C26: =SUM(C8:C25) -> 5.4228538e+09 | D26: =B26+C26 -> 6.0271013e+09
A28: ARE - A | B28: 96906533 | C28: ='SEPTEMBER DIBAYAR OKT 2025 '!V544 -> 6.866745e+08 | D28: =B28+C28 -> 7.8358103e+08
A30: ARE - B1 | B30: 89304800 | C30: ='SEPTEMBER DIBAYAR OKT 2025 '!V546 -> 6.7607006e+08 | D30: =B30+C30 -> 7.6537486e+08
A32: ARE - B2 | B32: 89209566 | C32: ='SEPTEMBER DIBAYAR OKT 2025 '!V548 -> 6.2822493e+08 | D32: =B32+C32 -> 7.1743449e+08
A34: ARE - C | B34: 1.8974675e+08 | C34: ='SEPTEMBER DIBAYAR OKT 2025 '!V550 -> 1.2824897e+09 | D34: =B34+C34 -> 1.4722365e+09
A36: WORKSHOP ARE | B36: 3546165.8 | C36: ='SEPTEMBER DIBAYAR OKT 2025 '!V552 -> 28906719 | D36: =B36+C36 -> 32452885
A38: TOTAL C/ROLL | B38: =SUM(B26:B37) -> 1.0729613e+09 | C38: =SUM(C26:C37) -> 8.7252197e+09 | D38: =SUM(D26:D37) -> 9.798181e+09
A40: BLT + AM | B40: 30426819 | C40: ='SEPTEMBER DIBAYAR OKT 2025 '!V556 -> 2.2267996e+08 | D40: =B40+C40 -> 2.5310678e+08

Sheet SUMMARY - WAGES IJL
A1: PT.IMPIAN JAYA LESTARI
A3: SUMMARY - WAGES OKTOBER 2025
A5: ESTATE/DIVISION | N5: WORKERS | Y5: WORKERS | Z5: TOTAL PPH PASAL 21 | AA5: TOTAL | AB5: TOTAL | AC5: TOTAL | AD5: TOTAL | AE5: TOTAL | AF5: TOTAL | AG5: THUMB PRINT | AH5: SELISIH | AI5: NAIK/TURUN
N6: JULI 2025 | O6: 100000 | P6: 50000 | Q6: 20000 | R6: 10000 | S6: 5000 | T6: 1000 | U6: 500 | V6: 100 | W6: 50 | X6: OTHERS | Y6: SEPT 2025 | Z6: (MASA SEPT 2025) | AA6: SPSI | AB6: PREMI OKT 2025 | AC6: PRUNNING | AD6: LEMBUR | AE6: SEPT 2025 | AF6: OKT 2025
A8: BLT + AM | N8: 43 | Y8: ='SEPTEMBER DIBAYAR OKT 2025 '!C556 -> 43 | Z8: ='SEPTEMBER DIBAYAR OKT 2025 '!Q556 -> 1269044 | AA8: ='SEPTEMBER DIBAYAR OKT 2025 '!S456 -> 430000 | AB8: ='SEPTEMBER DIBAYAR OKT 2025 '!T556 -> 43738652 | AC8: ='SEPTEMBER DIBAYAR OKT 2025 '!AD556 -> 0 | AD8: ='SEPTEMBER DIBAYAR OKT 2025 '!U556 -> 9994008.8 | AE8: 236957607 | AF8: ='SEPTEMBER DIBAYAR OKT 2025 '!V556 -> 2.2267996e+08 | AG8: ='SEPTEMBER DIBAYAR OKT 2025 '!AA556 -> 222679965 | AH8: ='SEPTEMBER DIBAYAR OKT 2025 '!AB556 -> -0.16000003 | AI8: =AF8-AE8 -> -14277642
A10: Grand Total | N10: 43 | O10: =SUM(O8:O9) -> 0 | P10: =SUM(P8:P9) -> 0 | Q10: =SUM(Q8:Q9) -> 0 | R10: =SUM(R8:R9) -> 0 | S10: =SUM(S8:S9) -> 0 | T10: =SUM(T8:T9) -> 0 | U10: =SUM(U8:U9) -> 0 | V10: =SUM(V8:V9) -> 0 | ... AD10: =SUM(AD8:AD9) -> 9994008.8 | AE10: =AE8 -> 236957607 | AF10: =SUM(AF8:AF9) -> 2.2267996e+08 | AG10: =SUM(AG8:AG9) -> 222679965 | AH10: =SUM(AH8:AH9) -> -0.16000003 | AI10: =SUM(AI8:AI9) -> -14277642
AD14: TONASE | AE14: 480.87 | AF14: 587.88 | AI14: =AF14-AE14 -> 107.01
A18: DIBUAT OLEH : | N18: DIPERIKSA OLEH: | AC18: DISETUJUI OLEH:
A62: PT.IMPIAN JAYA LESTARI
A63: =A3 -> SUMMARY - WAGES OKTOBER 2025
A64: 01-31 MEI 2022 & 26-30 APRIL 2022
A66: ESTATE/DIVISION | N66: WORKERS | Y66: WORKERS | Z66: TOTAL PPH PASAL 21 | AA66: TOTAL | AB66: TOTAL | AC66: TOTAL | AD66: TOTAL | AE66: TOTAL | AF66: TOTAL | AI66: NAIK/TURUN
N67: APR 2022 | O67: 100000 | P67: 50000 | Q67: 20000 | R67: 10000 | S67: 5000 | T67: 1000 | U67: 500 | V67: 100 | W67: 50 | X67: OTHERS | Y67: MEI 2022 | Z67: (MASA MEI 2022) | AA67: SPSI | AB67: PREMI 2022 | AC67: PRUNNING | AD67: LEMBUR | AE67: APR 2022 | AF67: MEI 2022
A69: BLT + AM | N69: 44 | Y69: =Y8 -> 43 | Z69: =Z8 -> 1269044 | AA69: =AA8 -> 430000 | AB69: =AB8 -> 43738652 | AC69: =AC8 -> 0 | AD69: =AD8 -> 9994008.8 | AE69: =145808894 -> 145808894 | AF69: =Sheet8!D40 -> 2.5310678e+08 | AI69: =AF69-AE69 -> 1.0729789e+08
A71: Grand Total | N71: 44 | Y71: =SUM(Y69:Y70) -> 43 | Z71: =SUM(Z69:Z70) -> 1269044 | AA71: =SUM(AA69:AA70) -> 430000 | AB71: =SUM(AB69:AB70) -> 43738652 | AC71: =SUM(AC69:AC70) -> 0 | AD71: =SUM(AD69:AD70) -> 9994008.8 | AE71: =SUM(AE69:AE70) -> 145808894 | AF71: =SUM(AF69:AF70) -> 2.5310678e+08 | AI71: =SUM(AI69:AI70) -> 1.0729789e+08
AD75: TONASE | AE75: 630.58 | AF75: 572.82 | AI75: =AF75-AE75 -> -57.76
A78: DIBUAT OLEH : | N78: DIPERIKSA OLEH: | AC78: DISETUJUI OLEH:

Sheet SUMMARY - WAGES PT.RJ
A1: PT. REBINMAS JAYA
A2: ='SUMMARY - WAGES IJL'!A3 -> SUMMARY - WAGES OKTOBER 2025
A4: ESTATE/DIVISION | N4: WORKERS | Y4: WORKERS | Z4: TOTAL PPH 21 | AA4: POT | AB4: TOTAL | AC4: TOTAL | AD4: TOTAL | AE4: TOTAL | AF4: SEPTEMBER 2025 | AH4: OKTOBER 2025 | AK4: SELISIH | AL4: NAIK/TURUN | AP4: SELISIH | AQ4: NAIK/TURUN | AT4: PG IA | AU4: 2008.47 | AW4: Ton | AX4: =AU4/1000 -> 2.00847
N5: SEPT 2025 | O5: 100000 | P5: 50000 | Q5: 20000 | R5: 10000 | S5: 5000 | T5: 1000 | U5: 500 | V5: 100 | W5: 50 | X5: OTHERS | Y5: OKT 2025 | Z5: (MASA OKT 2025) | AA5: SPSI | AB5: PAJAK EX-GRATIA | AC5: PREMI OKT 2025 | AD5: PRUNNING | AE5: LEMBUR | AF5: GAJI | AG5: TBS ( Ton ) | AH5: GAJI | AI5: TBS ( Ton ) | AJ5: THUMB PRINT | AT5: PG IB | AW5: Ton | AX5: =AU5/1000 -> 0
AT6: PG IIA | AW6: Ton | AX6: =AU6/1000 -> 0
A7: PHASE IA | N7: 195 | Y7: ='SEPTEMBER DIBAYAR OKT 2025 '!C522 -> 193 | Z7: ='SEPTEMBER DIBAYAR OKT 2025 '!Q522 -> 1437096 | AA7: ='SEPTEMBER DIBAYAR OKT 2025 '!S522 -> 676000 | AC7: ='SEPTEMBER DIBAYAR OKT 2025 '!T522 -> 74684519 | AD7: ='SEPTEMBER DIBAYAR OKT 2025 '!AD522 -> 15466750 | AE7: ='SEPTEMBER DIBAYAR OKT 2025 '!U522 -> 27954094 | AF7: 9.0199714e+08 | AG7: 1204.65 | AH7: ='SEPTEMBER DIBAYAR OKT 2025 '!V522 -> 8.7837028e+08 | AI7: 1480.67 | AJ7: ='SEPTEMBER DIBAYAR OKT 2025 '!AA522 -> 878370277 | AK7: ='SEPTEMBER DIBAYAR OKT 2025 '!AB522 -> 0.0050001144 | AL7: =AH7-AF7 -> -23626867 | AP7: =AH7-AJ7 -> 0.0050001144 | AQ7: =AH7-AF7 -> -23626867 | AT7: PG IIB | AW7: Ton | AX7: =AU7/1000 -> 0
AJ8: ='SEPTEMBER DIBAYAR OKT 2025 '!AA523 -> 0 | AK8: ='SEPTEMBER DIBAYAR OKT 2025 '!AB523 -> 0 | AL8: =AH8-AF8 -> 0 | AT8: DME A | AW8: Ton | AX8: =AU8/1000 -> 0
A9: PHASE IB | N9: 171 | Y9: ='SEPTEMBER DIBAYAR OKT 2025 '!C524 -> 172 | Z9: ='SEPTEMBER DIBAYAR OKT 2025 '!Q524 -> 551340 | AA9: ='SEPTEMBER DIBAYAR OKT 2025 '!S524 -> 656000 | AC9: ='SEPTEMBER DIBAYAR OKT 2025 '!T524 -> 13295647 | AD9: ='SEPTEMBER DIBAYAR OKT 2025 '!AD524 -> 0 | AE9: ='SEPTEMBER DIBAYAR OKT 2025 '!U524 -> 21086014 | AF9: 6.722109e+08 | AG9: 162.57 | AH9: ='SEPTEMBER DIBAYAR OKT 2025 '!V524 -> 6.9539181e+08 | AI9: 231.69 | AJ9: ='SEPTEMBER DIBAYAR OKT 2025 '!AA524 -> 695391805 | AK9: ='SEPTEMBER DIBAYAR OKT 2025 '!AB524 -> 0.44148147 | AL9: =AH9-AF9 -> 23180910 | AP9: =AH9-AJ9 -> 0.44148147 | AQ9: =AH9-AF9 -> 23180910 | AT9: DME B | AW9: Ton
AJ10: ='SEPTEMBER DIBAYAR OKT 2025 '!AA525 -> 0 | AK10: ='SEPTEMBER DIBAYAR OKT 2025 '!AB525 -> 0 | AL10: =AH10-AF10 -> 0 | AU10: =SUM(AU4:AU9) -> 2008.47 | AW10: Ton
A11: PHASE IIA | N11: 177 | Y11: ='SEPTEMBER DIBAYAR OKT 2025 '!C526 -> 176 | Z11: ='SEPTEMBER DIBAYAR OKT 2025 '!Q526 -> 1213652 | AA11: ='SEPTEMBER DIBAYAR OKT 2025 '!S526 -> 604000 | AC11: ='SEPTEMBER DIBAYAR OKT 2025 '!T526 -> 69844530 | AD11: ='SEPTEMBER DIBAYAR OKT 2025 '!AD526 -> 16282050 | AE11: ='SEPTEMBER DIBAYAR OKT 2025 '!U526 -> 26699242 | AF11: 8.0045532e+08 | AG11: 1241.79 | AH11: ='SEPTEMBER DIBAYAR OKT 2025 '!V526 -> 8.0436036e+08 | AI11: 1501.58 | AJ11: ='SEPTEMBER DIBAYAR OKT 2025 '!AA526 -> 804360365 | AK11: ='SEPTEMBER DIBAYAR OKT 2025 '!AB526 -> -1.7399998 | AL11: =AH11-AF11 -> 3905046 | AP11: =AH11-AJ11 -> -1.7399998 | AQ11: =AH11-AF11 -> 3905046
AJ12: ='SEPTEMBER DIBAYAR OKT 2025 '!AA527 -> 0 | AK12: ='SEPTEMBER DIBAYAR OKT 2025 '!AB527 -> 0 | AL12: =AH12-AF12 -> 0 | AT12: ARE A | AW12: Ton
A13: PHASE IIB | N13: 124 | Y13: ='SEPTEMBER DIBAYAR OKT 2025 '!C528 -> 125 | Z13: ='SEPTEMBER DIBAYAR OKT 2025 '!Q528 -> 1312034 | AA13: ='SEPTEMBER DIBAYAR OKT 2025 '!S528 -> 492000 | AC13: ='SEPTEMBER DIBAYAR OKT 2025 '!T528 -> 68659726 | AD13: ='SEPTEMBER DIBAYAR OKT 2025 '!AD528 -> 8599500 | AE13: ='SEPTEMBER DIBAYAR OKT 2025 '!U528 -> 21142035 | AF13: 6.3890182e+08 | AG13: 1132.97 | AH13: ='SEPTEMBER DIBAYAR OKT 2025 '!V528 -> 5.945058e+08 | AI13: 1433.46 | AJ13: ='SEPTEMBER DIBAYAR OKT 2025 '!AA528 -> 594505798 | AK13: ='SEPTEMBER DIBAYAR OKT 2025 '!AB528 -> 0.47682667 | AL13: =AH13-AF13 -> -44396022 | AP13: =AH13-AJ13 -> 0.47682667 | AQ13: =AH13-AF13 -> -44396022 | AT13: ARE B1 | AW13: Ton
AJ14: ='SEPTEMBER DIBAYAR OKT 2025 '!AA529 -> 0 | AK14: ='SEPTEMBER DIBAYAR OKT 2025 '!AB529 -> 0 | AL14: =AH14-AF14 -> 0 | AT14: ARE B2 | AW14: Ton
A15: DARUL MAKMUR | N15: 204 | Y15: ='SEPTEMBER DIBAYAR OKT 2025 '!C530 -> 205 | Z15: ='SEPTEMBER DIBAYAR OKT 2025 '!Q530 -> 2694867 | AA15: ='SEPTEMBER DIBAYAR OKT 2025 '!S530 -> 812000 | AC15: ='SEPTEMBER DIBAYAR OKT 2025 '!T530 -> 110461585 | AD15: ='SEPTEMBER DIBAYAR OKT 2025 '!AD530 -> 45629800 | AE15: ='SEPTEMBER DIBAYAR OKT 2025 '!U530 -> 25029838 | AF15: 9.4818318e+08 | AG15: 2224.25 | AH15: ='SEPTEMBER DIBAYAR OKT 2025 '!V530 -> 9.6692756e+08 | AI15: 2564.16 | AJ15: ='SEPTEMBER DIBAYAR OKT 2025 '!AA530 -> 966927557 | AK15: ='SEPTEMBER DIBAYAR OKT 2025 '!AB530 -> 0.39999998 | AL15: =AH15-AF15 -> 18744380 | AP15: =AH15-AJ15 -> 0.39999998 | AQ15: =AH15-AF15 -> 18744380 | AT15: ARE C | AW15: Ton
AJ16: ='SEPTEMBER DIBAYAR OKT 2025 '!AA531 -> 0 | AK16: ='SEPTEMBER DIBAYAR OKT 2025 '!AB531 -> 0 | AL16: =AH16-AF16 -> 0 | AU16: =SUM(AU12:AU15) -> 0 | AW16: Ton
A17: WORKSHOP PGE | N17: 14 | Y17: ='SEPTEMBER DIBAYAR OKT 2025 '!C532 -> 14 | Z17: ='SEPTEMBER DIBAYAR OKT 2025 '!Q532 -> 614448 | AA17: ='SEPTEMBER DIBAYAR OKT 2025 '!S532 -> 24000 | AC17: ='SEPTEMBER DIBAYAR OKT 2025 '!T532 -> 0 | AD17: ='SEPTEMBER DIBAYAR OKT 2025 '!AD532 -> 0 | AE17: ='SEPTEMBER DIBAYAR OKT 2025 '!U532 -> 34289981 | AF17: 80279506 | AH17: ='SEPTEMBER DIBAYAR OKT 2025 '!V532 -> 87891747 | AJ17: ='SEPTEMBER DIBAYAR OKT 2025 '!AA532 -> 87891672 | AK17: ='SEPTEMBER DIBAYAR OKT 2025 '!AB532 -> 75.22 | AL17: =AH17-AF17 -> 7612241.2 | AP17: =AH17-AJ17 -> 75.22 | AQ17: =AH17-AF17 -> 7612241.2
AJ18: ='SEPTEMBER DIBAYAR OKT 2025 '!AA533 -> 0 | AK18: ='SEPTEMBER DIBAYAR OKT 2025 '!AB533 -> 0 | AL18: =AH18-AF18 -> 0
A19: INFRASTUKTUR | N19: 29 | Y19: ='SEPTEMBER DIBAYAR OKT 2025 '!C534 -> 29 | Z19: ='SEPTEMBER DIBAYAR OKT 2025 '!Q534 -> 1010024 | AA19: ='SEPTEMBER DIBAYAR OKT 2025 '!S534 -> 116000 | AC19: ='SEPTEMBER DIBAYAR OKT 2025 '!T534 -> 3117520 | AD19: ='SEPTEMBER DIBAYAR OKT 2025 '!AD534 -> 0 | AE19: ='SEPTEMBER DIBAYAR OKT 2025 '!U534 -> 45947790 | AF19: 163108145 | AH19: ='SEPTEMBER DIBAYAR OKT 2025 '!V534 -> 1.611283e+08 | AJ19: ='SEPTEMBER DIBAYAR OKT 2025 '!AA534 -> 161128233 | AK19: ='SEPTEMBER DIBAYAR OKT 2025 '!AB534 -> 67.28 | AL19: =AH19-AF19 -> -1979844.7 | AN19: =AF19-AJ19 -> 1979912 | AP19: =AH19-AJ19 -> 67.28 | AQ19: =AH19-AF19 -> -1979844.7 | AT19: G.TOTAL RMJ | AU19: =AU10+AU16 -> 2008.47 | AW19: Ton
AJ20: ='SEPTEMBER DIBAYAR OKT 2025 '!AA535 -> 0 | AK20: ='SEPTEMBER DIBAYAR OKT 2025 '!AB535 -> 0 | AL20: =AH20-AF20 -> 0
A21: NURSERY | N21: 18 | Y21: =+'SEPTEMBER DIBAYAR OKT 2025 '!C536 -> 18 | Z21: =+'SEPTEMBER DIBAYAR OKT 2025 '!Q536 -> 389632 | AA21: =+'SEPTEMBER DIBAYAR OKT 2025 '!S536 -> 72000 | AC21: =+'SEPTEMBER DIBAYAR OKT 2025 '!T536 -> 0 | AD21: 0 | AE21: =+'SEPTEMBER DIBAYAR OKT 2025 '!U536 -> 20581832 | AF21: 88815910 | AH21: ='SEPTEMBER DIBAYAR OKT 2025 '!V536 -> 90844468 | AJ21: ='SEPTEMBER DIBAYAR OKT 2025 '!AA536 -> 90844403 | AK21: ='SEPTEMBER DIBAYAR OKT 2025 '!AB536 -> 64.75 | AL21: =AH21-AF21 -> 2028557.8 | AP21: =AH21-AJ21 -> 64.75 | AQ21: =AH21-AF21 -> 2028557.8
AJ22: ='SEPTEMBER DIBAYAR OKT 2025 '!AA537 -> 0 | AK22: ='SEPTEMBER DIBAYAR OKT 2025 '!AB537 -> 0 | AL22: =AH22-AF22 -> 0
A23: MILL PKS | N23: 167 | Y23: ='SEPTEMBER DIBAYAR OKT 2025 '!C538 -> 167 | Z23: ='SEPTEMBER DIBAYAR OKT 2025 '!Q538 -> 15090000 | AA23: ='SEPTEMBER DIBAYAR OKT 2025 '!S538 -> 604000 | AB23: ……………………………………………………………………………………………………………………………………………………………………………………………………………………………………………………………………………………………………………………………………………………………………………………………………………………………………………………………………………………………………………………………………………………………………………………………………………………………………………………………………………………………….................................................................................................................................................................................................................................................................................................................................................................................................................................................................................................................................................................................................................................................................................................................................................................................................................................................................................................................................................................................................................................................................................................................................................................................................................................................. | AC23: ='SEPTEMBER DIBAYAR OKT 2025 '!T538 -> 0 | AD23: ='SEPTEMBER DIBAYAR OKT 2025 '!AD538 -> 0 | AE23: ='SEPTEMBER DIBAYAR OKT 2025 '!U538 -> 587803801 | AF23: 1207391151 | AH23: ='SEPTEMBER DIBAYAR OKT 2025 '!V538 -> 1234277949 | AJ23: ='SEPTEMBER DIBAYAR OKT 2025 '!AA538 -> 1234277949 | AK23: ='SEPTEMBER DIBAYAR OKT 2025 '!AB538 -> 0 | AL23: =AH23-AF23 -> 26886798 | AN23: =AF23-AJ23 -> -26886798 | AO23: =AF23/37*7 -> 2.2842535e+08 | AP23: =AH23-AJ23 -> 0 | AQ23: =AH23-AF23 -> 26886798 | AT23: PT.IJL | AW23: Ton
AJ24: ='SEPTEMBER DIBAYAR OKT 2025 '!AA539 -> 0 | AL24: =AH24-AF24 -> 0 | AX24: 1593610
A25: Mill Bioplant | N25: 0 | Y25: ='SEPTEMBER DIBAYAR OKT 2025 '!C540 -> 0 | Z25: ='SEPTEMBER DIBAYAR OKT 2025 '!Q540 -> 0 | AA25: 0 | AC25: 0 | AD25: 0 | AE25: ='SEPTEMBER DIBAYAR OKT 2025 '!U540 -> 0 | AF25: 0 | AH25: 0 | AJ25: ='SEPTEMBER DIBAYAR OKT 2025 '!AA540 -> 0 | AL25: =AH25-AF25 -> 0 | AQ25: =AH25-AF25 -> 0
A27: SUB TOTAL | N27: 1099 | O27: =SUM(O7:O23) -> 0 | P27: =SUM(P7:P23) -> 0 | Q27: =SUM(Q7:Q23) -> 0 | R27: =SUM(R7:R23) -> 0 | S27: =SUM(S7:S23) -> 0 | T27: =SUM(T7:T23) -> 0 | U27: =SUM(U7:U23) -> 0 | V27: =SUM(V7:V23) -> 0 | ... X27: =SUM(X7:X23) -> 0 | Y27: =SUM(Y7:Y26) -> 1099 | Z27: =SUM(Z7:Z26) -> 24313093 | AA27: =SUM(AA7:AA26) -> 4056000 | AB27: =SUM(AB7:AB26) -> 0 | AC27: =SUM(AC7:AC26) -> 340063527 | AD27: =SUM(AD7:AD26) -> 85978100 | AE27: =SUM(AE7:AE26) -> 8.1053463e+08 | AF27: 5.5013431e+09 | AG27: 5966.23 | AH27: =SUM(AH7:AH26) -> 5.5136983e+09 | AI27: =SUM(AI7:AI26) -> 7211.56 | AJ27: =SUM(AJ7:AJ26) -> 5513698059 | AK27: =SUM(AK7:AK26) -> 206.83331 | AL27: =SUM(AL7:AL26) -> 12355198 | AN27: =SUM(AN7:AN26) -> -24906886 | AO27: =SUM(AO7:AO26) -> 2.2842535e+08 | AP27: =SUM(AP7:AP26) -> 206.83331 | AQ27: =SUM(AQ7:AQ26) -> 12355198
AX28: 456610
A29: ARE - A | N29: 141 | Y29: ='SEPTEMBER DIBAYAR OKT 2025 '!C544 -> 140 | Z29: ='SEPTEMBER DIBAYAR OKT 2025 '!Q544 -> 2070117 | AA29: ='SEPTEMBER DIBAYAR OKT 2025 '!S544 -> 428000 | AC29: ='SEPTEMBER DIBAYAR OKT 2025 '!T544 -> 80854039 | AD29: ='SEPTEMBER DIBAYAR OKT 2025 '!AD544 -> 26023250 | AE29: ='SEPTEMBER DIBAYAR OKT 2025 '!U544 -> 24267963 | AF29: 6.6607642e+08 | AG29: 1428.52 | AH29: ='SEPTEMBER DIBAYAR OKT 2025 '!V544 -> 6.866745e+08 | AI29: 1825.69 | AJ29: ='SEPTEMBER DIBAYAR OKT 2025 '!AA544 -> 686674495 | AK29: ='SEPTEMBER DIBAYAR OKT 2025 '!AB544 -> 1.61 | AL29: =AH29-AF29 -> 20598080 | AN29: =AF29-AJ29 -> -20598078 | AO29: =AJ29-AF29 -> 20598078 | AP29: =AH29-AJ29 -> 1.61 | AQ29: =AH29-AF29 -> 20598080
AJ30: ='SEPTEMBER DIBAYAR OKT 2025 '!AA545 -> 0 | AK30: ='SEPTEMBER DIBAYAR OKT 2025 '!AB545 -> 0 | AL30: =AH30-AF30 -> 0 | AO30: =AJ30-AF30 -> 0
A31: ARE - B1 | N31: 139 | Y31: ='SEPTEMBER DIBAYAR OKT 2025 '!C546 -> 139 | Z31: ='SEPTEMBER DIBAYAR OKT 2025 '!Q546 -> 1653863 | AA31: ='SEPTEMBER DIBAYAR OKT 2025 '!S546 -> 556000 | AC31: ='SEPTEMBER DIBAYAR OKT 2025 '!T546 -> 71495925 | AD31: ='SEPTEMBER DIBAYAR OKT 2025 '!AD546 -> 29981600 | AE31: ='SEPTEMBER DIBAYAR OKT 2025 '!U546 -> 23931842 | AF31: 668699821 | AG31: 1697.47 | AH31: ='SEPTEMBER DIBAYAR OKT 2025 '!V546 -> 6.7607006e+08 | AI31: 1996.52 | AJ31: ='SEPTEMBER DIBAYAR OKT 2025 '!AA546 -> 676070056 | AK31: ='SEPTEMBER DIBAYAR OKT 2025 '!AB546 -> 0.35000002 | AL31: =AH31-AF31 -> 7370235.4 | AN31: =AF31-AJ31 -> -7370235 | AO31: =AJ31-AF31 -> 7370235 | AP31: =AH31-AJ31 -> 0.35000002 | AQ31: =AH31-AF31 -> 7370235.4
AJ32: ='SEPTEMBER DIBAYAR OKT 2025 '!AA547 -> 0 | AK32: ='SEPTEMBER DIBAYAR OKT 2025 '!AB547 -> 0 | AL32: =AH32-AF32 -> 0 | AO32: =AJ32-AF32 -> 0
A33: ARE - B2 | N33: 128 | Y33: ='SEPTEMBER DIBAYAR OKT 2025 '!C548 -> 124 | Z33: ='SEPTEMBER DIBAYAR OKT 2025 '!Q548 -> 2327867 | AA33: ='SEPTEMBER DIBAYAR OKT 2025 '!S548 -> 484000 | AC33: ='SEPTEMBER DIBAYAR OKT 2025 '!T548 -> 81408652 | AD33: ='SEPTEMBER DIBAYAR OKT 2025 '!AD548 -> 20870600 | AE33: ='SEPTEMBER DIBAYAR OKT 2025 '!U548 -> 34295584 | AF33: 622111088 | AG33: 1437.68 | AH33: ='SEPTEMBER DIBAYAR OKT 2025 '!V548 -> 6.2822493e+08 | AI33: 1806.87 | AJ33: ='SEPTEMBER DIBAYAR OKT 2025 '!AA548 -> 657131647 | AK33: ='SEPTEMBER DIBAYAR OKT 2025 '!AB548 -> -28906719 | AL33: =AH33-AF33 -> 6113840.3 | AN33: =AF33-AJ33 -> -35020559 | AO33: =AJ33-AF33 -> 35020559 | AP33: =AH33-AJ33 -> -28906719 | AQ33: =AH33-AF33 -> 6113840.3
AJ34: ='SEPTEMBER DIBAYAR OKT 2025 '!AA549 -> 0 | AK34: ='SEPTEMBER DIBAYAR OKT 2025 '!AB549 -> 0 | AL34: =AH34-AF34 -> 0 | AO34: =AJ34-AF34 -> 0
A35: ARE - C | N35: 264 | Y35: ='SEPTEMBER DIBAYAR OKT 2025 '!C550 -> 260 | Z35: ='SEPTEMBER DIBAYAR OKT 2025 '!Q550 -> 4625191 | AA35: ='SEPTEMBER DIBAYAR OKT 2025 '!S550 -> 996000 | AC35: ='SEPTEMBER DIBAYAR OKT 2025 '!T550 -> 1.5532868e+08 | AD35: ='SEPTEMBER DIBAYAR OKT 2025 '!AD550 -> 45028000 | AE35: ='SEPTEMBER DIBAYAR OKT 2025 '!U550 -> 57555184 | AF35: 1.2927092e+09 | AG35: 2211.9 | AH35: ='SEPTEMBER DIBAYAR OKT 2025 '!V550 -> 1.2824897e+09 | AI35: 2533.65 | AJ35: ='SEPTEMBER DIBAYAR OKT 2025 '!AA550 -> 1282489712 | AK35: ='SEPTEMBER DIBAYAR OKT 2025 '!AB550 -> 0.050000191 | AL35: =AH35-AF35 -> -10219467 | AN35: =AF35-AJ35 -> 10219467 | AO35: =AJ35-AF35 -> -10219467 | AP35: =AH35-AJ35 -> 0.050000191 | AQ35: =AH35-AF35 -> -10219467 | AS35: =AF7+AF9+AF11+AF13+AF15+AF17+AF19+AF29+AF31+AF33+AF35+AF37 -> 7.4815384e+09 | AT35: GAJI PT RJ
AJ36: ='SEPTEMBER DIBAYAR OKT 2025 '!AA551 -> 0 | AK36: ='SEPTEMBER DIBAYAR OKT 2025 '!AB551 -> 0 | AL36: =AH36-AF36 -> 0 | AO36: =AJ36-AF36 -> 0
A37: WORKSHOP ARE | N37: 5 | Y37: ='SEPTEMBER DIBAYAR OKT 2025 '!C552 -> 5 | Z37: ='SEPTEMBER DIBAYAR OKT 2025 '!Q552 -> 78309 | AA37: ='SEPTEMBER DIBAYAR OKT 2025 '!S552 -> 20000 | AC37: ='SEPTEMBER DIBAYAR OKT 2025 '!T552 -> 400000 | AD37: ='SEPTEMBER DIBAYAR OKT 2025 '!AD552 -> 0 | AE37: ='SEPTEMBER DIBAYAR OKT 2025 '!U552 -> 8358218 | AF37: 26805912 | AH37: ='SEPTEMBER DIBAYAR OKT 2025 '!V552 -> 28906719 | AJ37: 0 | AK37: ='SEPTEMBER DIBAYAR OKT 2025 '!AB552 -> 28906719 | AL37: =AH37-AF37 -> 2100807 | AN37: =AF37-AJ37 -> 26805912 | AO37: =AJ37-AF37 -> -26805912 | AP37: =AH37-AJ37 -> 28906719 | AQ37: =AH37-AF37 -> 2100807 | AS37: =AS35+AF23 -> 8.6889296e+09 | AT37: GAJI PT RJ + MILL
AL38: =AF38-AH38 -> 0
A39: SUB TOTAL | N39: 677 | O39: =SUM(O29:O37) -> 0 | P39: =SUM(P29:P37) -> 0 | Q39: =SUM(Q29:Q37) -> 0 | R39: =SUM(R29:R37) -> 0 | S39: =SUM(S29:S37) -> 0 | T39: =SUM(T29:T37) -> 0 | U39: =SUM(U29:U37) -> 0 | V39: =SUM(V29:V37) -> 0 | ... AB39: =SUM(AB29:AB37) -> 0 | AC39: =SUM(AC28:AC38) -> 3.894873e+08 | AD39: =SUM(AD28:AD38) -> 121903450 | AE39: =SUM(AE28:AE38) -> 1.4840879e+08 | AF39: 3.2764024e+09 | AG39: 6775.57 | AH39: =SUM(AH28:AH38) -> 3.3023659e+09 | AI39: =SUM(AI28:AI38) -> 8162.73 | AJ39: =SUM(AJ28:AJ38) -> 3302365910 | AK39: =SUM(AK28:AK38) -> 2.3800003 | AL39: =SUM(AL28:AL38) -> 25963496 | AN39: =SUM(AN28:AN38) -> -25963493 | AO39: =SUM(AO28:AO38) -> 25963493 | AP39: =SUM(AP28:AP38) -> 2.3800003 | AQ39: =SUM(AQ28:AQ38) -> 25963496
A41: Grand Total | N41: 1776 | O41: =O39+O27 -> 0 | P41: =P39+P27 -> 0 | Q41: =Q39+Q27 -> 0 | R41: =R39+R27 -> 0 | S41: =S39+S27 -> 0 | T41: =T39+T27 -> 0 | U41: =U39+U27 -> 0 | V41: =V39+V27 -> 0 | ... AE41: =AE39+AE27 -> 9.5894342e+08 | AF41: 8.7777455e+09 | AG41: 12741.8 | AH41: =AH39+AH27 -> 8.8160642e+09 | AI41: =AI39+AI27 -> 15374.29 | AJ41: =AJ39+AJ27 -> 8816063969 | AK41: =AK39+AK27 -> 209.21331 | AL41: =AL39+AL27 -> 38318694 | AN41: =AN39+AN27 -> -50870379 | AO41: =AO39+AO27 -> 2.5438885e+08 | AP41: =AP39+AP27 -> 209.21331 | AQ41: =AQ39+AQ27 -> 38318694
AI42: =#REF!-AG41 -> #REF! | AL42: =AG41-AI41 -> -2632.49
X43: ESTATE | AE43: ESTATE | AF43: =AF7+AF9+AF11+AF13+AF15+AF17+AF19+AF29+AF31+AF33+AF35+AF37+AF21 -> 7.5703543e+09 | AH43: =AH7+AH9+AH11+AH13+AH15+AH17+AH19+AH29+AH31+AH33+AH35+AH37+AH21 -> 7.5817862e+09 | AJ43: =AH41-AJ41 -> 209.21331 | AL43: =AF43-AH43 -> -11431896 | AO43: =AF43-#REF! -> #REF! | AS43: =AO43/#REF!*100 -> #REF!
...

Sheet IMPACT RMJ
A1: MONTH OF OKTOBER 2025
A3: Estate | B3: Luas Ha Productive | C3: Jumlah Karyawan | G3: Nilai Gaji ( All) | K3: Tonase TBS | M3: % Gaji Naik/Turun | P3: % TBS Naik / Turun
C4: 45931 | D4: 45901 | E4: Diff | F4: 45931 | G4: 45901 | H4: Diff | I4: 45931 | J4: 45901 | K4: Diff | L4: (Okt`25 - Sept`25 )
A5: PGE 1A | B5: 1188.85 | C5: ='SUMMARY - WAGES PT.RJ'!Y7 -> 193 | D5: 195 | E5: =C5-D5 -> -2 | F5: ='SUMMARY - WAGES PT.RJ'!AH7 -> 8.7837028e+08 | G5: 9.0199714e+08 | H5: =F5-G5 -> -23626867 | I5: ='SUMMARY - WAGES PT.RJ'!AI7 -> 1480.67 | J5: 1204.65 | K5: =I5-J5 -> 276.02 | L5: =K5/J5*100 -> 22.912879 | M5: =H5/G5*100 -> -2.6193949
A6: PGE 1B | B6: 61.83 | C6: ='SUMMARY - WAGES PT.RJ'!Y9 -> 172 | D6: 171 | E6: =C6-D6 -> 1 | F6: ='SUMMARY - WAGES PT.RJ'!AH9 -> 6.9539181e+08 | G6: 6.722109e+08 | H6: =F6-G6 -> 23180910 | I6: ='SUMMARY - WAGES PT.RJ'!AI9 -> 231.69 | J6: 162.57 | K6: =I6-J6 -> 69.12 | L6: =K6/J6*100 -> 42.51707 | M6: =H6/G6*100 -> 3.4484579
A7: PGE 2A | B7: 1491.97 | C7: ='SUMMARY - WAGES PT.RJ'!Y11 -> 176 | D7: 177 | E7: =C7-D7 -> -1 | F7: ='SUMMARY - WAGES PT.RJ'!AH11 -> 8.0436036e+08 | G7: 8.0045532e+08 | H7: =F7-G7 -> 3905046 | I7: ='SUMMARY - WAGES PT.RJ'!AI11 -> 1501.58 | J7: 1241.79 | K7: =I7-J7 -> 259.79 | L7: =K7/J7*100 -> 20.920607 | M7: =H7/G7*100 -> 0.48785309
A8: PGE 2B | B8: 982.11 | C8: ='SUMMARY - WAGES PT.RJ'!Y13 -> 125 | D8: 124 | E8: =C8-D8 -> 1 | F8: ='SUMMARY - WAGES PT.RJ'!AH13 -> 5.945058e+08 | G8: 6.3890182e+08 | H8: =F8-G8 -> -44396022 | I8: ='SUMMARY - WAGES PT.RJ'!AI13 -> 1433.46 | J8: 1132.97 | K8: =I8-J8 -> 300.49 | L8: =K8/J8*100 -> 26.522326 | M8: =H8/G8*100 -> -6.9488019
A9: DME | B9: 1518.88 | C9: ='SUMMARY - WAGES PT.RJ'!Y15 -> 205 | D9: 204 | E9: =C9-D9 -> 1 | F9: ='SUMMARY - WAGES PT.RJ'!AH15 -> 9.6692756e+08 | G9: 9.4818318e+08 | H9: =F9-G9 -> 18744380 | I9: ='SUMMARY - WAGES PT.RJ'!AI15 -> 2564.16 | J9: 2224.25 | K9: =I9-J9 -> 339.91 | L9: =K9/J9*100 -> 15.282005 | M9: =H9/G9*100 -> 1.9768733
A10: ARE A | B10: 1158.2 | C10: ='SUMMARY - WAGES PT.RJ'!Y29 -> 140 | D10: 141 | E10: =C10-D10 -> -1 | F10: ='SUMMARY - WAGES PT.RJ'!AH29 -> 6.866745e+08 | G10: 6.6607642e+08 | H10: =F10-G10 -> 20598080 | I10: ='SUMMARY - WAGES PT.RJ'!AI29 -> 1825.69 | J10: 1428.52 | K10: =I10-J10 -> 397.17 | L10: =K10/J10*100 -> 27.802901 | M10: =H10/G10*100 -> 3.09245
A11: ARE B1 | B11: 1210.1 | C11: ='SUMMARY - WAGES PT.RJ'!Y31 -> 139 | D11: 139 | E11: =C11-D11 -> 0 | F11: ='SUMMARY - WAGES PT.RJ'!AH31 -> 6.7607006e+08 | G11: 668699821 | H11: =F11-G11 -> 7370235.4 | I11: ='SUMMARY - WAGES PT.RJ'!AI31 -> 1996.52 | J11: 1697.47 | K11: =I11-J11 -> 299.05 | L11: =K11/J11*100 -> 17.617395 | M11: =H11/G11*100 -> 1.102174
A12: ARE B2 | B12: 1056.13 | C12: ='SUMMARY - WAGES PT.RJ'!Y33 -> 124 | D12: 128 | E12: =C12-D12 -> -4 | F12: ='SUMMARY - WAGES PT.RJ'!AH33 -> 6.2822493e+08 | G12: 622111088 | H12: =F12-G12 -> 6113840.3 | I12: ='SUMMARY - WAGES PT.RJ'!AI33 -> 1806.87 | J12: 1437.68 | K12: =I12-J12 -> 369.19 | L12: =K12/J12*100 -> 25.679567 | M12: =H12/G12*100 -> 0.98275701
A13: ARE C | B13: 1824.94 | C13: ='SUMMARY - WAGES PT.RJ'!Y35 -> 260 | D13: 264 | E13: =C13-D13 -> -4 | F13: ='SUMMARY - WAGES PT.RJ'!AH35 -> 1.2824897e+09 | G13: 1.2927092e+09 | H13: =F13-G13 -> -10219467 | I13: ='SUMMARY - WAGES PT.RJ'!AI35 -> 2533.65 | J13: 2211.9 | K13: =I13-J13 -> 321.75 | L13: =K13/J13*100 -> 14.546318 | M13: =H13/G13*100 -> -0.79054649
A14: MILL PKS | C14: ='SUMMARY - WAGES PT.RJ'!Y23 -> 167 | D14: 167 | E14: =C14-D14 -> 0 | F14: ='SUMMARY - WAGES PT.RJ'!AH23 -> 1234277949 | G14: 1207391151 | H14: =F14-G14 -> 26886798 | I14: 0 | J14: 0 | K14: =I14-J14 -> 0 | L14: 0 | M14: =H14/G14*100 -> 2.2268507
A15: BIBITAN | C15: ='SUMMARY - WAGES PT.RJ'!Y21 -> 18 | D15: 18 | E15: =C15-D15 -> 0 | F15: ='SUMMARY - WAGES PT.RJ'!AH21 -> 90844468 | G15: 88815910 | H15: =F15-G15 -> 2028557.8 | I15: 0 | J15: 0 | K15: =I15-J15 -> 0 | L15: 0 | M15: =H15/G15*100 -> 2.2840027
A16: Workshop ARE | C16: ='SUMMARY - WAGES PT.RJ'!Y37 -> 5 | D16: 5 | E16: =C16-D16 -> 0 | F16: ='SUMMARY - WAGES PT.RJ'!AH37 -> 28906719 | G16: 26805912 | H16: =F16-G16 -> 2100807 | I16: 0 | J16: 0 | K16: =I16-J16 -> 0 | L16: 0 | M16: =H16/G16*100 -> 7.8371034
A17: Workshop PGE | C17: ='SUMMARY - WAGES PT.RJ'!Y17 -> 14 | D17: 14 | E17: =C17-D17 -> 0 | F17: ='SUMMARY - WAGES PT.RJ'!AH17 -> 87891747 | G17: 80279506 | H17: =F17-G17 -> 7612241.2 | I17: 0 | J17: 0 | K17: =I17-J17 -> 0 | L17: 0 | M17: =H17/G17*100 -> 9.4821725
A18: Infrastruktur | C18: ='SUMMARY - WAGES PT.RJ'!Y19 -> 29 | D18: 29 | E18: =C18-D18 -> 0 | F18: ='SUMMARY - WAGES PT.RJ'!AH19 -> 1.611283e+08 | G18: 163108145 | H18: =F18-G18 -> -1979844.7 | I18: 0 | J18: 0 | K18: =I18-J18 -> 0 | L18: 0 | M18: =H18/G18*100 -> -1.2138233
B19: =SUM(B5:B18) -> 10493.01 | C19: =SUM(C5:C18) -> 1767 | D19: 1776 | E19: =SUM(E5:E18) -> -9 | F19: =SUM(F5:F18) -> 8.8160642e+09 | G19: 8.7777455e+09 | H19: =SUM(H5:H18) -> 38318694 | I19: =SUM(I5:I18) -> 15374.29 | J19: 12741.8 | K19: =SUM(K5:K18) -> 2632.49 | L19: =K19/J19*100 -> 20.660268 | M19: =H19/G19*100 -> 0.43654369
A21: Prunning
A23: Estate | B23: This Month
C24: Premi | D24: Total | I24: TURUN HK (Okt'25 - Sept'25 ) | M24: =K39 -> 180132680
A25: PGE 1A | C25: ='SUMMARY - WAGES PT.RJ'!AD7 -> 15466750 | D25: =C25+B25 -> 15466750 | I25: Premi Estate TURUN dari bulan lalu | L25: ( Lampiran I) | M25: =Rekapitulasi!F282 -> -59993946
A26: PGE 1B | C26: ='SUMMARY - WAGES PT.RJ'!AD9-C37 -> 0 | D26: =C26+B26 -> 0 | I26: OT Estate + Mill TURUN dari bulan lalu | L26: ( Lampiran I) | M26: =Rekapitulasi!G282 -> -5940259.2
A27: PGE 2A | C27: ='SUMMARY - WAGES PT.RJ'!AD11 -> 16282050 | D27: =C27+B27 -> 16282050 | I27: Progressive Pruning TURUN dari bulan lalu | L27: ( Lampiran II ) | M27: =Prunning!G16 -> -134517050
A28: PGE 2B | C28: ='SUMMARY - WAGES PT.RJ'!AD13-C38 -> 8599500 | D28: =C28+B28 -> 8599500 | I28: Insentif Panen NAIK dari bulan lalu | M28: =M37 -> 62481733
A29: DME | C29: ='SUMMARY - WAGES PT.RJ'!AD15 -> 45629800 | D29: =C29+B29 -> 45629800
A30: ARE A | C30: ='SUMMARY - WAGES PT.RJ'!AD29 -> 26023250 | D30: =C30+B30 -> 26023250 | I30: TOTAL | M30: =SUM(M24:M29) -> 42163158 | P30: =M30-H19 -> 3844464.2
A31: ARE B1 | C31: ='SUMMARY - WAGES PT.RJ'!AD31 -> 29981600 | D31: =C31+B31 -> 29981600
A32: ARE B2 | C32: ='SUMMARY - WAGES PT.RJ'!AD33 -> 20870600 | D32: =C32+B32 -> 20870600 | I32: Tonase TBS NAIK dari bulan lalu | M32: =K19 -> 2632.49 | N32: Ton
A33: ARE C | C33: ='SUMMARY - WAGES PT.RJ'!AD35-C39-C40 -> 45028000 | D33: =C33+B33 -> 45028000
C34: =SUM(C25:C33) -> 207881550 | D34: =SUM(D25:D33) -> 207881550
A35: Prunning | I35: Hk September | J35: 51837 | K35: =J35*129220 -> 6698377140 | L35: Insentif September 2025 | M35: 41467455
A36: PLASMA | C36: Premi | D36: Total | I36: Hk Oktober | J36: ='SEPTEMBER DIBAYAR OKT 2025 '!E554 -> 53231 | K36: =J36*129220 -> 6878509820 | L36: Insentif Oktober 2025 | M36: ='SEPTEMBER DIBAYAR OKT 2025 '!AG554 -> 1.0394919e+08
A37: AIR BATU | C37: 0 | D37: =SUM(C37) -> 0 | J37: =J36-J35 -> 1394 | K37: =K36-K35 -> 180132680 | M37: =M36-M35 -> 62481733
A38: CENDIL | C38: 0 | D38: =SUM(C38) -> 0 | I38: Pengurangan Koreksi
A39: TUNGKUP | C39: 0 | D39: =SUM(C39) -> 0 | K39: =K37+K38 -> 180132680
A40: SIMPANG TIGE | C40: 0 | D40: =SUM(C40) -> 0
C41: =SUM(C37:C40) -> 0 | D41: =SUM(D37:D40) -> 0
A46: Month of MEI 2022
A48: Estate | B48: Luas Ha Productive | C48: Jumlah Karyawan | F48: Nilai Gaji ( All) | I48: Tonase TBS | L48: % TBS Naik / Turun | M48: % Gaji Naik/Turun
...

Sheet SUMMARY - CASH PG & ARE
A1: PT. REBINMAS JAYA CASH DENOMINATION JUNI 2018
A3: ESTATE/DIVISION | B3: WORKERS | C3: 100000 | D3: 50000 | E3: 20000 | F3: 10000 | G3: 5000 | H3: 1000 | I3: OTHERS
J4: TOTAL
A6: PETTY CASH MILL | B6: =#REF! -> #REF! | C6: =#REF! -> #REF! | D6: =#REF! -> #REF! | E6: =#REF! -> #REF! | F6: =#REF! -> #REF! | G6: =#REF! -> #REF! | H6: =#REF! -> #REF! | I6: =#REF! -> #REF! | J6: =SUM(C6:I6) -> #REF!
A8: PHASE 1A - PREMI | B8: =#REF! -> #REF! | C8: 13400000 | D8: =#REF! -> #REF! | E8: 840000 | F8: 500000 | G8: =#REF! -> #REF! | H8: =#REF! -> #REF! | I8: 29180 | J8: =#REF! -> #REF!
A10: PHASE 1B - PREMI | B10: =#REF! -> #REF! | C10: =#REF! -> #REF! | D10: =#REF! -> #REF! | E10: =#REF! -> #REF! | F10: =#REF! -> #REF! | G10: =#REF! -> #REF! | H10: =#REF! -> #REF! | I10: =#REF! -> #REF! | J10: =SUM(C10:I10) -> #REF!
A12: PHASE 2A - PREMI | B12: =#REF! -> #REF! | C12: =#REF! -> #REF! | D12: =#REF! -> #REF! | E12: =#REF! -> #REF! | F12: =#REF! -> #REF! | G12: =#REF! -> #REF! | H12: =#REF! -> #REF! | I12: =#REF! -> #REF! | J12: =SUM(C12:I12) -> #REF!
A14: PHASE 2B - PREMI | B14: =#REF! -> #REF! | C14: =#REF! -> #REF! | D14: =#REF! -> #REF! | E14: =#REF! -> #REF! | F14: =#REF! -> #REF! | G14: =#REF! -> #REF! | H14: =#REF! -> #REF! | I14: =#REF! -> #REF! | J14: =SUM(C14:I14) -> #REF!
A16: DME 1 - PREMI | B16: =#REF! -> #REF! | C16: =#REF! -> #REF! | D16: =#REF! -> #REF! | E16: =#REF! -> #REF! | F16: =#REF! -> #REF! | G16: =#REF! -> #REF! | H16: =#REF! -> #REF! | I16: =#REF! -> #REF! | J16: =SUM(C16:I16) -> #REF!
A18: DME 2 - PREMI | B18: =#REF! -> #REF! | C18: =#REF! -> #REF! | D18: =#REF! -> #REF! | E18: =#REF! -> #REF! | F18: =#REF! -> #REF! | G18: =#REF! -> #REF! | H18: =#REF! -> #REF! | I18: =#REF! -> #REF! | J18: =SUM(C18:I18) -> #REF!
A20: BULUH TUMBANG - PREMI | B20: =#REF! -> #REF! | C20: =#REF! -> #REF! | D20: =#REF! -> #REF! | E20: =#REF! -> #REF! | F20: =#REF! -> #REF! | G20: =#REF! -> #REF! | H20: =#REF! -> #REF! | I20: =#REF! -> #REF! | J20: =SUM(C20:I20) -> #REF!
A22: MC ALLOWANCE | B22: =#REF! -> #REF! | C22: =#REF! -> #REF! | D22: =#REF! -> #REF! | E22: =#REF! -> #REF! | F22: =#REF! -> #REF! | G22: =#REF! -> #REF! | H22: =#REF! -> #REF! | I22: =#REF! -> #REF! | J22: =#REF! -> #REF!
A24: PETTY CASH ESTATE | B24: =#REF! -> #REF! | C24: =#REF! -> #REF! | D24: =#REF! -> #REF! | E24: =#REF! -> #REF! | F24: =#REF! -> #REF! | G24: =#REF! -> #REF! | H24: =#REF! -> #REF! | I24: =#REF! -> #REF! | J24: =SUM(C24:I24) -> #REF!
A28: SUB TOTAL | B28: =SUM(B5:B27) -> #REF! | C28: =SUM(C5:C27) -> #REF! | D28: =SUM(D5:D27) -> #REF! | E28: =SUM(E5:E27) -> #REF! | F28: =SUM(F5:F27) -> #REF! | G28: =SUM(G5:G27) -> #REF! | H28: =SUM(H5:H27) -> #REF! | I28: =SUM(I5:I27) -> #REF! | J28: =SUM(J5:J27) -> #REF!
A29: =+A1 -> PT. REBINMAS JAYA CASH DENOMINATION JUNI 2018
A32: ARE - A (CASH PAYMENT ) | B32: =#REF! -> #REF! | C32: 3600000 | D32: =#REF! -> #REF! | E32: 260000 | F32: 100000 | G32: =#REF! -> #REF! | H32: =#REF! -> #REF! | I32: 7839 | J32: =#REF! -> #REF!
A34: ARE - B1 PREMI | B34: =#REF! -> #REF! | C34: =#REF! -> #REF! | D34: =#REF! -> #REF! | E34: =#REF! -> #REF! | F34: =#REF! -> #REF! | G34: =#REF! -> #REF! | H34: =#REF! -> #REF! | I34: =#REF! -> #REF! | J34: =SUM(C34:I34) -> #REF!
A36: ARE - B2 PREMI | B36: =#REF! -> #REF! | C36: =#REF! -> #REF! | D36: =#REF! -> #REF! | E36: =#REF! -> #REF! | F36: =#REF! -> #REF! | G36: =#REF! -> #REF! | H36: =#REF! -> #REF! | I36: =#REF! -> #REF! | J36: =SUM(C36:I36) -> #REF!
A38: ARE - C ( CASH PAYMENT ) | B38: 0 | C38: 0 | D38: 0 | E38: 0 | F38: 0 | G38: 0 | H38: 0 | I38: 0 | J38: =#REF! -> #REF!
A40: WORKSHOP ARE - PREMI | B40: =#REF! -> #REF! | C40: =#REF! -> #REF! | D40: =#REF! -> #REF! | E40: =#REF! -> #REF! | F40: =#REF! -> #REF! | G40: =#REF! -> #REF! | H40: =#REF! -> #REF! | I40: =#REF! -> #REF! | J40: =SUM(C40:I40) -> #REF!
A42: SUB TOTAL | B42: =SUM(B31:B41) -> #REF! | C42: =SUM(C31:C41) -> #REF! | D42: =SUM(D31:D41) -> #REF! | E42: =SUM(E31:E41) -> #REF! | F42: =SUM(F31:F41) -> #REF! | G42: =SUM(G31:G41) -> #REF! | H42: =SUM(H31:H41) -> #REF! | I42: =SUM(I31:I41) -> #REF! | J42: =SUM(J31:J41) -> #REF!
A44: GRAND TOTAL | B44: =B28+B42 -> #REF! | C44: =C28+C42 -> #REF! | D44: =D28+D42 -> #REF! | E44: =E28+E42 -> #REF! | F44: =F28+F42 -> #REF! | G44: =G28+G42 -> #REF! | H44: =H28+H42 -> #REF! | I44: =I28+I42 -> #REF! | J44: =J28+J42 -> #REF!
A51: DIBUAT OLEH : | B51: DIPERIKSA OLEH: | F51: DISETUJUI OLEH:
C56: JUMLAH | D56: NILAI | E56: TOTAL ( RP ) | G56: JUMLAH | H56: NILAI | I56: TOTAL ( RP )
C57: 36 | D57: 100000 | E57: =C57*D57 -> 3600000 | G57: 134 | H57: 100000 | I57: 13400000
C58: 0 | D58: 50000 | E58: =C58*D58 -> 0 | G58: 0 | H58: 50000 | I58: 0
C59: 13 | D59: 20000 | E59: =C59*D59 -> 260000 | G59: 42 | H59: 20000 | I59: 840000
C60: 10 | D60: 10000 | E60: =C60*D60 -> 100000 | G60: 50 | H60: 10000 | I60: 500000
C61: 0 | D61: 5000 | E61: =C61*D61 -> 0 | G61: 0 | H61: 5000 | I61: 0
C62: 0 | D62: 1000 | E62: =C62*D62 -> 0 | G62: 0 | H62: 1000 | I62: 0
C63: 10 | D63: 500 | E63: =C63*D63 -> 5000 | G63: 42 | H63: 500 | I63: 21000
C64: 22 | D64: 100 | E64: =C64*D64 -> 2200 | G64: 58 | H64: 100 | I64: 5800
C65: Balance | E65: 638 | G65: Balance | I65: 2370
E66: =SUM(E57:E65) -> 3967838 | I66: 14769170

Sheet JUNI 2018 DIBAYAR JULI 2018 (2)
A3: PT. REBINMAS JAYA
A4: DENOMINATION FOR JULI 2018
A6: ESTATE/DIVISION | B6: WORKERS | M6: Pot. | N6: TOTAL PPH 21 | O6: TOTAL PPH | P6: TOTAL PREMI | Q6: TOTAL LEMBUR | R6: TOTAL | S6: Upah & Astek | T6: Total & | X6: PRUNNING | AA6: TOTAL PREMI
C7: 100000 | D7: 50000 | E7: 20000 | F7: 10000 | G7: 5000 | H7: 1000 | I7: 500 | J7: 100 | K7: 50 | L7: OTHERS | M7: Pinjaman | N7: (MASA JUNI - 2018) | O7: EX-GRATIA | T7: Rata-rata
A9: PHASE IA HARVESTING KHL (AIR HIJAU) | B9: 10 | N9: 0 | P9: =3240140+66990+464000 -> 3771130 | Q9: 0 | R9: 26387252 | X9: 883500 | AA9: =P9+X9 -> 4654630
A10: PHASE IA MAINTENANCE KHT (AIR HIJAU) | B10: 41 | N10: 0 | P10: 1851220 | Q10: 2038710 | R10: 116157613 | X10: 0 | AA10: =P10+X10 -> 1851220
A11: PHASE IA OPERATOR (AIR HIJAU) | B11: 6 | N11: 1304 | P11: 7188000 | Q11: 4186834 | R11: 28463887 | X11: 0 | AA11: =P11+X11 -> 7188000
A12: PHASE IA HARVESTING MANDOR & KERANI (AIR HIJAU) | B12: 28 | N12: 182777 | P12: =20239160+2063530 -> 22302690 | Q12: 2667843 | R12: 106196357 | X12: 7307500 | AA12: =P12+X12 -> 29610190
A13: PHASE IA HARVESTING KHT (AIR BATU) | B13: 25 | N13: 0 | P13: =6633310 -> 6633310 | Q13: 1855544 | R13: 76919231 | X13: 3806000 | AA13: =P13+X13 -> 10439310
A14: PHASE IA MAINTENANCE KHT (AIR BATU) | B14: 33 | N14: 0 | P14: 746900 | Q14: 1242341 | R14: 89870308 | X14: 0 | AA14: =P14+X14 -> 746900
A15: PHASE IA OPERATOR (AIR BATU) | B15: 4 | N15: 0 | P15: 2122245 | Q15: 2110359 | R15: 15540812 | X15: 0 | AA15: =P15+X15 -> 2122245
A16: PHASE IA HARVESTING KHL (AIR BATU) | B16: 6 | N16: 0 | P16: =2984050 -> 2984050 | Q16: 0 | R16: 16995845 | X16: 846000 | AA16: =P16+X16 -> 3830050
A17: PHASE IA HARVESTING KHT (AIR KUNDO) | B17: 23 | N17: 64502 | P17: =13152550+3486700+330605 -> 16969855 | Q17: 2245766 | R17: 86968930 | X17: 6816000 | AA17: =P17+X17 -> 23785855
A18: PHASE IA MAINTENANCE KHT (AIR KUNDO) | B18: 30 | N18: 0 | P18: 533889 | Q18: 2110383 | R18: 83286601 | X18: 0 | AA18: =P18+X18 -> 533889
A19: PHASE IA PANEN KHL (AIR KUNDO) | B19: 7 | N19: 0 | P19: =314710+1533000 -> 1847710 | Q19: 0 | R19: 15841552 | X19: 192000 | AA19: =P19+X19 -> 2039710
A20: PHASE IA OPERATOR (AIR KUNDO) | B20: 4 | N20: 0 | P20: 1542382 | Q20: 2078528 | R20: 14218530 | X20: 0 | AA20: =P20+X20 -> 1542382
A22: TOTAL | B22: =SUM(B8:B21) -> 217 | C22: =SUM(C8:C21) -> 0 | D22: =SUM(D8:D21) -> 0 | E22: =SUM(E8:E21) -> 0 | F22: =SUM(F8:F21) -> 0 | G22: =SUM(G8:G21) -> 0 | H22: =SUM(H8:H21) -> 0 | I22: =SUM(I8:I21) -> 0 | ... R22: =SUM(R8:R21) -> 676846918 | T22: =#REF!/#REF! -> #REF! | U22: Upah rata-rata/ hk | X22: =SUM(X8:X21) -> 19851000 | AA22: =SUM(AA9:AA21) -> 88344381
A28: DIBUAT OLEH : DIPERIKSA OLEH : | D28: DIPERIKSA OLEH : | J28: DISETUJUI OLEH :
A37: PT. REBINMAS JAYA
A38: =A4 -> DENOMINATION FOR JULI 2018
A40: ESTATE/DIVISION | B40: WORKERS | M40: =M6 -> Pot. | N40: TOTAL PPH 21 | O40: TOTAL PPH | P40: =P6 -> TOTAL PREMI | Q40: =Q6 -> TOTAL LEMBUR | R40: TOTAL | S40: Upah & Astek | T40: Total & | X40: PRUNNING
C41: 100000 | D41: 50000 | E41: 20000 | F41: 10000 | G41: 5000 | H41: 1000 | I41: 500 | J41: 100 | K41: 50 | L41: OTHERS | M41: =M7 -> Pinjaman | N41: =N7 -> (MASA JUNI - 2018) | O41: EX-GRATIA | T41: Rata-rata
A43: PHASE IB OPERATOR (GUNUNG RUM) | B43: 4 | N43: 0 | P43: 2861073 | Q43: 2094456 | R43: 15339652 | X43: 0 | AA43: =P43+X43 -> 2861073
A44: PHASE IB HARVESTING KHT (GUNUNG RUM) | B44: 31 | N44: 0 | P44: =3925330+247100 -> 4172430 | Q44: 2548387 | R44: 101467542 | X44: 12593000 | AA44: =P44+X44 -> 16765430
A45: PHASE IB MAINTENANCE KHT (GUNUNG RUM) | B45: 36 | N45: 0 | P45: =26760+1814800 -> 1841560 | Q45: 1258266 | R45: 101352495 | X45: 0 | AA45: =P45+X45 -> 1841560
A46: PHASE IB HARVESTING KHT (GUNUNG PANJANG) | B46: 21 | N46: 0 | P46: =1281130+499100 -> 1780230 | Q46: 1847580 | R46: 62202310 | X46: 3680500 | AA46: =P46+X46 -> 5460730
A47: PHASE IB MAINTENANCE KHT (GUNUNG PANJANG) | B47: 32 | N47: 0 | P47: 0 | Q47: 915827 | R47: 86660331 | X47: 0 | AA47: =P47+X47 -> 0
A48: PHASE IB OPERATOR (GUNUNG PANJANG) | B48: 5 | N48: 0 | P48: 3169027 | Q48: 3201412 | R48: 20687222 | X48: 0 | AA48: =P48+X48 -> 3169027
A49: PHASE IB HARVESTING KHL (GUNUNG PANJANG) | B49: 4 | N49: 0 | P49: =90640+100100 -> 190740 | Q49: 0 | R49: 9055768 | X49: 276000 | AA49: =P49+X49 -> 466740 | AC49: =37+31 -> 68
A50: PHASE IB MAINTENANCE KHL (GUNUNG PANJANG) | B50: 24 | N50: 0 | P50: 0 | Q50: 0 | R50: 5621105 | X50: 0 | AA50: =P50+X50 -> 0
A51: PHASE IB HARVESTING & MANDOR & KERANI (PADANG TEMBALUN) | B51: 23 | N51: 25502 | P51: =9595200 -> 9595200 | Q51: 2182057 | R51: 78686731 | X51: 6705500 | AA51: =P51+X51 -> 16300700
A52: PHASE IB MAINTENANCE KHT (PADANG TEMBALUN) | B52: 46 | N52: 0 | P52: 1666800 | Q52: 1704227 | R52: 128548713 | X52: 0 | AA52: =P52+X52 -> 1666800
A53: PHASE IB PLASMA (PADANG TEMBALUN) | B53: 8 | N53: 0 | P53: =739710+788200 -> 1527910 | Q53: 772480 | R53: 25254834 | X53: 2473500 | AA53: =P53+X53 -> 4001410
A54: PHASE IB HARVESTING KHL (PADANG TEMBALUN) | B54: 21 | N54: 0 | P54: =7561260+189000 -> 7750260 | Q54: 0 | R54: 50038491 | X54: 0 | AA54: =P54+X54 -> 7750260
A55: PHASE IB OPERATOR (PADANG TEMBALUN) | B55: 6 | N55: 0 | P55: 3232953 | Q55: 3550922 | R55: 23950232 | AA55: =P55+X55 -> 3232953
AA56: =P56+X56 -> 0
A57: TOTAL | B57: =SUM(B43:B56) -> 261 | C57: =SUM(C43:C56) -> 0 | D57: =SUM(D43:D56) -> 0 | E57: =SUM(E43:E56) -> 0 | F57: =SUM(F43:F56) -> 0 | G57: =SUM(G43:G56) -> 0 | H57: =SUM(H43:H56) -> 0 | I57: =SUM(I43:I56) -> 0 | ... R57: =SUM(R43:R56) -> 708865426 | T57: =#REF!/#REF! -> #REF! | U57: Upah rata-rata/HK | X57: =SUM(X42:X56) -> 25728500 | AA57: =SUM(AA43:AA56) -> 63516683
A63: DIBUAT OLEH : DIPERIKSA OLEH : | D63: DIPERIKSA OLEH : | J63: DISETUJUI OLEH :
A72: PT. REBINMAS JAYA
A73: =A4 -> DENOMINATION FOR JULI 2018
...

Sheet Sheet5
A5: NO | B5: ESTATE | C5: STATUS
A6: 1 | B6: PGE 1A | C6: ROBY
A7: 2 | B7: PGE 1B | C7: UNKNOWN
A8: 3 | B8: PGE 2A | C8: UNKNOWN
A9: 4 | B9: PGE 2B | C9: UNKNOWN
A10: 5 | B10: DME | C10: UNKNOWN
A11: 6 | B11: ARE A | C11: ROBY
A12: 7 | B12: ARE B1 | C12: UNKNOWN
A13: 8 | B13: ARE B2 | C13: UNKNOWN
A14: 9 | B14: ARE C | C14: UNKNOWN
A15: 10 | B15: INFRASTRUKTUR | C15: ROBY
A16: 11 | B16: WORKSHOP PG | C16: ROBY
A17: 12 | B17: WORKSHOP ARE | C17: UNKNOWN
A18: 13 | B18: IJL | C18: REVISI
E27: 100000 | F27: 50000 | G27: 20000 | H27: 10000 | I27: 5000 | J27: 1000 | K27: 500 | L27: 100 | M27: Balance
B28: 1 | C28: 330653 | E28: =ROUNDDOWN(C28/100000,0) -> 3 | F28: =ROUNDDOWN((C28-E28*100000)/50000,0) -> 0 | G28: =ROUNDDOWN((C28-E28*100000-F28*50000)/20000,0) -> 1 | H28: =ROUNDDOWN((C28-E28*100000-F28*50000-G28*20000)/10000,0) -> 1 | I28: =ROUNDDOWN((C28-E28*100000-F28*50000-G28*20000-H28*10000)/5000,0) -> 0 | J28: =ROUNDDOWN((C28-E28*100000-F28*50000-G28*20000-H28*10000-I28*5000)/1000,0) -> 0 | K28: =ROUNDDOWN((C28-E28*100000-F28*50000-G28*20000-H28*10000-I28*5000-J28*1000)/500,0) -> 1 | L28: =ROUNDDOWN((C28-E28*100000-F28*50000-G28*20000-H28*10000-I28*5000-J28*1000-K28*500)/100,0) -> 1 | M28: =C28-N28 -> 53 | N28: =E28*100000+F28*50000+G28*20000+H28*10000+I28*5000+J28*1000+K28*500+L28*100 -> 330600 | O28: =N28+M28 -> 330653
B29: 2 | C29: 330653 | E29: =ROUNDDOWN(C29/100000,0) -> 3 | F29: =ROUNDDOWN((C29-E29*100000)/50000,0) -> 0 | G29: =ROUNDDOWN((C29-E29*100000-F29*50000)/20000,0) -> 1 | H29: =ROUNDDOWN((C29-E29*100000-F29*50000-G29*20000)/10000,0) -> 1 | I29: =ROUNDDOWN((C29-E29*100000-F29*50000-G29*20000-H29*10000)/5000,0) -> 0 | J29: =ROUNDDOWN((C29-E29*100000-F29*50000-G29*20000-H29*10000-I29*5000)/1000,0) -> 0 | K29: =ROUNDDOWN((C29-E29*100000-F29*50000-G29*20000-H29*10000-I29*5000-J29*1000)/500,0) -> 1 | L29: =ROUNDDOWN((C29-E29*100000-F29*50000-G29*20000-H29*10000-I29*5000-J29*1000-K29*500)/100,0) -> 1 | M29: =C29-N29 -> 53 | N29: =E29*100000+F29*50000+G29*20000+H29*10000+I29*5000+J29*1000+K29*500+L29*100 -> 330600 | O29: =N29+M29 -> 330653
B30: 3 | C30: 330653 | E30: =ROUNDDOWN(C30/100000,0) -> 3 | F30: =ROUNDDOWN((C30-E30*100000)/50000,0) -> 0 | G30: =ROUNDDOWN((C30-E30*100000-F30*50000)/20000,0) -> 1 | H30: =ROUNDDOWN((C30-E30*100000-F30*50000-G30*20000)/10000,0) -> 1 | I30: =ROUNDDOWN((C30-E30*100000-F30*50000-G30*20000-H30*10000)/5000,0) -> 0 | J30: =ROUNDDOWN((C30-E30*100000-F30*50000-G30*20000-H30*10000-I30*5000)/1000,0) -> 0 | K30: =ROUNDDOWN((C30-E30*100000-F30*50000-G30*20000-H30*10000-I30*5000-J30*1000)/500,0) -> 1 | L30: =ROUNDDOWN((C30-E30*100000-F30*50000-G30*20000-H30*10000-I30*5000-J30*1000-K30*500)/100,0) -> 1 | M30: =C30-N30 -> 53 | N30: =E30*100000+F30*50000+G30*20000+H30*10000+I30*5000+J30*1000+K30*500+L30*100 -> 330600 | O30: =N30+M30 -> 330653
B31: 4 | C31: 330653 | E31: =ROUNDDOWN(C31/100000,0) -> 3 | F31: =ROUNDDOWN((C31-E31*100000)/50000,0) -> 0 | G31: =ROUNDDOWN((C31-E31*100000-F31*50000)/20000,0) -> 1 | H31: =ROUNDDOWN((C31-E31*100000-F31*50000-G31*20000)/10000,0) -> 1 | I31: =ROUNDDOWN((C31-E31*100000-F31*50000-G31*20000-H31*10000)/5000,0) -> 0 | J31: =ROUNDDOWN((C31-E31*100000-F31*50000-G31*20000-H31*10000-I31*5000)/1000,0) -> 0 | K31: =ROUNDDOWN((C31-E31*100000-F31*50000-G31*20000-H31*10000-I31*5000-J31*1000)/500,0) -> 1 | L31: =ROUNDDOWN((C31-E31*100000-F31*50000-G31*20000-H31*10000-I31*5000-J31*1000-K31*500)/100,0) -> 1 | M31: =C31-N31 -> 53 | N31: =E31*100000+F31*50000+G31*20000+H31*10000+I31*5000+J31*1000+K31*500+L31*100 -> 330600 | O31: =N31+M31 -> 330653
B32: 5 | C32: 330653 | E32: =ROUNDDOWN(C32/100000,0) -> 3 | F32: =ROUNDDOWN((C32-E32*100000)/50000,0) -> 0 | G32: =ROUNDDOWN((C32-E32*100000-F32*50000)/20000,0) -> 1 | H32: =ROUNDDOWN((C32-E32*100000-F32*50000-G32*20000)/10000,0) -> 1 | I32: =ROUNDDOWN((C32-E32*100000-F32*50000-G32*20000-H32*10000)/5000,0) -> 0 | J32: =ROUNDDOWN((C32-E32*100000-F32*50000-G32*20000-H32*10000-I32*5000)/1000,0) -> 0 | K32: =ROUNDDOWN((C32-E32*100000-F32*50000-G32*20000-H32*10000-I32*5000-J32*1000)/500,0) -> 1 | L32: =ROUNDDOWN((C32-E32*100000-F32*50000-G32*20000-H32*10000-I32*5000-J32*1000-K32*500)/100,0) -> 1 | M32: =C32-N32 -> 53 | N32: =E32*100000+F32*50000+G32*20000+H32*10000+I32*5000+J32*1000+K32*500+L32*100 -> 330600 | O32: =N32+M32 -> 330653
B33: 6 | C33: 330653 | E33: =ROUNDDOWN(C33/100000,0) -> 3 | F33: =ROUNDDOWN((C33-E33*100000)/50000,0) -> 0 | G33: =ROUNDDOWN((C33-E33*100000-F33*50000)/20000,0) -> 1 | H33: =ROUNDDOWN((C33-E33*100000-F33*50000-G33*20000)/10000,0) -> 1 | I33: =ROUNDDOWN((C33-E33*100000-F33*50000-G33*20000-H33*10000)/5000,0) -> 0 | J33: =ROUNDDOWN((C33-E33*100000-F33*50000-G33*20000-H33*10000-I33*5000)/1000,0) -> 0 | K33: =ROUNDDOWN((C33-E33*100000-F33*50000-G33*20000-H33*10000-I33*5000-J33*1000)/500,0) -> 1 | L33: =ROUNDDOWN((C33-E33*100000-F33*50000-G33*20000-H33*10000-I33*5000-J33*1000-K33*500)/100,0) -> 1 | M33: =C33-N33 -> 53 | N33: =E33*100000+F33*50000+G33*20000+H33*10000+I33*5000+J33*1000+K33*500+L33*100 -> 330600 | O33: =N33+M33 -> 330653
B34: 7 | C34: 330653 | E34: =ROUNDDOWN(C34/100000,0) -> 3 | F34: =ROUNDDOWN((C34-E34*100000)/50000,0) -> 0 | G34: =ROUNDDOWN((C34-E34*100000-F34*50000)/20000,0) -> 1 | H34: =ROUNDDOWN((C34-E34*100000-F34*50000-G34*20000)/10000,0) -> 1 | I34: =ROUNDDOWN((C34-E34*100000-F34*50000-G34*20000-H34*10000)/5000,0) -> 0 | J34: =ROUNDDOWN((C34-E34*100000-F34*50000-G34*20000-H34*10000-I34*5000)/1000,0) -> 0 | K34: =ROUNDDOWN((C34-E34*100000-F34*50000-G34*20000-H34*10000-I34*5000-J34*1000)/500,0) -> 1 | L34: =ROUNDDOWN((C34-E34*100000-F34*50000-G34*20000-H34*10000-I34*5000-J34*1000-K34*500)/100,0) -> 1 | M34: =C34-N34 -> 53 | N34: =E34*100000+F34*50000+G34*20000+H34*10000+I34*5000+J34*1000+K34*500+L34*100 -> 330600 | O34: =N34+M34 -> 330653
B35: 8 | C35: 330653 | E35: =ROUNDDOWN(C35/100000,0) -> 3 | F35: =ROUNDDOWN((C35-E35*100000)/50000,0) -> 0 | G35: =ROUNDDOWN((C35-E35*100000-F35*50000)/20000,0) -> 1 | H35: =ROUNDDOWN((C35-E35*100000-F35*50000-G35*20000)/10000,0) -> 1 | I35: =ROUNDDOWN((C35-E35*100000-F35*50000-G35*20000-H35*10000)/5000,0) -> 0 | J35: =ROUNDDOWN((C35-E35*100000-F35*50000-G35*20000-H35*10000-I35*5000)/1000,0) -> 0 | K35: =ROUNDDOWN((C35-E35*100000-F35*50000-G35*20000-H35*10000-I35*5000-J35*1000)/500,0) -> 1 | L35: =ROUNDDOWN((C35-E35*100000-F35*50000-G35*20000-H35*10000-I35*5000-J35*1000-K35*500)/100,0) -> 1 | M35: =C35-N35 -> 53 | N35: =E35*100000+F35*50000+G35*20000+H35*10000+I35*5000+J35*1000+K35*500+L35*100 -> 330600 | O35: =N35+M35 -> 330653
B36: 9 | C36: 330653 | E36: =ROUNDDOWN(C36/100000,0) -> 3 | F36: =ROUNDDOWN((C36-E36*100000)/50000,0) -> 0 | G36: =ROUNDDOWN((C36-E36*100000-F36*50000)/20000,0) -> 1 | H36: =ROUNDDOWN((C36-E36*100000-F36*50000-G36*20000)/10000,0) -> 1 | I36: =ROUNDDOWN((C36-E36*100000-F36*50000-G36*20000-H36*10000)/5000,0) -> 0 | J36: =ROUNDDOWN((C36-E36*100000-F36*50000-G36*20000-H36*10000-I36*5000)/1000,0) -> 0 | K36: =ROUNDDOWN((C36-E36*100000-F36*50000-G36*20000-H36*10000-I36*5000-J36*1000)/500,0) -> 1 | L36: =ROUNDDOWN((C36-E36*100000-F36*50000-G36*20000-H36*10000-I36*5000-J36*1000-K36*500)/100,0) -> 1 | M36: =C36-N36 -> 53 | N36: =E36*100000+F36*50000+G36*20000+H36*10000+I36*5000+J36*1000+K36*500+L36*100 -> 330600 | O36: =N36+M36 -> 330653
B37: 10 | C37: 330653 | E37: =ROUNDDOWN(C37/100000,0) -> 3 | F37: =ROUNDDOWN((C37-E37*100000)/50000,0) -> 0 | G37: =ROUNDDOWN((C37-E37*100000-F37*50000)/20000,0) -> 1 | H37: =ROUNDDOWN((C37-E37*100000-F37*50000-G37*20000)/10000,0) -> 1 | I37: =ROUNDDOWN((C37-E37*100000-F37*50000-G37*20000-H37*10000)/5000,0) -> 0 | J37: =ROUNDDOWN((C37-E37*100000-F37*50000-G37*20000-H37*10000-I37*5000)/1000,0) -> 0 | K37: =ROUNDDOWN((C37-E37*100000-F37*50000-G37*20000-H37*10000-I37*5000-J37*1000)/500,0) -> 1 | L37: =ROUNDDOWN((C37-E37*100000-F37*50000-G37*20000-H37*10000-I37*5000-J37*1000-K37*500)/100,0) -> 1 | M37: =C37-N37 -> 53 | N37: =E37*100000+F37*50000+G37*20000+H37*10000+I37*5000+J37*1000+K37*500+L37*100 -> 330600 | O37: =N37+M37 -> 330653
B38: 11 | C38: 330653 | E38: =ROUNDDOWN(C38/100000,0) -> 3 | F38: =ROUNDDOWN((C38-E38*100000)/50000,0) -> 0 | G38: =ROUNDDOWN((C38-E38*100000-F38*50000)/20000,0) -> 1 | H38: =ROUNDDOWN((C38-E38*100000-F38*50000-G38*20000)/10000,0) -> 1 | I38: =ROUNDDOWN((C38-E38*100000-F38*50000-G38*20000-H38*10000)/5000,0) -> 0 | J38: =ROUNDDOWN((C38-E38*100000-F38*50000-G38*20000-H38*10000-I38*5000)/1000,0) -> 0 | K38: =ROUNDDOWN((C38-E38*100000-F38*50000-G38*20000-H38*10000-I38*5000-J38*1000)/500,0) -> 1 | L38: =ROUNDDOWN((C38-E38*100000-F38*50000-G38*20000-H38*10000-I38*5000-J38*1000-K38*500)/100,0) -> 1 | M38: =C38-N38 -> 53 | N38: =E38*100000+F38*50000+G38*20000+H38*10000+I38*5000+J38*1000+K38*500+L38*100 -> 330600 | O38: =N38+M38 -> 330653
B39: 12 | C39: 330653 | E39: =ROUNDDOWN(C39/100000,0) -> 3 | F39: =ROUNDDOWN((C39-E39*100000)/50000,0) -> 0 | G39: =ROUNDDOWN((C39-E39*100000-F39*50000)/20000,0) -> 1 | H39: =ROUNDDOWN((C39-E39*100000-F39*50000-G39*20000)/10000,0) -> 1 | I39: =ROUNDDOWN((C39-E39*100000-F39*50000-G39*20000-H39*10000)/5000,0) -> 0 | J39: =ROUNDDOWN((C39-E39*100000-F39*50000-G39*20000-H39*10000-I39*5000)/1000,0) -> 0 | K39: =ROUNDDOWN((C39-E39*100000-F39*50000-G39*20000-H39*10000-I39*5000-J39*1000)/500,0) -> 1 | L39: =ROUNDDOWN((C39-E39*100000-F39*50000-G39*20000-H39*10000-I39*5000-J39*1000-K39*500)/100,0) -> 1 | M39: =C39-N39 -> 53 | N39: =E39*100000+F39*50000+G39*20000+H39*10000+I39*5000+J39*1000+K39*500+L39*100 -> 330600 | O39: =N39+M39 -> 330653
